Workbook

Sheet 0_Guide
B2: One Matrix - Four Steps (LLM-ready, no background assumed)
B3: A single progressive-disclosure matrix for screening, coding, deep-read analysis and reporting.
B5: CONTEXT PRIMER (read this before coding any paper)
B6: What is this review about | C6: This is a systematic literature review about DIGITAL TWINS used in the built-environment industry, specifically to improve SAFETY and QUALITY of designs. You are screening and coding academic papers.
B7: AECO | C7: AECO = Architecture, Engineering, Construction and Operations. It means the built-environment / construction industry (buildings, bridges, infrastructure, civil engineering). NOT manufacturing, automotive, aerospace, power/electrical equipment, healthcare, or agriculture.
B8: Digital Twin (DT) | C8: A Digital Twin is a live virtual replica of a physical asset that is connected to it by data. It is MORE than a static 3D/BIM model. If a paper only says the words 'digital twin' in passing but does not actually build or study one, treat DT as a buzzword (answer 'No').
B9: Design for Safety (DfS) | C9: Design for Safety = designing to prevent construction/operation safety incidents (e.g. fall from height, hazards, accident prevention).
B10: Safety (scope) | C10: The review scope is Design for Safety and construction/operational safety. Quality-only studies are out of scope.
B11: Prevention through Design (PtD) | C11: Prevention through Design = the principle of eliminating risks at the design stage before construction begins. Closely related to Design for Safety.
B12: BIM | C12: BIM = Building Information Modelling. A static, design-stage digital model. A BIM model alone is NOT a Digital Twin (no live data link).
B13: bidirectional | C13: 'bidirectional' means data flows BOTH ways: physical->virtual AND virtual->physical (the twin can act back on the real asset). One-way data flow is only a 'digital shadow'.
B14: Answer format | C14: Every Stage-1 and Stage-2 question is answered strictly as 'Yes' or 'No'. If genuinely unsure from the abstract, answer 'No' (conservative) and add a note. Do not invent information not present in the text.
B15: One reason only | C15: When a paper is excluded, the matrix auto-picks ONE standardized reason by priority. You do not write the reason yourself.
B17: THE FOUR STEPS
B18: Step 1 (all 450 papers) | C18: An LLM or reviewer fills the AMBER Stage-1 columns (G-K) for EVERY paper, from the TITLE and ABSTRACT only. Column L auto-decides Include/Exclude; column M auto-writes the single exclusion reason.
B19: Step 2 (the matrix) | C19: This workbook IS the summary matrix. There is nothing separate to generate.
B20: Retrieval + PDF gateway | C20: For Stage-1 includes, first mark column N 'PDF full text on hand?'. This is the gateway: only papers with the PDF on hand can be deep-read. You can revisit later - when a PDF is found, change N from 'No' to 'Yes' and the paper becomes ready for Stage-2/3.
B21: Step 3 (deep read) | C21: For papers whose PDF is on hand, fill the RED Stage-2 columns (P-R) and then the GREEN synthesis 'angle' columns (U-AG). These are the evidence for your findings section.
B22: Step 4 (report) | C22: Open 'Step1_Report' (screening + PRISMA chain + exclusion reasons) and 'Step3_Report' (capability-tier / phase / method / modality / validation / self-improvement tables). Both auto-tally from the same rows.
B24: COLOUR KEY
B25: Bands | C25: AMBER = Stage-1 input (from abstract) · BLUE = PDF gateway · RED = Stage-2 input (from full text) · GREEN = Stage-3 deep-read input · BLUE-GREY = auto formula, do not edit.
B26: Golden rule | C26: Never delete a paper. A paper excluded at any stage stays in the matrix with its reason recorded. This is what makes the PRISMA flow reproducible.
A27: Update 2026-09-30 | B27: Matrix rebuilt from SLR summary matrix step 1.md (956 records, 244 Stage-1 includes) and step 3.md (214 full-text coded: 200 included, 14 excluded; 30 includes awaiting full text). Differences against the previous 429-record matrix are listed in 3_Change_Log. 21 Methodology labels "Perception / Computer Vision" were normalised to "Computer Vision / CNN / object-detection".
A28: Update 2026-10-04 | B28: Stage-2/3 coding replaced with SLR summary matrix step 3.md (DfS-only scope): 244 Stage-1 includes; 240 full-text coded (222 included, 18 excluded); 4 awaiting full text. Stage-1 title/abstract screening applied the earlier broader criterion (Design for Safety, Design for Quality, Prevention through Design); quality-only papers carried through were removed at Stage 2 (Q = No). 21 methodology labels "Perception / Computer Vision" normalised to "Computer Vision / CNN / object-detection". Changes vs v260930 in 3_Change_Log.

Sheet 1_CodeLists
A1: YN | B1: Src | C1: Bin | D1: Tier | E1: DfX | F1: Self | G1: Method | H1: Modality | I1: Valid | J1: Cluster | K1: Fusion | L1: Conf
A2: Yes | B2: Scopus | C2: 0 | D2: Tier 1 - Digital Model (static, no live data) | E2: Design for Safety (DfS) | F2: None | G2: Computer Vision / CNN / object-detection | H2: Single (one data type) | I2: Conceptual (no test) | J2: BIM-to-Digital-Twin architecture | K2: Single | L2: High
A3: No | B3: Web of Science | C3: 1 | D3: Tier 2 - Digital Shadow (one-way physical to virtual) | E3: Other | F3: Mentioned only | G3: Graph Neural Network (GNN) | H3: Multi (two or more data types) | I3: Simulation | J3: Semantic interoperability | K3: Co-present | L3: Medium
B4: Lens.org | D4: Tier 3 - Digital Twin (bidirectional, two-way) | F4: Implemented | G4: LSTM / RNN (recurrent networks) | I4: Lab / scale-model experiment | J4: Perception / Computer Vision | K4: Aligned | L4: Low
B5: Backward-snowball | D5: Tier 4 - Cognitive / Self-improving | F5: Convergence-characterised | G5: Transformer / Large Language Model (LLM) | I5: Single case study | J5: Design for Safety | K5: Fused
B6: Forward-snowball | D6: Unclear | G6: Reinforcement Learning (RL) | I6: Cross-project (multiple real projects) | J6: Predictive analytics / decision support | K6: Unclear
G7: Bayesian / probabilistic | J7: Lifecycle / governance
G8: Agent-based model (ABM) | J8: Other
G9: Finite Element Method / physics-based
G10: Ontology / semantic
G11: Statistical / change-point
G12: Digital Twin platform (no machine learning)
G13: Other / Mixed

Sheet Matrix
P1: a | Q1: b | R1: c | T1: d - 2nd duplicate (none in merged 956 corpus)
G2: a | H2: b | I2: c | K2: e | L2: =COUNTIF(L4:L960,"Exclude") -> 712 | N2: =COUNTIF(N4:N960,"No") -> 4 | O2: =COUNTIF(O4:O960,"No") -> 4 | P2: =COUNTIF(P4:P960,"No") -> 14 | Q2: =COUNTIF(Q4:Q960,"No") -> 6 | R2: =COUNTIF(R4:R960,"No") -> 13 | S2: =COUNTIF(S4:S960,"Exclude") -> 18 | T2: 0
A3: =COUNTA(A5:A960) -> 956 | G3: =COUNTIF(G4:G960,"No") -> 415 | H3: =COUNTIF(H4:H960,"No") -> 268 | I3: =COUNTIF(I4:I960,"No") -> 166 | J3: =COUNTIF(J4:J960,"No") -> 1 | K3: =COUNTIF(K4:K960,"No") -> 20 | L3: =COUNTIF(L4:L960,"Include") -> 244 | N3: =COUNTIF(N4:N960,"Yes") -> 240 | O3: =COUNTIF(O4:O960,"Yes") -> 240 | P3: =COUNTIF(P4:P960,"Yes") -> 226 | Q3: =COUNTIF(Q4:Q960,"Yes") -> 234 | R3: =COUNTIF(R4:R960,"Yes") -> 227 | S3: =COUNTIF(S4:S960,"Include")-T2 -> 222
A4: ID | B4: Authors (year) | C4: Year | D4: Journal | E4: Title | F4: Source database | G4: Stage1: Domain is AECO (built environment)? | H4: Stage1: Digital Twin is core (not just a buzzword)? | I4: Stage1: About Design for Safety / safety / Prevention through Design? | J4: Stage1: Publication type OK (journal/conference article, not editorial/erratum)? | K4: Stage1: Written in English (full text)? | L4: STAGE-1 decision | M4: Stage-1 exclusion reason (auto) | N4: GATEWAY: PDF full text on hand? (change to Yes when found) | O4: Full text retrieved for PRISMA? | P4: Stage2: Digital Twin is the actual subject (full text)? | Q4: Stage2: Design for Safety confirmed in full text? | R4: Stage2: Methodology is clear enough to code? | S4: STAGE-2 decision | T4: Stage-2 exclusion reason (auto) | U4: Deep-read: Digital Twin capability tier | V4: Phase: Design (1/0) | W4: Phase: Construction (1/0) | X4: Phase: Operation (1/0) | Y4: Cross-phase? (auto) | Z4: Deep-read: Design-for-X target (DfS scope) | AA4: Deep-read: Self-improvement / convergence | AB4: Deep-read: Methodology | AC4: Deep-read: Data modality | AD4: Deep-read: Validation level | AE4: Deep-read: Quality appraisal score (0 to 5) | AF4: Deep-read: Thematic cluster | AG4: Deep-read: Key evidence / notes | AH4: Deep-read: Strength / research gap filled | AI4: Deep-read: Deficiencies & future work | AJ4: Deep-read: Fusion depth (AC1) | AK4: Deep-read: Fusion evidence (AC2) | AL4: Deep-read: Fusion confidence (AC3) | AM4: Fusion coding flag (review) | AN4: Full-text verification (date, source, outcome) | AO4: DOI
A5: 1 | B5: Ullah, F et al. (2026) | C5: 2026 | E5: A scoping review of green Internet of Things in construction and smart cities: current applications, adoption strategies and future directions | F5: Scopus | G5: Yes | H5: No | I5: No | J5: Yes | K5: Yes | L5: =IF(COUNTBLANK(G5:K5)=5,"",IF(COUNTIF(G5:K5,"No")>0,"EXCLUDE","INCLUDE")) -> EXCLUDE | M5: =IF(L5<>"EXCLUDE","",IF(G5="No","Wrong domain (non-AECO)",IF(H5="No","Digital Twin not core / buzzword",IF(I5="No","No Design for Safety / PtD focus",IF(J5="No","Wrong publication type",IF(K5="No","Non-English","")))))) -> Digital Twin not core / buzzword | S5: =IF(N5<>"Yes","",IF(COUNTBLANK(P5:R5)=3,"",IF(COUNTIF(P5:R5,"No")>0,"EXCLUDE","INCLUDE"))) | T5: =IF(S5<>"EXCLUDE","",IF(P5="No","Digital Twin mentioned only, not the subject",IF(Q5="No","No Design for Safety focus in full text",IF(R5="No","Methodology not codable","")))) | Y5: =IF(SUM(V5:X5)=0,"",IF(SUM(V5:X5)>=2,"Multi","Single")) | AN5: Step-1 note: G-IoT scoping review; DT only future trend, no DfS/DfQ core | AO5: 10.1108/SASBE-11-2023-0349
A6: 2 | B6: Pavón, R.M et al. (2026) | C6: 2026 | E6: Digital Twin development and implementation for the management of irrigation networks | F6: Scopus | G6: No | H6: Yes | I6: No | J6: Yes | K6: Yes | L6: =IF(COUNTBLANK(G6:K6)=5,"",IF(COUNTIF(G6:K6,"No")>0,"EXCLUDE","INCLUDE")) -> EXCLUDE | M6: =IF(L6<>"EXCLUDE","",IF(G6="No","Wrong domain (non-AECO)",IF(H6="No","Digital Twin not core / buzzword",IF(I6="No","No Design for Safety / PtD focus",IF(J6="No","Wrong publication type",IF(K6="No","Non-English","")))))) -> Wrong domain (non-AECO) | S6: =IF(N6<>"Yes","",IF(COUNTBLANK(P6:R6)=3,"",IF(COUNTIF(P6:R6,"No")>0,"EXCLUDE","INCLUDE"))) | T6: =IF(S6<>"EXCLUDE","",IF(P6="No","Digital Twin mentioned only, not the subject",IF(Q6="No","No Design for Safety focus in full text",IF(R6="No","Methodology not codable","")))) | Y6: =IF(SUM(V6:X6)=0,"",IF(SUM(V6:X6)>=2,"Multi","Single")) | AN6: Step-1 note: Irrigation networks; agriculture/water domain, no safety/quality angle | AO6: 10.1016/j.eswa.2025.129330
A7: 3 | B7: Zhu, H et al. (2025) | C7: 2025 | E7: Research on Multi-Sensor Data Fusion Based Real-Scene 3D Reconstruction and Digital Twin Visualization Methodology for Coal Mine Tunnels | F7: Scopus | G7: No | H7: Yes | I7: Yes | J7: Yes | K7: Yes | L7: =IF(COUNTBLANK(G7:K7)=5,"",IF(COUNTIF(G7:K7,"No")>0,"EXCLUDE","INCLUDE")) -> EXCLUDE | M7: =IF(L7<>"EXCLUDE","",IF(G7="No","Wrong domain (non-AECO)",IF(H7="No","Digital Twin not core / buzzword",IF(I7="No","No Design for Safety / PtD focus",IF(J7="No","Wrong publication type",IF(K7="No","Non-English","")))))) -> Wrong domain (non-AECO) | S7: =IF(N7<>"Yes","",IF(COUNTBLANK(P7:R7)=3,"",IF(COUNTIF(P7:R7,"No")>0,"EXCLUDE","INCLUDE"))) | T7: =IF(S7<>"EXCLUDE","",IF(P7="No","Digital Twin mentioned only, not the subject",IF(Q7="No","No Design for Safety focus in full text",IF(R7="No","Methodology not codable","")))) | Y7: =IF(SUM(V7:X7)=0,"",IF(SUM(V7:X7)>=2,"Multi","Single")) | AN7: Step-1 note: Coal mine tunnels; mining domain, not AECO | AO7: 10.3390/s25196153
A8: 4 | B8: Shen, Z et al. (2026) | C8: 2026 | E8: Hazard-responsive digital twin for weather-driven urban resilience and affordability | F8: Scopus | G8: Yes | H8: Yes | I8: No | J8: Yes | K8: Yes | L8: =IF(COUNTBLANK(G8:K8)=5,"",IF(COUNTIF(G8:K8,"No")>0,"EXCLUDE","INCLUDE")) -> EXCLUDE | M8: =IF(L8<>"EXCLUDE","",IF(G8="No","Wrong domain (non-AECO)",IF(H8="No","Digital Twin not core / buzzword",IF(I8="No","No Design for Safety / PtD focus",IF(J8="No","Wrong publication type",IF(K8="No","Non-English","")))))) -> No Design for Safety / PtD focus | S8: =IF(N8<>"Yes","",IF(COUNTBLANK(P8:R8)=3,"",IF(COUNTIF(P8:R8,"No")>0,"EXCLUDE","INCLUDE"))) | T8: =IF(S8<>"EXCLUDE","",IF(P8="No","Digital Twin mentioned only, not the subject",IF(Q8="No","No Design for Safety focus in full text",IF(R8="No","Methodology not codable","")))) | Y8: =IF(SUM(V8:X8)=0,"",IF(SUM(V8:X8)>=2,"Multi","Single")) | AN8: Step-1 note: Urban resilience/affordability DT; no DfS/DfQ focus | AO8: 10.1016/j.scs.2026.107413
A9: 5 | B9: Vallée, A (2026) | C9: 2026 | E9: From prediction to intervention: causal digital twins for personalized clinical decision support | F9: Scopus | G9: No | H9: Yes | I9: No | J9: Yes | K9: Yes | L9: =IF(COUNTBLANK(G9:K9)=5,"",IF(COUNTIF(G9:K9,"No")>0,"EXCLUDE","INCLUDE")) -> EXCLUDE | M9: =IF(L9<>"EXCLUDE","",IF(G9="No","Wrong domain (non-AECO)",IF(H9="No","Digital Twin not core / buzzword",IF(I9="No","No Design for Safety / PtD focus",IF(J9="No","Wrong publication type",IF(K9="No","Non-English","")))))) -> Wrong domain (non-AECO) | S9: =IF(N9<>"Yes","",IF(COUNTBLANK(P9:R9)=3,"",IF(COUNTIF(P9:R9,"No")>0,"EXCLUDE","INCLUDE"))) | T9: =IF(S9<>"EXCLUDE","",IF(P9="No","Digital Twin mentioned only, not the subject",IF(Q9="No","No Design for Safety focus in full text",IF(R9="No","Methodology not codable","")))) | Y9: =IF(SUM(V9:X9)=0,"",IF(SUM(V9:X9)>=2,"Multi","Single")) | AN9: Step-1 note: Clinical causal DT; healthcare domain | AO9: 10.1186/s12967-026-07895-8
A10: 6 | B10: Redondo, P et al. (2026) | C10: 2026 | E10: Residual dynamic spatio-temporal graph attention network for enhanced urban traffic origin/destination demand calibration | F10: Scopus | G10: No | H10: Yes | I10: No | J10: Yes | K10: Yes | L10: =IF(COUNTBLANK(G10:K10)=5,"",IF(COUNTIF(G10:K10,"No")>0,"EXCLUDE","INCLUDE")) -> EXCLUDE | M10: =IF(L10<>"EXCLUDE","",IF(G10="No","Wrong domain (non-AECO)",IF(H10="No","Digital Twin not core / buzzword",IF(I10="No","No Design for Safety / PtD focus",IF(J10="No","Wrong publication type",IF(K10="No","Non-English","")))))) -> Wrong domain (non-AECO) | S10: =IF(N10<>"Yes","",IF(COUNTBLANK(P10:R10)=3,"",IF(COUNTIF(P10:R10,"No")>0,"EXCLUDE","INCLUDE"))) | T10: =IF(S10<>"EXCLUDE","",IF(P10="No","Digital Twin mentioned only, not the subject",IF(Q10="No","No Design for Safety focus in full text",IF(R10="No","Methodology not codable","")))) | Y10: =IF(SUM(V10:X10)=0,"",IF(SUM(V10:X10)>=2,"Multi","Single")) | AN10: Step-1 note: Traffic OD calibration; SUMO as DT, not built asset | AO10: 10.1108/EC-09-2024-0900
A11: 7 | B11: Guo, X et al. (2026) | C11: 2026 | E11: Digital twin-enabled cooperative autonomous truck platooning framework for modeling, cost estimation, and decision-making in transportation systems | F11: Scopus | G11: No | H11: Yes | I11: No | J11: Yes | K11: Yes | L11: =IF(COUNTBLANK(G11:K11)=5,"",IF(COUNTIF(G11:K11,"No")>0,"EXCLUDE","INCLUDE")) -> EXCLUDE | M11: =IF(L11<>"EXCLUDE","",IF(G11="No","Wrong domain (non-AECO)",IF(H11="No","Digital Twin not core / buzzword",IF(I11="No","No Design for Safety / PtD focus",IF(J11="No","Wrong publication type",IF(K11="No","Non-English","")))))) -> Wrong domain (non-AECO) | S11: =IF(N11<>"Yes","",IF(COUNTBLANK(P11:R11)=3,"",IF(COUNTIF(P11:R11,"No")>0,"EXCLUDE","INCLUDE"))) | T11: =IF(S11<>"EXCLUDE","",IF(P11="No","Digital Twin mentioned only, not the subject",IF(Q11="No","No Design for Safety focus in full text",IF(R11="No","Methodology not codable","")))) | Y11: =IF(SUM(V11:X11)=0,"",IF(SUM(V11:X11)>=2,"Multi","Single")) | AN11: Step-1 note: Truck platooning logistics; not AECO | AO11: 10.1016/j.tre.2025.104596
A12: 8 | B12: Hong, K et al. (2025) | C12: 2025 | E12: Digital construction site layout planning and real-time trajectory analysis for proactive safety monitoring and control of struck-by hazards | F12: Scopus | G12: Yes | H12: Yes | I12: Yes | J12: Yes | K12: Yes | L12: =IF(COUNTBLANK(G12:K12)=5,"",IF(COUNTIF(G12:K12,"No")>0,"EXCLUDE","INCLUDE")) -> INCLUDE | M12: =IF(L12<>"EXCLUDE","",IF(G12="No","Wrong domain (non-AECO)",IF(H12="No","Digital Twin not core / buzzword",IF(I12="No","No Design for Safety / PtD focus",IF(J12="No","Wrong publication type",IF(K12="No","Non-English","")))))) | N12: Yes | O12: Yes | P12: Yes | Q12: Yes | R12: Yes | S12: =IF(N12<>"Yes","",IF(COUNTBLANK(P12:R12)=3,"",IF(COUNTIF(P12:R12,"No")>0,"EXCLUDE","INCLUDE"))) -> INCLUDE | T12: =IF(S12<>"EXCLUDE","",IF(P12="No","Digital Twin mentioned only, not the subject",IF(Q12="No","No Design for Safety focus in full text",IF(R12="No","Methodology not codable","")))) | U12: Tier 2 - Digital Shadow (one-way physical to virtual) | V12: 0 | W12: 1 | X12: 0 | Y12: =IF(SUM(V12:X12)=0,"",IF(SUM(V12:X12)>=2,"Multi","Single")) -> Single | Z12: Design for Safety (DfS) | AA12: None | AB12: Digital Twin platform (no machine learning) | AC12: Single (one data type) | AD12: Single case study | AE12: 4 | AF12: Design for Safety | AG12: Digital construction site layout planning and real-time trajectory analysis for proactive safety monitoring and control of struck-by hazards (DTCS Right-time Analysis and Mitigation module; DTU/TUM): RTK-GNSS + LoRa live location tracking of pedestrian workers and heavy equipment streamed to DTCS; semi-static and dynamic hazard zones (1-m boundary + operator blind-space geometry); real-time incident detection of unauthorized entry and too-close proximity; density maps / histogram heatmaps identify hazardous activities; safety-plan revision recommendations (separating worker/equipment areas, temporary pedestrian walkways); field experiments in Munich subway rail maintenance staging area showed significant reduction in spatial conflicts and improved zone connectivity, with newly detected hazards (rail traffic, delivery trucks) triggering iterative plan updates. One-way monitoring to analysis to mitigation recommendations/alerts for safety personnel; no actuation, no learning loop. [Full-text source: 04c-port] | AH12: Extends the Digital Twin for Construction Safety concept with a Right-time Analysis and Mitigation module tested at a Munich railway maintenance staging area: safeBIM rule checking plus RTK-GNSS over LoRa tracking at 1.0 cm median and 2.3 cm 95th percentile precision, detecting 99 unauthorized entries, mapping telehandler blind spots (right side obstructed to 1.9 m) and computing safety-weighted walkway routes that informed a revised safeBIM plan. | AI12: Experiments lasted a limited period in a controlled staging area, RTK-GNSS suffers signal loss and interference, and operator awareness of workers could not be recorded, so head-pose or eye-tracking data is proposed; future work includes longer data collection, other equipment types, drone-based condition capture, big data analytics and standards for safe distances. | AJ12: Single | AK12: Only RTK-GNSS over LoRa position tracking (1.0 cm median, 2.3 cm 95th percentile) drives the right-time analysis; no second measured data type exists. | AL12: High | AN12: Step-1 note: DTCS struck-by hazard monitoring; PtD planning | Coded from Step-3 deep-read markdown (DfS-only scope), imported 2026-10-04 | AO12: 10.1016/j.autcon.2025.106353
A13: 9 | B13: Oliinyk, V et al. (2025) | C13: 2025 | E13: Optimising the construction process through digitalisation: Case studies of projects under unstable resource supply | F13: Scopus | G13: Yes | H13: No | I13: No | J13: Yes | K13: Yes | L13: =IF(COUNTBLANK(G13:K13)=5,"",IF(COUNTIF(G13:K13,"No")>0,"EXCLUDE","INCLUDE")) -> EXCLUDE | M13: =IF(L13<>"EXCLUDE","",IF(G13="No","Wrong domain (non-AECO)",IF(H13="No","Digital Twin not core / buzzword",IF(I13="No","No Design for Safety / PtD focus",IF(J13="No","Wrong publication type",IF(K13="No","Non-English","")))))) -> Digital Twin not core / buzzword | S13: =IF(N13<>"Yes","",IF(COUNTBLANK(P13:R13)=3,"",IF(COUNTIF(P13:R13,"No")>0,"EXCLUDE","INCLUDE"))) | T13: =IF(S13<>"EXCLUDE","",IF(P13="No","Digital Twin mentioned only, not the subject",IF(Q13="No","No Design for Safety focus in full text",IF(R13="No","Methodology not codable","")))) | Y13: =IF(SUM(V13:X13)=0,"",IF(SUM(V13:X13)>=2,"Multi","Single")) | AN13: Step-1 note: Digitalisation overview; DT one of many technologies | AO13: 10.56318/as/1.2025.92
A14: 10 | B14: Zhao, B et al. (2026) | C14: 2026 | E14: From instance segmentation to physical quantification: High-resolution UAV-based dataset for façade defect assessment | F14: Scopus | G14: Yes | H14: No | I14: Yes | J14: Yes | K14: Yes | L14: =IF(COUNTBLANK(G14:K14)=5,"",IF(COUNTIF(G14:K14,"No")>0,"EXCLUDE","INCLUDE")) -> EXCLUDE | M14: =IF(L14<>"EXCLUDE","",IF(G14="No","Wrong domain (non-AECO)",IF(H14="No","Digital Twin not core / buzzword",IF(I14="No","No Design for Safety / PtD focus",IF(J14="No","Wrong publication type",IF(K14="No","Non-English","")))))) -> Digital Twin not core / buzzword | S14: =IF(N14<>"Yes","",IF(COUNTBLANK(P14:R14)=3,"",IF(COUNTIF(P14:R14,"No")>0,"EXCLUDE","INCLUDE"))) | T14: =IF(S14<>"EXCLUDE","",IF(P14="No","Digital Twin mentioned only, not the subject",IF(Q14="No","No Design for Safety focus in full text",IF(R14="No","Methodology not codable","")))) | Y14: =IF(SUM(V14:X14)=0,"",IF(SUM(V14:X14)>=2,"Multi","Single")) | AN14: Step-1 note: Defect dataset+segmentation; DT only deployment target | AO14: 10.1016/j.autcon.2026.106980
A15: 11 | B15: Kaewunruen, S et al. (2025) | C15: 2025 | E15: Digital twin-driven strategic demolition plan for circular asset management of bridge infrastructures | F15: Scopus | G15: Yes | H15: No | I15: No | J15: Yes | K15: Yes | L15: =IF(COUNTBLANK(G15:K15)=5,"",IF(COUNTIF(G15:K15,"No")>0,"EXCLUDE","INCLUDE")) -> EXCLUDE | M15: =IF(L15<>"EXCLUDE","",IF(G15="No","Wrong domain (non-AECO)",IF(H15="No","Digital Twin not core / buzzword",IF(I15="No","No Design for Safety / PtD focus",IF(J15="No","Wrong publication type",IF(K15="No","Non-English","")))))) -> Digital Twin not core / buzzword | S15: =IF(N15<>"Yes","",IF(COUNTBLANK(P15:R15)=3,"",IF(COUNTIF(P15:R15,"No")>0,"EXCLUDE","INCLUDE"))) | T15: =IF(S15<>"EXCLUDE","",IF(P15="No","Digital Twin mentioned only, not the subject",IF(Q15="No","No Design for Safety focus in full text",IF(R15="No","Methodology not codable","")))) | Y15: =IF(SUM(V15:X15)=0,"",IF(SUM(V15:X15)>=2,"Multi","Single")) | AN15: Step-1 note: BIM 6D circular demolition; no live DT, no DfS/DfQ | AO15: 10.1038/s41598-025-94117-8
A16: 12 | B16: Al-Sadoon, N et al. (2026) | C16: 2026 | E16: Enhancing resilience through environmental data integration in early construction planning: a cloud-based framework | F16: Scopus | G16: Yes | H16: No | I16: No | J16: Yes | K16: Yes | L16: =IF(COUNTBLANK(G16:K16)=5,"",IF(COUNTIF(G16:K16,"No")>0,"EXCLUDE","INCLUDE")) -> EXCLUDE | M16: =IF(L16<>"EXCLUDE","",IF(G16="No","Wrong domain (non-AECO)",IF(H16="No","Digital Twin not core / buzzword",IF(I16="No","No Design for Safety / PtD focus",IF(J16="No","Wrong publication type",IF(K16="No","Non-English","")))))) -> Digital Twin not core / buzzword | S16: =IF(N16<>"Yes","",IF(COUNTBLANK(P16:R16)=3,"",IF(COUNTIF(P16:R16,"No")>0,"EXCLUDE","INCLUDE"))) | T16: =IF(S16<>"EXCLUDE","",IF(P16="No","Digital Twin mentioned only, not the subject",IF(Q16="No","No Design for Safety focus in full text",IF(R16="No","Methodology not codable","")))) | Y16: =IF(SUM(V16:X16)=0,"",IF(SUM(V16:X16)>=2,"Multi","Single")) | AN16: Step-1 note: BIM-ICDD semantic linking; no DT | AO16: 10.3389/fbuil.2026.1748837
A17: 13 | B17: Jung, B et al. (2025) | C17: 2025 | E17: Transient-Aware Multi-Objective Optimization of Water Distribution Systems for Cost and Fire Flow Reliability | F17: Scopus | G17: No | H17: No | I17: Yes | J17: Yes | K17: Yes | L17: =IF(COUNTBLANK(G17:K17)=5,"",IF(COUNTIF(G17:K17,"No")>0,"EXCLUDE","INCLUDE")) -> EXCLUDE | M17: =IF(L17<>"EXCLUDE","",IF(G17="No","Wrong domain (non-AECO)",IF(H17="No","Digital Twin not core / buzzword",IF(I17="No","No Design for Safety / PtD focus",IF(J17="No","Wrong publication type",IF(K17="No","Non-English","")))))) -> Wrong domain (non-AECO) | S17: =IF(N17<>"Yes","",IF(COUNTBLANK(P17:R17)=3,"",IF(COUNTIF(P17:R17,"No")>0,"EXCLUDE","INCLUDE"))) | T17: =IF(S17<>"EXCLUDE","",IF(P17="No","Digital Twin mentioned only, not the subject",IF(Q17="No","No Design for Safety focus in full text",IF(R17="No","Methodology not codable","")))) | Y17: =IF(SUM(V17:X17)=0,"",IF(SUM(V17:X17)>=2,"Multi","Single")) | AN17: Step-1 note: Water distribution optimization; no DT, not AECO | AO17: 10.3390/su17188274
A18: 14 | B18: Sigmund, Z et al. (2026) | C18: 2026 | E18: Reducing Latency in Digital Twins: A Framework for Near-Real-Time Progress and Quality Reporting | F18: Scopus | G18: Yes | H18: Yes | I18: Yes | J18: Yes | K18: Yes | L18: =IF(COUNTBLANK(G18:K18)=5,"",IF(COUNTIF(G18:K18,"No")>0,"EXCLUDE","INCLUDE")) -> INCLUDE | M18: =IF(L18<>"EXCLUDE","",IF(G18="No","Wrong domain (non-AECO)",IF(H18="No","Digital Twin not core / buzzword",IF(I18="No","No Design for Safety / PtD focus",IF(J18="No","Wrong publication type",IF(K18="No","Non-English","")))))) | N18: Yes | O18: Yes | P18: Yes | Q18: Yes | R18: Yes | S18: =IF(N18<>"Yes","",IF(COUNTBLANK(P18:R18)=3,"",IF(COUNTIF(P18:R18,"No")>0,"EXCLUDE","INCLUDE"))) -> INCLUDE | T18: =IF(S18<>"EXCLUDE","",IF(P18="No","Digital Twin mentioned only, not the subject",IF(Q18="No","No Design for Safety focus in full text",IF(R18="No","Methodology not codable","")))) | U18: Tier 2 - Digital Shadow (one-way physical to virtual) | V18: 0 | W18: 1 | X18: 0 | Y18: =IF(SUM(V18:X18)=0,"",IF(SUM(V18:X18)>=2,"Multi","Single")) -> Single | Z18: Design for Safety (DfS) | AA18: None | AB18: Computer Vision / CNN / object-detection | AC18: Multi (two or more data types) | AD18: Conceptual (no test) | AE18: 2 | AF18: Perception / Computer Vision | AG18: Technical note (Buildings 2026, U Zagreb): proposes a tiered edge-cloud processing framework for near-real-time automated progress monitoring and quality reporting, synthesising NORMENG field metrics (terrestrial LiDAR, UAS photogrammetry, 360-degree vision); shifts to neural rendering to bypass photogrammetric latency; lightweight edge analysis for immediate safety/progress alarms plus asynchronous high-fidelity DT updates as single source of truth. Framework only - no implementation or empirical validation (informs AutoGreenTraC). One-way sensing->analysis->reporting; no actuation, no learning loop. [Full-text source: browser-oa] | AH18: Identifies data-acquisition latency and photogrammetric compute as the two bottlenecks and contributes a tiered edge-cloud hierarchy (millisecond safety alarms to asynchronous high-fidelity DT updates) with neural rendering as the latency bypass, grounded in NORMENG field metrics. | AI18: No implementation or empirical validation; latency targets, neural-rendering pipeline details and DT update scheduling remain future work in AutoGreenTraC. | AJ18: Unclear | AK18: LiDAR, SfM-MVS and 360-degree streams are discussed within a tiered hierarchy but no fusion mechanism is implemented or tested (framework only). | AL18: Low | AM18: REVIEW: fusion Unclear / Low confidence | AN18: Step-1 note: DT framework for near-real-time progress/quality reporting | Methodology label normalised (source: "Perception / Computer Vision") | Coded from Step-3 deep-read markdown (DfS-only scope), imported 2026-10-04 | AO18: 10.3390/buildings16071448
A19: 15 | B19: Cao, J et al. (2026) | C19: 2026 | E19: In-Depth Discussion on the Construction of Security Collaborative Management and Control System Based on Digital Twins and Intelligent Sensing in the United Nations Clean Coal Project | F19: Scopus | G19: No | H19: Yes | I19: Yes | J19: Yes | K19: Yes | L19: =IF(COUNTBLANK(G19:K19)=5,"",IF(COUNTIF(G19:K19,"No")>0,"EXCLUDE","INCLUDE")) -> EXCLUDE | M19: =IF(L19<>"EXCLUDE","",IF(G19="No","Wrong domain (non-AECO)",IF(H19="No","Digital Twin not core / buzzword",IF(I19="No","No Design for Safety / PtD focus",IF(J19="No","Wrong publication type",IF(K19="No","Non-English","")))))) -> Wrong domain (non-AECO) | S19: =IF(N19<>"Yes","",IF(COUNTBLANK(P19:R19)=3,"",IF(COUNTIF(P19:R19,"No")>0,"EXCLUDE","INCLUDE"))) | T19: =IF(S19<>"EXCLUDE","",IF(P19="No","Digital Twin mentioned only, not the subject",IF(Q19="No","No Design for Safety focus in full text",IF(R19="No","Methodology not codable","")))) | Y19: =IF(SUM(V19:X19)=0,"",IF(SUM(V19:X19)>=2,"Multi","Single")) | AN19: Step-1 note: Clean coal industrial project; not AECO built asset | AO19: 10.7716/aem.v15i3.3430
A20: 16 | B20: Kanyilmaz, A et al. (2026) | C20: 2026 | E20: AI-driven assessment of steel structures | F20: Scopus | G20: Yes | H20: No | I20: Yes | J20: Yes | K20: Yes | L20: =IF(COUNTBLANK(G20:K20)=5,"",IF(COUNTIF(G20:K20,"No")>0,"EXCLUDE","INCLUDE")) -> EXCLUDE | M20: =IF(L20<>"EXCLUDE","",IF(G20="No","Wrong domain (non-AECO)",IF(H20="No","Digital Twin not core / buzzword",IF(I20="No","No Design for Safety / PtD focus",IF(J20="No","Wrong publication type",IF(K20="No","Non-English","")))))) -> Digital Twin not core / buzzword | S20: =IF(N20<>"Yes","",IF(COUNTBLANK(P20:R20)=3,"",IF(COUNTIF(P20:R20,"No")>0,"EXCLUDE","INCLUDE"))) | T20: =IF(S20<>"EXCLUDE","",IF(P20="No","Digital Twin mentioned only, not the subject",IF(Q20="No","No Design for Safety focus in full text",IF(R20="No","Methodology not codable","")))) | Y20: =IF(SUM(V20:X20)=0,"",IF(SUM(V20:X20)>=2,"Multi","Single")) | AN20: Step-1 note: AI assessment case-study review; DT one of several methods | AO20: 10.1002/stab.70174
A21: 17 | B21: Casini, M (2026) | C21: 2026 | E21: From WebGIS to a Digital Twin for Sustainable Water Governance and Climate-Resilient River Basin District Planning: The AUBAC Case in Central Italy | F21: Scopus | G21: No | H21: Yes | I21: No | J21: Yes | K21: Yes | L21: =IF(COUNTBLANK(G21:K21)=5,"",IF(COUNTIF(G21:K21,"No")>0,"EXCLUDE","INCLUDE")) -> EXCLUDE | M21: =IF(L21<>"EXCLUDE","",IF(G21="No","Wrong domain (non-AECO)",IF(H21="No","Digital Twin not core / buzzword",IF(I21="No","No Design for Safety / PtD focus",IF(J21="No","Wrong publication type",IF(K21="No","Non-English","")))))) -> Wrong domain (non-AECO) | S21: =IF(N21<>"Yes","",IF(COUNTBLANK(P21:R21)=3,"",IF(COUNTIF(P21:R21,"No")>0,"EXCLUDE","INCLUDE"))) | T21: =IF(S21<>"EXCLUDE","",IF(P21="No","Digital Twin mentioned only, not the subject",IF(Q21="No","No Design for Safety focus in full text",IF(R21="No","Methodology not codable","")))) | Y21: =IF(SUM(V21:X21)=0,"",IF(SUM(V21:X21)>=2,"Multi","Single")) | AN21: Step-1 note: River-basin water governance; not built asset | AO21: 10.3390/su18052168
A22: 18 | B22: Gao, K et al. (2026) | C22: 2026 | E22: Resilient ventilation network construction in complex underground mining environments: A holistic strategy from resilience perception to resilience enhancement | F22: Scopus | G22: No | H22: Yes | I22: Yes | J22: Yes | K22: Yes | L22: =IF(COUNTBLANK(G22:K22)=5,"",IF(COUNTIF(G22:K22,"No")>0,"EXCLUDE","INCLUDE")) -> EXCLUDE | M22: =IF(L22<>"EXCLUDE","",IF(G22="No","Wrong domain (non-AECO)",IF(H22="No","Digital Twin not core / buzzword",IF(I22="No","No Design for Safety / PtD focus",IF(J22="No","Wrong publication type",IF(K22="No","Non-English","")))))) -> Wrong domain (non-AECO) | S22: =IF(N22<>"Yes","",IF(COUNTBLANK(P22:R22)=3,"",IF(COUNTIF(P22:R22,"No")>0,"EXCLUDE","INCLUDE"))) | T22: =IF(S22<>"EXCLUDE","",IF(P22="No","Digital Twin mentioned only, not the subject",IF(Q22="No","No Design for Safety focus in full text",IF(R22="No","Methodology not codable","")))) | Y22: =IF(SUM(V22:X22)=0,"",IF(SUM(V22:X22)>=2,"Multi","Single")) | AN22: Step-1 note: Mine ventilation resilience; mining domain | AO22: 10.1016/j.ress.2026.112634
A23: 19 | B23: Wang, G et al. (2025) | C23: 2025 | E23: Research on modeling and application of digital twin system for mine auxiliary transportation | F23: Scopus | G23: No | H23: Yes | I23: Yes | J23: Yes | K23: Yes | L23: =IF(COUNTBLANK(G23:K23)=5,"",IF(COUNTIF(G23:K23,"No")>0,"EXCLUDE","INCLUDE")) -> EXCLUDE | M23: =IF(L23<>"EXCLUDE","",IF(G23="No","Wrong domain (non-AECO)",IF(H23="No","Digital Twin not core / buzzword",IF(I23="No","No Design for Safety / PtD focus",IF(J23="No","Wrong publication type",IF(K23="No","Non-English","")))))) -> Wrong domain (non-AECO) | S23: =IF(N23<>"Yes","",IF(COUNTBLANK(P23:R23)=3,"",IF(COUNTIF(P23:R23,"No")>0,"EXCLUDE","INCLUDE"))) | T23: =IF(S23<>"EXCLUDE","",IF(P23="No","Digital Twin mentioned only, not the subject",IF(Q23="No","No Design for Safety focus in full text",IF(R23="No","Methodology not codable","")))) | Y23: =IF(SUM(V23:X23)=0,"",IF(SUM(V23:X23)>=2,"Multi","Single")) | AN23: Step-1 note: Mine auxiliary transport DT; mining domain | AO23: 10.1142/S1793962325500618
A24: 20 | B24: Zheng, H et al. (2026) | C24: 2026 | E24: Photorealistic Fire Scene Video Generation via Multimodal Large Language Model and Pre-Trained Video Diffusion Model | F24: Scopus | G24: No | H24: No | I24: No | J24: Yes | K24: Yes | L24: =IF(COUNTBLANK(G24:K24)=5,"",IF(COUNTIF(G24:K24,"No")>0,"EXCLUDE","INCLUDE")) -> EXCLUDE | M24: =IF(L24<>"EXCLUDE","",IF(G24="No","Wrong domain (non-AECO)",IF(H24="No","Digital Twin not core / buzzword",IF(I24="No","No Design for Safety / PtD focus",IF(J24="No","Wrong publication type",IF(K24="No","Non-English","")))))) -> Wrong domain (non-AECO) | S24: =IF(N24<>"Yes","",IF(COUNTBLANK(P24:R24)=3,"",IF(COUNTIF(P24:R24,"No")>0,"EXCLUDE","INCLUDE"))) | T24: =IF(S24<>"EXCLUDE","",IF(P24="No","Digital Twin mentioned only, not the subject",IF(Q24="No","No Design for Safety focus in full text",IF(R24="No","Methodology not codable","")))) | Y24: =IF(SUM(V24:X24)=0,"",IF(SUM(V24:X24)>=2,"Multi","Single")) | AN24: Step-1 note: Text-to-video fire generation; DT only future use | AO24: 10.26599/CVM.2025.9450511
A25: 21 | B25: Mahomed, A.S et al. (2025) | C25: 2025 | E25: Unleashing the Potential of 5G for Smart Cities: A Focus on Real-Time Digital Twin Integration | F25: Scopus | G25: Yes | H25: No | I25: No | J25: Yes | K25: Yes | L25: =IF(COUNTBLANK(G25:K25)=5,"",IF(COUNTIF(G25:K25,"No")>0,"EXCLUDE","INCLUDE")) -> EXCLUDE | M25: =IF(L25<>"EXCLUDE","",IF(G25="No","Wrong domain (non-AECO)",IF(H25="No","Digital Twin not core / buzzword",IF(I25="No","No Design for Safety / PtD focus",IF(J25="No","Wrong publication type",IF(K25="No","Non-English","")))))) -> Digital Twin not core / buzzword | S25: =IF(N25<>"Yes","",IF(COUNTBLANK(P25:R25)=3,"",IF(COUNTIF(P25:R25,"No")>0,"EXCLUDE","INCLUDE"))) | T25: =IF(S25<>"EXCLUDE","",IF(P25="No","Digital Twin mentioned only, not the subject",IF(Q25="No","No Design for Safety focus in full text",IF(R25="No","Methodology not codable","")))) | Y25: =IF(SUM(V25:X25)=0,"",IF(SUM(V25:X25)>=2,"Multi","Single")) | AN25: Step-1 note: 5G smart-city review; DT beneficiary, safety peripheral | AO25: 10.3390/smartcities8020070
A26: 22 | B26: Seng, N.H et al. (2025) | C26: 2025 | E26: Mapping the Evolution of 4D BIM in Construction Digitalisation: A Scientometric Analysis and Review | F26: Scopus | G26: Yes | H26: No | I26: No | J26: Yes | K26: Yes | L26: =IF(COUNTBLANK(G26:K26)=5,"",IF(COUNTIF(G26:K26,"No")>0,"EXCLUDE","INCLUDE")) -> EXCLUDE | M26: =IF(L26<>"EXCLUDE","",IF(G26="No","Wrong domain (non-AECO)",IF(H26="No","Digital Twin not core / buzzword",IF(I26="No","No Design for Safety / PtD focus",IF(J26="No","Wrong publication type",IF(K26="No","Non-English","")))))) -> Digital Twin not core / buzzword | S26: =IF(N26<>"Yes","",IF(COUNTBLANK(P26:R26)=3,"",IF(COUNTIF(P26:R26,"No")>0,"EXCLUDE","INCLUDE"))) | T26: =IF(S26<>"EXCLUDE","",IF(P26="No","Digital Twin mentioned only, not the subject",IF(Q26="No","No Design for Safety focus in full text",IF(R26="No","Methodology not codable","")))) | Y26: =IF(SUM(V26:X26)=0,"",IF(SUM(V26:X26)>=2,"Multi","Single")) | AN26: Step-1 note: 4D BIM scientometric; no DT core | AO26: 10.17576/jkukm-2025-37(6)-11
A27: 23 | B27: Cui, X (2026) | C27: 2026 | E27: Artificial intelligence assisted structural realignment of high-rise buildings through lifting, grouting and reinforcement | F27: Scopus | G27: Yes | H27: No | I27: Yes | J27: Yes | K27: Yes | L27: =IF(COUNTBLANK(G27:K27)=5,"",IF(COUNTIF(G27:K27,"No")>0,"EXCLUDE","INCLUDE")) -> EXCLUDE | M27: =IF(L27<>"EXCLUDE","",IF(G27="No","Wrong domain (non-AECO)",IF(H27="No","Digital Twin not core / buzzword",IF(I27="No","No Design for Safety / PtD focus",IF(J27="No","Wrong publication type",IF(K27="No","Non-English","")))))) -> Digital Twin not core / buzzword | S27: =IF(N27<>"Yes","",IF(COUNTBLANK(P27:R27)=3,"",IF(COUNTIF(P27:R27,"No")>0,"EXCLUDE","INCLUDE"))) | T27: =IF(S27<>"EXCLUDE","",IF(P27="No","Digital Twin mentioned only, not the subject",IF(Q27="No","No Design for Safety focus in full text",IF(R27="No","Methodology not codable","")))) | Y27: =IF(SUM(V27:X27)=0,"",IF(SUM(V27:X27)>=2,"Multi","Single")) | AN27: Step-1 note: AI rectification scoping review; DT one element | AO27: 10.1038/s41598-026-48789-5
A28: 24 | B28: Ammairih, A (2025) | C28: 2025 | E28: A methodological approach to hybrid AI systems for real-time infrastructure monitoring in civil engineering | F28: Scopus | G28: Yes | H28: No | I28: Yes | J28: Yes | K28: Yes | L28: =IF(COUNTBLANK(G28:K28)=5,"",IF(COUNTIF(G28:K28,"No")>0,"EXCLUDE","INCLUDE")) -> EXCLUDE | M28: =IF(L28<>"EXCLUDE","",IF(G28="No","Wrong domain (non-AECO)",IF(H28="No","Digital Twin not core / buzzword",IF(I28="No","No Design for Safety / PtD focus",IF(J28="No","Wrong publication type",IF(K28="No","Non-English","")))))) -> Digital Twin not core / buzzword | S28: =IF(N28<>"Yes","",IF(COUNTBLANK(P28:R28)=3,"",IF(COUNTIF(P28:R28,"No")>0,"EXCLUDE","INCLUDE"))) | T28: =IF(S28<>"EXCLUDE","",IF(P28="No","Digital Twin mentioned only, not the subject",IF(Q28="No","No Design for Safety focus in full text",IF(R28="No","Methodology not codable","")))) | Y28: =IF(SUM(V28:X28)=0,"",IF(SUM(V28:X28)>=2,"Multi","Single")) | AN28: Step-1 note: Hybrid AI SHM framework; no DT built | AO28: 10.1007/s42107-025-01409-5
A29: 25 | B29: Zhou, X et al. (2025) | C29: 2025 | E29: Scheme and algorithm designs for optical fiber sensors based configuration inversion of umbilical cables in deep-water | F29: Scopus | G29: No | H29: No | I29: Yes | J29: Yes | K29: Yes | L29: =IF(COUNTBLANK(G29:K29)=5,"",IF(COUNTIF(G29:K29,"No")>0,"EXCLUDE","INCLUDE")) -> EXCLUDE | M29: =IF(L29<>"EXCLUDE","",IF(G29="No","Wrong domain (non-AECO)",IF(H29="No","Digital Twin not core / buzzword",IF(I29="No","No Design for Safety / PtD focus",IF(J29="No","Wrong publication type",IF(K29="No","Non-English","")))))) -> Wrong domain (non-AECO) | S29: =IF(N29<>"Yes","",IF(COUNTBLANK(P29:R29)=3,"",IF(COUNTIF(P29:R29,"No")>0,"EXCLUDE","INCLUDE"))) | T29: =IF(S29<>"EXCLUDE","",IF(P29="No","Digital Twin mentioned only, not the subject",IF(Q29="No","No Design for Safety focus in full text",IF(R29="No","Methodology not codable","")))) | Y29: =IF(SUM(V29:X29)=0,"",IF(SUM(V29:X29)>=2,"Multi","Single")) | AN29: Step-1 note: Deep-water umbilical cables; marine, not AECO | AO29: 10.1016/j.oceaneng.2025.121363
A30: 26 | B30: Han, F et al. (2026) | C30: 2026 | E30: Construction Path of Shanghai Oriental Hub Municipal Pipeline Full Cycle Digital Twin Platform | F30: Scopus | G30: Yes | H30: Yes | I30: Yes | J30: Yes | K30: Yes | L30: =IF(COUNTBLANK(G30:K30)=5,"",IF(COUNTIF(G30:K30,"No")>0,"EXCLUDE","INCLUDE")) -> INCLUDE | M30: =IF(L30<>"EXCLUDE","",IF(G30="No","Wrong domain (non-AECO)",IF(H30="No","Digital Twin not core / buzzword",IF(I30="No","No Design for Safety / PtD focus",IF(J30="No","Wrong publication type",IF(K30="No","Non-English","")))))) | N30: Yes | O30: Yes | P30: Yes | Q30: Yes | R30: Yes | S30: =IF(N30<>"Yes","",IF(COUNTBLANK(P30:R30)=3,"",IF(COUNTIF(P30:R30,"No")>0,"EXCLUDE","INCLUDE"))) -> INCLUDE | T30: =IF(S30<>"EXCLUDE","",IF(P30="No","Digital Twin mentioned only, not the subject",IF(Q30="No","No Design for Safety focus in full text",IF(R30="No","Methodology not codable","")))) | U30: Tier 2 - Digital Shadow (one-way physical to virtual) | V30: 1 | W30: 1 | X30: 1 | Y30: =IF(SUM(V30:X30)=0,"",IF(SUM(V30:X30)>=2,"Multi","Single")) -> Multi | Z30: Design for Safety (DfS) | AA30: None | AB30: Other / Mixed | AC30: Multi (two or more data types) | AD30: Single case study | AE30: 4 | AF30: Lifecycle / governance | AG30: Full-cycle municipal pipeline DT platform (Shanghai Oriental Hub): BIM0–BIM6 full-phase connection + lightweight BIM-GIS, 28 IoT sensing nodes (water pressure, gas leakage, surface temp, <1 s delay) with 5-month pilot; addresses planning collision risks, construction rework, and delayed leakage detection; AI risk model predicted a valve aging risk 7 days in advance (verified on-site); 36.4% O&M cost reduction. One-way IoT→platform monitoring/decision support, no actuation and no self-improvement loop. [Full-text source: 04c-port] | AH30: Fills the gap between macro city-level twin frameworks and single-phase pipeline platforms with a full-cycle BIM0 to BIM6 plus lightweight BIM-GIS architecture for the Shanghai Oriental Hub; a 5-month pilot deployed 28 IoT nodes (pressure, gas leakage, surface temperature) with under 1 s delay, raising planning collision detection from 68 to 97 percent and predicting one valve aging risk 7 days in advance. | AI30: The pilot covers only water supply and gas pipelines, lacking power and communication monitoring modules, and its data is not yet connected to Pudong Airport systems for cross-node emergency linkage; multi-type pipeline adaptability and cross-departmental data interface standards are stated as future work. | AJ30: Aligned | AK30: Twenty-eight IoT sensing nodes (water pressure, gas leakage, surface temperature) are mapped into a lightweight BIM-GIS platform, and the AI risk model predicts per-asset (valve aging) rather than fusing streams. | AL30: Medium | AN30: Step-1 note: Full-cycle municipal pipeline DT; safe operation focus | Coded from Step-3 deep-read markdown (DfS-only scope), imported 2026-10-04 | AO30: 10.1155/adce/8916300
A31: 27 | B31: Carlini, B et al. (2025) | C31: 2025 | E31: Enhancing climate resilience in urban areas through satellite data: A case study of flood mapping during a rainfall event in Tuscany, Italy | F31: Scopus | G31: Yes | H31: No | I31: Yes | J31: Yes | K31: Yes | L31: =IF(COUNTBLANK(G31:K31)=5,"",IF(COUNTIF(G31:K31,"No")>0,"EXCLUDE","INCLUDE")) -> EXCLUDE | M31: =IF(L31<>"EXCLUDE","",IF(G31="No","Wrong domain (non-AECO)",IF(H31="No","Digital Twin not core / buzzword",IF(I31="No","No Design for Safety / PtD focus",IF(J31="No","Wrong publication type",IF(K31="No","Non-English","")))))) -> Digital Twin not core / buzzword | S31: =IF(N31<>"Yes","",IF(COUNTBLANK(P31:R31)=3,"",IF(COUNTIF(P31:R31,"No")>0,"EXCLUDE","INCLUDE"))) | T31: =IF(S31<>"EXCLUDE","",IF(P31="No","Digital Twin mentioned only, not the subject",IF(Q31="No","No Design for Safety focus in full text",IF(R31="No","Methodology not codable","")))) | Y31: =IF(SUM(V31:X31)=0,"",IF(SUM(V31:X31)>=2,"Multi","Single")) | AN31: Step-1 note: SAR flood mapping; GIS DT only supporting tool | AO31: 10.1016/j.heliyon.2025.e44108
A32: 28 | B32: Jian, R et al. (2026) | C32: 2026 | E32: BIM-GIS Integration for Collaborative Management in Complex Highway Engineering Projects | F32: Scopus | G32: Yes | H32: No | I32: Yes | J32: Yes | K32: Yes | L32: =IF(COUNTBLANK(G32:K32)=5,"",IF(COUNTIF(G32:K32,"No")>0,"EXCLUDE","INCLUDE")) -> EXCLUDE | M32: =IF(L32<>"EXCLUDE","",IF(G32="No","Wrong domain (non-AECO)",IF(H32="No","Digital Twin not core / buzzword",IF(I32="No","No Design for Safety / PtD focus",IF(J32="No","Wrong publication type",IF(K32="No","Non-English","")))))) -> Digital Twin not core / buzzword | S32: =IF(N32<>"Yes","",IF(COUNTBLANK(P32:R32)=3,"",IF(COUNTIF(P32:R32,"No")>0,"EXCLUDE","INCLUDE"))) | T32: =IF(S32<>"EXCLUDE","",IF(P32="No","Digital Twin mentioned only, not the subject",IF(Q32="No","No Design for Safety focus in full text",IF(R32="No","Methodology not codable","")))) | Y32: =IF(SUM(V32:X32)=0,"",IF(SUM(V32:X32)>=2,"Multi","Single")) | AN32: Step-1 note: BIM-GIS highway loop; DT integration future only | AO32: 10.4018/IJAEIS.414579
A33: 29 | B33: Choi, W.G et al. (2026) | C33: 2026 | E33: MirrorLake: A Digital Twin Platform for Real-Time Synchronization with the Real World | F33: Scopus | G33: No | H33: Yes | I33: No | J33: Yes | K33: Yes | L33: =IF(COUNTBLANK(G33:K33)=5,"",IF(COUNTIF(G33:K33,"No")>0,"EXCLUDE","INCLUDE")) -> EXCLUDE | M33: =IF(L33<>"EXCLUDE","",IF(G33="No","Wrong domain (non-AECO)",IF(H33="No","Digital Twin not core / buzzword",IF(I33="No","No Design for Safety / PtD focus",IF(J33="No","Wrong publication type",IF(K33="No","Non-English","")))))) -> Wrong domain (non-AECO) | S33: =IF(N33<>"Yes","",IF(COUNTBLANK(P33:R33)=3,"",IF(COUNTIF(P33:R33,"No")>0,"EXCLUDE","INCLUDE"))) | T33: =IF(S33<>"EXCLUDE","",IF(P33="No","Digital Twin mentioned only, not the subject",IF(Q33="No","No Design for Safety focus in full text",IF(R33="No","Methodology not codable","")))) | Y33: =IF(SUM(V33:X33)=0,"",IF(SUM(V33:X33)>=2,"Multi","Single")) | AN33: Step-1 note: Generic DT platform; AECO application unspecified | AO33: 10.1109/ACCESS.2026.3680878
A34: 30 | B34: Liu, W et al. (2026) | C34: 2026 | E34: Digital twin-enabled safety management: A bibliometric and knowledge mapping analysis with core challenge insights | F34: Scopus | G34: No | H34: Yes | I34: Yes | J34: Yes | K34: Yes | L34: =IF(COUNTBLANK(G34:K34)=5,"",IF(COUNTIF(G34:K34,"No")>0,"EXCLUDE","INCLUDE")) -> EXCLUDE | M34: =IF(L34<>"EXCLUDE","",IF(G34="No","Wrong domain (non-AECO)",IF(H34="No","Digital Twin not core / buzzword",IF(I34="No","No Design for Safety / PtD focus",IF(J34="No","Wrong publication type",IF(K34="No","Non-English","")))))) -> Wrong domain (non-AECO) | S34: =IF(N34<>"Yes","",IF(COUNTBLANK(P34:R34)=3,"",IF(COUNTIF(P34:R34,"No")>0,"EXCLUDE","INCLUDE"))) | T34: =IF(S34<>"EXCLUDE","",IF(P34="No","Digital Twin mentioned only, not the subject",IF(Q34="No","No Design for Safety focus in full text",IF(R34="No","Methodology not codable","")))) | Y34: =IF(SUM(V34:X34)=0,"",IF(SUM(V34:X34)>=2,"Multi","Single")) | AN34: Step-1 note: Process-industry DT-safety bibliometric; not AECO | AO34: 10.1016/j.jlp.2026.106105
A35: 31 | B35: Manocha, A et al. (2025) | C35: 2025 | E35: Enhancing sensor data reliability in structural health monitoring systems using digital twin technology | F35: Scopus | G35: Yes | H35: Yes | I35: Yes | J35: Yes | K35: Yes | L35: =IF(COUNTBLANK(G35:K35)=5,"",IF(COUNTIF(G35:K35,"No")>0,"EXCLUDE","INCLUDE")) -> INCLUDE | M35: =IF(L35<>"EXCLUDE","",IF(G35="No","Wrong domain (non-AECO)",IF(H35="No","Digital Twin not core / buzzword",IF(I35="No","No Design for Safety / PtD focus",IF(J35="No","Wrong publication type",IF(K35="No","Non-English","")))))) | N35: Yes | O35: Yes | P35: Yes | Q35: Yes | R35: Yes | S35: =IF(N35<>"Yes","",IF(COUNTBLANK(P35:R35)=3,"",IF(COUNTIF(P35:R35,"No")>0,"EXCLUDE","INCLUDE"))) -> INCLUDE | T35: =IF(S35<>"EXCLUDE","",IF(P35="No","Digital Twin mentioned only, not the subject",IF(Q35="No","No Design for Safety focus in full text",IF(R35="No","Methodology not codable","")))) | U35: Tier 2 - Digital Shadow (one-way physical to virtual) | V35: 0 | W35: 0 | X35: 1 | Y35: =IF(SUM(V35:X35)=0,"",IF(SUM(V35:X35)>=2,"Multi","Single")) -> Single | Z35: Design for Safety (DfS) | AA35: Implemented | AB35: Bayesian / probabilistic | AC35: Multi (two or more data types) | AD35: Single case study | AE35: 4 | AF35: Predictive analytics / decision support | AG35: cDTSHD structural-health DT framework links building smart sensors, cloud platform, virtual model and weighted Naive Bayes value-of-structural-health analysis to identify anomalies and building-health risk from irregular sensor data. Case-study validation tests the DT/cloud platform for real-time SHM; no actuation. [Full-text source: browser-oa] | AH35: Adds a sensor-data reliability layer to DT-enabled SHM, using weighted Naive Bayes and value-of-structural-health analysis to reduce misleading decisions from degraded sensors. | AI35: The demonstration is mainly one case/numerical SHM setup; broader building types, sensor suites, long-term drift and quantified false-alarm behaviour need validation. | AJ35: Fused | AK35: Building smart-sensor streams, cloud SHM data and virtual structural-health state are fused through weighted Naive Bayes and value-of-structural-health change analysis. | AL35: High | AN35: Step-1 note: DT + W-BBN for SHM sensor-data reliability incl. buildings | Coded from Step-3 deep-read markdown (DfS-only scope), imported 2026-10-04 | AO35: 10.1002/suco.202400969
A36: 32 | B36: Marangwanda, G.T et al. (2026) | C36: 2026 | E36: Development of a Boiler Monitoring System for Predictive Maintenance of Boiler Tube Failures | F36: Scopus | G36: No | H36: Yes | I36: Yes | J36: Yes | K36: Yes | L36: =IF(COUNTBLANK(G36:K36)=5,"",IF(COUNTIF(G36:K36,"No")>0,"EXCLUDE","INCLUDE")) -> EXCLUDE | M36: =IF(L36<>"EXCLUDE","",IF(G36="No","Wrong domain (non-AECO)",IF(H36="No","Digital Twin not core / buzzword",IF(I36="No","No Design for Safety / PtD focus",IF(J36="No","Wrong publication type",IF(K36="No","Non-English","")))))) -> Wrong domain (non-AECO) | S36: =IF(N36<>"Yes","",IF(COUNTBLANK(P36:R36)=3,"",IF(COUNTIF(P36:R36,"No")>0,"EXCLUDE","INCLUDE"))) | T36: =IF(S36<>"EXCLUDE","",IF(P36="No","Digital Twin mentioned only, not the subject",IF(Q36="No","No Design for Safety focus in full text",IF(R36="No","Methodology not codable","")))) | Y36: =IF(SUM(V36:X36)=0,"",IF(SUM(V36:X36)>=2,"Multi","Single")) | AN36: Step-1 note: Power-plant boiler monitoring; not AECO | AO36: 10.1115/1.4071543
A37: 33 | B37: Luning, X et al. (2025) | C37: 2025 | E37: Inversion model of stress state reconstruction for geological hazard pipelines based on digital twin | F37: Scopus | G37: No | H37: Yes | I37: Yes | J37: Yes | K37: Yes | L37: =IF(COUNTBLANK(G37:K37)=5,"",IF(COUNTIF(G37:K37,"No")>0,"EXCLUDE","INCLUDE")) -> EXCLUDE | M37: =IF(L37<>"EXCLUDE","",IF(G37="No","Wrong domain (non-AECO)",IF(H37="No","Digital Twin not core / buzzword",IF(I37="No","No Design for Safety / PtD focus",IF(J37="No","Wrong publication type",IF(K37="No","Non-English","")))))) -> Wrong domain (non-AECO) | S37: =IF(N37<>"Yes","",IF(COUNTBLANK(P37:R37)=3,"",IF(COUNTIF(P37:R37,"No")>0,"EXCLUDE","INCLUDE"))) | T37: =IF(S37<>"EXCLUDE","",IF(P37="No","Digital Twin mentioned only, not the subject",IF(Q37="No","No Design for Safety focus in full text",IF(R37="No","Methodology not codable","")))) | Y37: =IF(SUM(V37:X37)=0,"",IF(SUM(V37:X37)>=2,"Multi","Single")) | AN37: Step-1 note: Energy pipeline geohazard DT; not AECO | AO37: 10.1007/s42452-025-07435-x
A38: 34 | B38: Čaleta, D (2025) | C38: 2025 | E38: International Dimension of Critical Infrastructure Resilience: Challenges of the Mediterranean Security Environment | F38: Scopus | G38: Yes | H38: No | I38: No | J38: Yes | K38: Yes | L38: =IF(COUNTBLANK(G38:K38)=5,"",IF(COUNTIF(G38:K38,"No")>0,"EXCLUDE","INCLUDE")) -> EXCLUDE | M38: =IF(L38<>"EXCLUDE","",IF(G38="No","Wrong domain (non-AECO)",IF(H38="No","Digital Twin not core / buzzword",IF(I38="No","No Design for Safety / PtD focus",IF(J38="No","Wrong publication type",IF(K38="No","Non-English","")))))) -> Digital Twin not core / buzzword | S38: =IF(N38<>"Yes","",IF(COUNTBLANK(P38:R38)=3,"",IF(COUNTIF(P38:R38,"No")>0,"EXCLUDE","INCLUDE"))) | T38: =IF(S38<>"EXCLUDE","",IF(P38="No","Digital Twin mentioned only, not the subject",IF(Q38="No","No Design for Safety focus in full text",IF(R38="No","Methodology not codable","")))) | Y38: =IF(SUM(V38:X38)=0,"",IF(SUM(V38:X38)>=2,"Multi","Single")) | AN38: Step-1 note: CI resilience policy paper; no DT | AO38: 10.70908/2232-6022/18.177-205
A39: 35 | B39: Matsuk, Z et al. (2026) | C39: 2026 | E39: SYMMETRIC APPROACH TO INDUSTRIAL SAFETY RISK ASSESSMENT BASED ON MUTUAL PROBABILITY CORRESPONDENCE | F39: Scopus | G39: No | H39: No | I39: Yes | J39: Yes | K39: Yes | L39: =IF(COUNTBLANK(G39:K39)=5,"",IF(COUNTIF(G39:K39,"No")>0,"EXCLUDE","INCLUDE")) -> EXCLUDE | M39: =IF(L39<>"EXCLUDE","",IF(G39="No","Wrong domain (non-AECO)",IF(H39="No","Digital Twin not core / buzzword",IF(I39="No","No Design for Safety / PtD focus",IF(J39="No","Wrong publication type",IF(K39="No","Non-English","")))))) -> Wrong domain (non-AECO) | S39: =IF(N39<>"Yes","",IF(COUNTBLANK(P39:R39)=3,"",IF(COUNTIF(P39:R39,"No")>0,"EXCLUDE","INCLUDE"))) | T39: =IF(S39<>"EXCLUDE","",IF(P39="No","Digital Twin mentioned only, not the subject",IF(Q39="No","No Design for Safety focus in full text",IF(R39="No","Methodology not codable","")))) | Y39: =IF(SUM(V39:X39)=0,"",IF(SUM(V39:X39)>=2,"Multi","Single")) | AN39: Step-1 note: Industrial safety Bayesian network; not AECO | AO39: 10.15587/2706-5448.2026.353068
A40: 36 | B40: Kim, J et al. (2026) | C40: 2026 | E40: Active gravity-aligned reference Axis for high-precision verticality assessment in construction | F40: Scopus | G40: Yes | H40: No | I40: Yes | J40: Yes | K40: Yes | L40: =IF(COUNTBLANK(G40:K40)=5,"",IF(COUNTIF(G40:K40,"No")>0,"EXCLUDE","INCLUDE")) -> EXCLUDE | M40: =IF(L40<>"EXCLUDE","",IF(G40="No","Wrong domain (non-AECO)",IF(H40="No","Digital Twin not core / buzzword",IF(I40="No","No Design for Safety / PtD focus",IF(J40="No","Wrong publication type",IF(K40="No","Non-English","")))))) -> Digital Twin not core / buzzword | S40: =IF(N40<>"Yes","",IF(COUNTBLANK(P40:R40)=3,"",IF(COUNTIF(P40:R40,"No")>0,"EXCLUDE","INCLUDE"))) | T40: =IF(S40<>"EXCLUDE","",IF(P40="No","Digital Twin mentioned only, not the subject",IF(Q40="No","No Design for Safety focus in full text",IF(R40="No","Methodology not codable","")))) | Y40: =IF(SUM(V40:X40)=0,"",IF(SUM(V40:X40)>=2,"Multi","Single")) | AN40: Step-1 note: Verticality sensing device; no DT | AO40: 10.1016/j.autcon.2026.107025
...

Sheet Step1_Report
A1: STEP 1 & PRISMA - screening outcomes (auto)
A3: PRISMA stage | B3: n
A4: Records identified (in matrix) | B4: =COUNTA(Matrix!$A$5:$A$960) -> 956
A5: Records screened (Stage-1 decided) | B5: =COUNTIF(Matrix!$L$5:$L$960,"INCLUDE")+COUNTIF(Matrix!$L$5:$L$960,"EXCLUDE") -> 956
A6: Excluded at Stage-1 (title/abstract) | B6: =COUNTIF(Matrix!$L$5:$L$960,"EXCLUDE") -> 712
A7: Stage-1 INCLUDE -> sought for retrieval | B7: =COUNTIF(Matrix!$L$5:$L$960,"INCLUDE") -> 244
A8: PDF full text on hand (gateway = Yes) | B8: =COUNTIFS(Matrix!$L$5:$L$960,"INCLUDE",Matrix!$N$5:$N$960,"Yes") -> 240
A9: PDF not yet on hand (revisit later) | B9: =COUNTIFS(Matrix!$L$5:$L$960,"INCLUDE",Matrix!$N$5:$N$960,"No") -> 4
A10: Reports assessed for eligibility (full text) | B10: =COUNTIFS(Matrix!$N$5:$N$960,"Yes",Matrix!$S$5:$S$960,"INCLUDE")+COUNTIFS(Matrix!$N$5:$N$960,"Yes",Matrix!$S$5:$S$960,"EXCLUDE") -> 240
A11: Excluded at Stage-2 (full text, with reasons) | B11: =COUNTIF(Matrix!$S$5:$S$960,"EXCLUDE") -> 18
A12: STUDIES INCLUDED IN SYNTHESIS | B12: =COUNTIF(Matrix!$S$5:$S$960,"INCLUDE") -> 222
A14: Stage-1 exclusion reasons
A15: Reason | B15: n
A16: Wrong domain (non-AECO) | B16: =COUNTIF(Matrix!$M$5:$M$960,"Wrong domain (non-AECO)") -> 415
A17: Digital Twin not core / buzzword | B17: =COUNTIF(Matrix!$M$5:$M$960,"Digital Twin not core / buzzword") -> 229
A18: No Design for Safety / PtD focus | B18: =COUNTIF(Matrix!$M$5:$M$960,"No Design for Safety / PtD focus") -> 63
A19: Wrong publication type | B19: =COUNTIF(Matrix!$M$5:$M$960,"Wrong publication type") -> 1
A20: Non-English | B20: =COUNTIF(Matrix!$M$5:$M$960,"Non-English") -> 4
A21: Total Stage-1 exclusions | B21: =SUM(B16:B20) -> 712
A23: Stage-2 (full-text) exclusion reasons
A24: Reason | B24: n
A25: Digital Twin mentioned only, not the subject | B25: =COUNTIF(Matrix!$T$5:$T$960,"Digital Twin mentioned only, not the subject") -> 14
A26: No Design for Safety focus in full text | B26: =COUNTIF(Matrix!$T$5:$T$960,"No Design for Safety focus in full text") -> 4
A27: Methodology not codable | B27: =COUNTIF(Matrix!$T$5:$T$960,"Methodology not codable") -> 0
A28: Total Stage-2 exclusions | B28: =SUM(B25:B27) -> 18

Sheet PRISMA_Shapes
E14: 112
E15: 99
E16: 30
E17: 21
A58: LIVE DATA FEED — the text of every shape above is generated from these formula cells
A59: Key | B59: Text used in shape (live formula)
A60: Identified | B60: ="Records identified from databases"&CHAR(10)&"(Scopus · Web of Science)"&CHAR(10)&"n = "&TEXT(Step1_Report!$B$4,"0") -> Records identified from databases (Scopus · Web of Science) n = 956
A61: Screened | B61: ="Records screened at Stage 1"&CHAR(10)&"(title & abstract)"&CHAR(10)&"n = "&TEXT(Step1_Report!$B$5,"0") -> Records screened at Stage 1 (title & abstract) n = 956
A62: Excluded1 | B62: ="Records excluded at Stage 1 n = "&TEXT(Step1_Report!$B$6,"0")&CHAR(10)&"• "&Step1_Report!$A$17&": "&TEXT(Step1_Report!$B$17,"0")&CHAR(10)&"• "&Step1_Report!$A$16&": "&TEXT(Step1_Report!$B$16,"0")&CHAR(10)&"• "&Step1_Report!$A$20&": "&TEXT(Step1_Report!$B$20,"0")&CHAR(10)&"• "&Step1_Report!$A$18&": "&TEXT(Step1_Report!$B$18,"0")&CHAR(10)&"• "&Step1_Report!$A$19&": "&TEXT(Step1_Report!$B$19,"0") -> Records excluded at Stage 1 n = 712 • Digital Twin not core / buzzword: 229 • Wrong domain (non-AECO): 415 • Non-English: 4 • No Design for Safety / PtD focus: 63 • Wrong publication type: 1
A63: Sought | B63: ="Reports sought for retrieval"&CHAR(10)&"n = "&TEXT(Step1_Report!$B$7,"0") -> Reports sought for retrieval n = 244
A64: NotRetrieved | B64: ="Reports not retrieved"&CHAR(10)&"(full-text PDF not on hand)"&CHAR(10)&"n = "&TEXT(Step1_Report!$B$7-Step1_Report!$B$10,"0") -> Reports not retrieved (full-text PDF not on hand) n = 4
A65: Assessed | B65: ="Reports assessed for eligibility"&CHAR(10)&"(Stage 2 — full text)"&CHAR(10)&"n = "&TEXT(Step1_Report!$B$10,"0") -> Reports assessed for eligibility (Stage 2 — full text) n = 240
A66: Excluded2 | B66: ="Reports excluded at Stage 2 n = "&TEXT(Step1_Report!$B$11,"0")&CHAR(10)&"• "&Step1_Report!$A$25&": "&TEXT(Step1_Report!$B$25,"0")&CHAR(10)&"• "&Step1_Report!$A$26&": "&TEXT(Step1_Report!$B$26,"0")&CHAR(10)&"• "&Step1_Report!$A$27&": "&TEXT(Step1_Report!$B$27,"0") -> Reports excluded at Stage 2 n = 18 • Digital Twin mentioned only, not the subject: 14 • No Design for Safety focus in full text: 4 • Methodology not codable: 0
A67: Included | B67: ="STUDIES INCLUDED IN SYNTHESIS"&CHAR(10)&"n = "&TEXT(Step1_Report!$B$12,"0") -> STUDIES INCLUDED IN SYNTHESIS n = 222
A68: PanelHeader | B68: ="Characteristics of the "&TEXT(Step3_Report!$B$2,"0")&" included studies" -> Characteristics of the 222 included studies
A69: PanelTier | B69: ="Digital Twin capability tier (Gap 1)"&CHAR(10)&"• Tier 1 – Digital Model: "&TEXT(Step3_Report!$B$6,"0")&" ("&TEXT(Step3_Report!$C$6,"0.0%")&")"&CHAR(10)&"• Tier 2 – Digital Shadow: "&TEXT(Step3_Report!$B$7,"0")&" ("&TEXT(Step3_Report!$C$7,"0.0%")&")"&CHAR(10)&"• Tier 3 – Digital Twin: "&TEXT(Step3_Report!$B$8,"0")&" ("&TEXT(Step3_Report!$C$8,"0.0%")&")"&CHAR(10)&"• Tier 4 – Cognitive: "&TEXT(Step3_Report!$B$9,"0")&" ("&TEXT(Step3_Report!$C$9,"0.0%")&")"&CHAR(10)&"• Unclear: "&TEXT(Step3_Report!$B$10,"0")&" ("&TEXT(Step3_Report!$C$10,"0.0%")&")" -> Digital Twin capability tier (Gap 1) • Tier 1 – Digital Model: 52 (23.4%) • Tier 2 – Digital Shadow: 137 (61.7%) • Tier 3 – Digital Twin: 29 (13.1%) • Tier 4 – Cognitive: 0 (0.0%) • Unclear: 4 (1.8%)
