Workbook

Sheet 0_Guide
B2: One Matrix - Four Steps (LLM-ready, no background assumed)
B3: A single progressive-disclosure matrix for screening, coding, deep-read analysis and reporting.
B5: CONTEXT PRIMER (read this before coding any paper)
B6: What is this review about | C6: This is a systematic literature review about DIGITAL TWINS used in the built-environment industry, specifically to improve SAFETY and QUALITY of designs. You are screening and coding academic papers.
B7: AECO | C7: AECO = Architecture, Engineering, Construction and Operations. It means the built-environment / construction industry (buildings, bridges, infrastructure, civil engineering). NOT manufacturing, automotive, aerospace, power/electrical equipment, healthcare, or agriculture.
B8: Digital Twin (DT) | C8: A Digital Twin is a live virtual replica of a physical asset that is connected to it by data. It is MORE than a static 3D/BIM model. If a paper only says the words 'digital twin' in passing but does not actually build or study one, treat DT as a buzzword (answer 'No').
B9: Design for Safety (DfS) | C9: Design for Safety = designing to prevent construction/operation safety incidents (e.g. fall from height, hazards, accident prevention).
B10: Design for Quality (DfQ) | C10: Design for Quality = designing to prevent defects, rework, or quality failures.
B11: Prevention through Design (PtD) | C11: Prevention through Design = the principle of eliminating risks at the design stage before construction begins. Closely related to DfS/DfQ.
B12: BIM | C12: BIM = Building Information Modelling. A static, design-stage digital model. A BIM model alone is NOT a Digital Twin (no live data link).
B13: bidirectional | C13: 'bidirectional' means data flows BOTH ways: physical->virtual AND virtual->physical (the twin can act back on the real asset). One-way data flow is only a 'digital shadow'.
B14: Answer format | C14: Every Stage-1 and Stage-2 question is answered strictly as 'Yes' or 'No'. If genuinely unsure from the abstract, answer 'No' (conservative) and add a note. Do not invent information not present in the text.
B15: One reason only | C15: When a paper is excluded, the matrix auto-picks ONE standardized reason by priority. You do not write the reason yourself.
B17: THE FOUR STEPS
B18: Step 1 (all 450 papers) | C18: An LLM or reviewer fills the AMBER Stage-1 columns (G-K) for EVERY paper, from the TITLE and ABSTRACT only. Column L auto-decides Include/Exclude; column M auto-writes the single exclusion reason.
B19: Step 2 (the matrix) | C19: This workbook IS the summary matrix. There is nothing separate to generate.
B20: Retrieval + PDF gateway | C20: For Stage-1 includes, first mark column N 'PDF full text on hand?'. This is the gateway: only papers with the PDF on hand can be deep-read. You can revisit later - when a PDF is found, change N from 'No' to 'Yes' and the paper becomes ready for Stage-2/3.
B21: Step 3 (deep read) | C21: For papers whose PDF is on hand, fill the RED Stage-2 columns (P-R) and then the GREEN synthesis 'angle' columns (U-AG). These are the evidence for your findings section.
B22: Step 4 (report) | C22: Open 'Step1_Report' (screening + PRISMA chain + exclusion reasons) and 'Step3_Report' (capability-tier / phase / method / modality / validation / self-improvement tables). Both auto-tally from the same rows.
B24: COLOUR KEY
B25: Bands | C25: AMBER = Stage-1 input (from abstract) · BLUE = PDF gateway · RED = Stage-2 input (from full text) · GREEN = Stage-3 deep-read input · BLUE-GREY = auto formula, do not edit.
B26: Golden rule | C26: Never delete a paper. A paper excluded at any stage stays in the matrix with its reason recorded. This is what makes the PRISMA flow reproducible.

Sheet 1_CodeLists
A1: YN | B1: Src | C1: Bin | D1: Tier | E1: DfX | F1: Self | G1: Method | H1: Modality | I1: Valid | J1: Cluster | K1: Fusion | L1: Conf
A2: Yes | B2: Scopus | C2: 0 | D2: Tier 1 - Digital Model (static, no live data) | E2: Design for Safety (DfS) | F2: None | G2: Computer Vision / CNN / object-detection | H2: Single (one data type) | I2: Conceptual (no test) | J2: BIM-to-Digital-Twin architecture | K2: Single | L2: High
A3: No | B3: Web of Science | C3: 1 | D3: Tier 2 - Digital Shadow (one-way physical to virtual) | E3: Design for Quality (DfQ) | F3: Mentioned only | G3: Graph Neural Network (GNN) | H3: Multi (two or more data types) | I3: Simulation | J3: Semantic interoperability | K3: Co-present | L3: Medium
B4: Lens.org | D4: Tier 3 - Digital Twin (bidirectional, two-way) | E4: Both | F4: Implemented | G4: LSTM / RNN (recurrent networks) | I4: Single case study | J4: Perception / Computer Vision | K4: Aligned | L4: Low
B5: Backward-snowball | D5: Tier 4 - Cognitive / Self-improving | E5: Other | F5: Convergence-characterised | G5: Transformer / Large Language Model (LLM) | I5: Cross-project (multiple real projects) | J5: Design for Safety | K5: Fused
B6: Forward-snowball | D6: Unclear | G6: Reinforcement Learning (RL) | J6: Predictive analytics / decision support | K6: Unclear
G7: Bayesian / probabilistic | J7: Lifecycle / governance
G8: Agent-based model (ABM) | J8: Other
G9: Finite Element Method / physics-based
G10: Ontology / semantic
G11: Statistical / change-point
G12: Digital Twin platform (no machine learning)
G13: Other / Mixed

Sheet Matrix
A1: ID | B1: Authors (year) | C1: Year | D1: Journal | E1: Title | F1: Source database | G1: Stage1: Domain is AECO (built environment)? | H1: Stage1: Digital Twin is core (not just a buzzword)? | I1: Stage1: About Design for Safety / Quality / Prevention through Design? | J1: Stage1: Publication type OK (journal/conference article, not editorial/erratum)? | K1: Stage1: Written in English (full text)? | L1: STAGE-1 decision | M1: Stage-1 exclusion reason (auto) | N1: GATEWAY: PDF full text on hand? (change to Yes when found) | O1: Full text retrieved for PRISMA? | P1: Stage2: Digital Twin is the actual subject (full text)? | Q1: Stage2: Design for Safety/Quality confirmed in full text? | R1: Stage2: Methodology is clear enough to code? | S1: STAGE-2 decision | T1: Stage-2 exclusion reason (auto) | U1: Deep-read: Digital Twin capability tier | V1: Phase: Design (1/0) | W1: Phase: Construction (1/0) | X1: Phase: Operation (1/0) | Y1: Cross-phase? (auto) | Z1: Deep-read: Design-for-X target | AA1: Deep-read: Self-improvement / convergence | AB1: Deep-read: Methodology | AC1: Deep-read: Data modality | AD1: Deep-read: Validation level | AE1: Deep-read: Quality appraisal score (0 to 5) | AF1: Deep-read: Thematic cluster | AG1: Deep-read: Key evidence / notes | AH1: Deep-read: Strength / research gap filled | AI1: Deep-read: Deficiencies & future work | AJ1: Deep-read: Fusion depth (AC1) | AK1: Deep-read: Fusion evidence (AC2) | AL1: Deep-read: Fusion confidence (AC3) | AM1: Fusion coding flag (review)
A2: 3566 | E2: An association rule mining model for the application of construction t… | F2: Scopus | G2: Yes | H2: No | I2: No | J2: Yes | K2: Yes | L2: =IF(COUNTBLANK(G2:K2)=5,"",IF(COUNTIF(G2:K2,"No")>0,"EXCLUDE","INCLUDE")) -> EXCLUDE | M2: =IF(L2<>"EXCLUDE","",IF(G2="No","Wrong domain (non-AECO)",IF(H2="No","Digital Twin not core / buzzword",IF(I2="No","No Design for Safety/Quality/PtD",IF(J2="No","Wrong publication type",IF(K2="No","Non-English","")))))) -> Digital Twin not core / buzzword | S2: =IF(N2<>"Yes","",IF(COUNTBLANK(P2:R2)=3,"",IF(COUNTIF(P2:R2,"No")>0,"EXCLUDE","INCLUDE"))) | T2: =IF(S2<>"EXCLUDE","",IF(P2="No","Digital Twin mentioned only, not the subject",IF(Q2="No","No Design for Safety/Quality in full text",IF(R2="No","Methodology not codable","")))) | Y2: =IF(SUM(V2:X2)=0,"",IF(SUM(V2:X2)>=2,"Multi","Single")) | AG2: Tech-adoption survey (ARM); no DT, no DfS/DfQ focus
A3: 3741 | E3: Digital twin and AI-driven smart adaptive walls for energy, comfort an… | F3: Scopus | G3: Yes | H3: Yes | I3: No | J3: Yes | K3: Yes | L3: =IF(COUNTBLANK(G3:K3)=5,"",IF(COUNTIF(G3:K3,"No")>0,"EXCLUDE","INCLUDE")) -> EXCLUDE | M3: =IF(L3<>"EXCLUDE","",IF(G3="No","Wrong domain (non-AECO)",IF(H3="No","Digital Twin not core / buzzword",IF(I3="No","No Design for Safety/Quality/PtD",IF(J3="No","Wrong publication type",IF(K3="No","Non-English","")))))) -> No Design for Safety/Quality/PtD | S3: =IF(N3<>"Yes","",IF(COUNTBLANK(P3:R3)=3,"",IF(COUNTIF(P3:R3,"No")>0,"EXCLUDE","INCLUDE"))) | T3: =IF(S3<>"EXCLUDE","",IF(P3="No","Digital Twin mentioned only, not the subject",IF(Q3="No","No Design for Safety/Quality in full text",IF(R3="No","Methodology not codable","")))) | Y3: =IF(SUM(V3:X3)=0,"",IF(SUM(V3:X3)>=2,"Multi","Single")) | AG3: Energy/comfort/carbon optimization; safety shield is control constraint (edge 5)
A4: 3665 | E4: Enhancing attack resilience of cyber-physical systems through state de… | F4: Scopus | G4: No | H4: No | I4: No | J4: Yes | K4: Yes | L4: =IF(COUNTBLANK(G4:K4)=5,"",IF(COUNTIF(G4:K4,"No")>0,"EXCLUDE","INCLUDE")) -> EXCLUDE | M4: =IF(L4<>"EXCLUDE","",IF(G4="No","Wrong domain (non-AECO)",IF(H4="No","Digital Twin not core / buzzword",IF(I4="No","No Design for Safety/Quality/PtD",IF(J4="No","Wrong publication type",IF(K4="No","Non-English","")))))) -> Wrong domain (non-AECO) | S4: =IF(N4<>"Yes","",IF(COUNTBLANK(P4:R4)=3,"",IF(COUNTIF(P4:R4,"No")>0,"EXCLUDE","INCLUDE"))) | T4: =IF(S4<>"EXCLUDE","",IF(P4="No","Digital Twin mentioned only, not the subject",IF(Q4="No","No Design for Safety/Quality in full text",IF(R4="No","Methodology not codable","")))) | Y4: =IF(SUM(V4:X4)=0,"",IF(SUM(V4:X4)>=2,"Multi","Single")) | AG4: Cybersecurity of industrial CPS/SCADA; not AECO
A5: 3657 | E5: IoT-Driven Resilience Monitoring: Case Study of a Cyber-Physical Syste… | F5: Scopus | G5: No | H5: Yes | I5: No | J5: Yes | K5: Yes | L5: =IF(COUNTBLANK(G5:K5)=5,"",IF(COUNTIF(G5:K5,"No")>0,"EXCLUDE","INCLUDE")) -> EXCLUDE | M5: =IF(L5<>"EXCLUDE","",IF(G5="No","Wrong domain (non-AECO)",IF(H5="No","Digital Twin not core / buzzword",IF(I5="No","No Design for Safety/Quality/PtD",IF(J5="No","Wrong publication type",IF(K5="No","Non-English","")))))) -> Wrong domain (non-AECO) | S5: =IF(N5<>"Yes","",IF(COUNTBLANK(P5:R5)=3,"",IF(COUNTIF(P5:R5,"No")>0,"EXCLUDE","INCLUDE"))) | T5: =IF(S5<>"EXCLUDE","",IF(P5="No","Digital Twin mentioned only, not the subject",IF(Q5="No","No Design for Safety/Quality in full text",IF(R5="No","Methodology not codable","")))) | Y5: =IF(SUM(V5:X5)=0,"",IF(SUM(V5:X5)>=2,"Multi","Single")) | AG5: Smart energy systems CI; not built environment
A6: 3685 | E6: Virtual Fencing for Safety-Critical Cyber-Physical Systems: Computer-V… | F6: Scopus | G6: No | H6: Yes | I6: No | J6: Yes | K6: Yes | L6: =IF(COUNTBLANK(G6:K6)=5,"",IF(COUNTIF(G6:K6,"No")>0,"EXCLUDE","INCLUDE")) -> EXCLUDE | M6: =IF(L6<>"EXCLUDE","",IF(G6="No","Wrong domain (non-AECO)",IF(H6="No","Digital Twin not core / buzzword",IF(I6="No","No Design for Safety/Quality/PtD",IF(J6="No","Wrong publication type",IF(K6="No","Non-English","")))))) -> Wrong domain (non-AECO) | S6: =IF(N6<>"Yes","",IF(COUNTBLANK(P6:R6)=3,"",IF(COUNTIF(P6:R6,"No")>0,"EXCLUDE","INCLUDE"))) | T6: =IF(S6<>"EXCLUDE","",IF(P6="No","Digital Twin mentioned only, not the subject",IF(Q6="No","No Design for Safety/Quality in full text",IF(R6="No","Methodology not codable","")))) | Y6: =IF(SUM(V6:X6)=0,"",IF(SUM(V6:X6)>=2,"Multi","Single")) | AG6: Crowd management/surveillance; no built asset DfS/DfQ
A7: 3756 | B7: Ahmad (2026) | C7: 2026 | E7: Lessons Learned from the Real-World Deployment of Multisensor Fusion f… | F7: Scopus | G7: Yes | H7: Yes | I7: Yes | J7: Yes | K7: Yes | L7: =IF(COUNTBLANK(G7:K7)=5,"",IF(COUNTIF(G7:K7,"No")>0,"EXCLUDE","INCLUDE")) -> INCLUDE | M7: =IF(L7<>"EXCLUDE","",IF(G7="No","Wrong domain (non-AECO)",IF(H7="No","Digital Twin not core / buzzword",IF(I7="No","No Design for Safety/Quality/PtD",IF(J7="No","Wrong publication type",IF(K7="No","Non-English","")))))) | N7: Yes | O7: Yes | P7: Yes | Q7: Yes | R7: Yes | S7: =IF(N7<>"Yes","",IF(COUNTBLANK(P7:R7)=3,"",IF(COUNTIF(P7:R7,"No")>0,"EXCLUDE","INCLUDE"))) -> INCLUDE | T7: =IF(S7<>"EXCLUDE","",IF(P7="No","Digital Twin mentioned only, not the subject",IF(Q7="No","No Design for Safety/Quality in full text",IF(R7="No","Methodology not codable","")))) | U7: Tier 2 - Digital Shadow (one-way physical to virtual) | V7: 0 | W7: 1 | X7: 0 | Y7: =IF(SUM(V7:X7)=0,"",IF(SUM(V7:X7)>=2,"Multi","Single")) -> Single | Z7: Design for Safety (DfS) | AA7: None | AB7: Other / Mixed | AC7: Multi (two or more data types) | AD7: Single case study | AE7: 4 | AF7: Design for Safety | AG7: Deployed LiDAR+radar+camera fusion validated with RTK-GNSS at real work zone (lane-level accuracy); Predictive DT framework (Digital Shadow + Digital Sibling, TTC/PET conflict metrics, C-V2X warnings) proposed but not implemented — hence Tier 2, AA None. [Full-text source: arXiv OA preprint] | AH7: Fills the gap between work zone safety DT research and real-world deployment: LiDAR+radar+camera fusion validated with RTK-GNSS at a real work zone achieving lane-level accuracy, feeding a predictive DT framework pairing a Digital Shadow and Digital Sibling with TTC/PET conflict metrics and C-V2X warnings for proactive safety. | AI7: Deployment lessons rather than controlled validation: one real work zone, and the predictive framework (conflict metrics, C-V2X warnings) stays at framework level without demonstrated closed-loop actuation; no explicit future work is stated. | AJ7: Fused | AK7: Deployed LiDAR+radar+camera fusion validated with RTK-GNSS at lane-level accuracy at a real work zone (joint multi-sensor deployment feeding conflict metrics). | AL7: Medium
A8: 3978 | B8: Akanmu (2021) | C8: 2021 | E8: TOWARDS NEXT GENERATION CYBER-PHYSICAL SYSTEMS AND DIGITAL TWINS FOR C… | F8: Web of Science | G8: Yes | H8: Yes | I8: Yes | J8: Yes | K8: Yes | L8: =IF(COUNTBLANK(G8:K8)=5,"",IF(COUNTIF(G8:K8,"No")>0,"EXCLUDE","INCLUDE")) -> INCLUDE | M8: =IF(L8<>"EXCLUDE","",IF(G8="No","Wrong domain (non-AECO)",IF(H8="No","Digital Twin not core / buzzword",IF(I8="No","No Design for Safety/Quality/PtD",IF(J8="No","Wrong publication type",IF(K8="No","Non-English","")))))) | N8: Yes | O8: Yes | P8: Yes | Q8: Yes | R8: Yes | S8: =IF(N8<>"Yes","",IF(COUNTBLANK(P8:R8)=3,"",IF(COUNTIF(P8:R8,"No")>0,"EXCLUDE","INCLUDE"))) -> INCLUDE | T8: =IF(S8<>"EXCLUDE","",IF(P8="No","Digital Twin mentioned only, not the subject",IF(Q8="No","No Design for Safety/Quality in full text",IF(R8="No","Methodology not codable","")))) | U8: Tier 3 - Digital Twin (bidirectional, two-way) | V8: 0 | W8: 1 | X8: 1 | Y8: =IF(SUM(V8:X8)=0,"",IF(SUM(V8:X8)>=2,"Multi","Single")) -> Multi | Z8: Design for Safety (DfS) | AA8: Mentioned only | AB8: Digital Twin platform (no machine learning) | AC8: Multi (two or more data types) | AD8: Conceptual (no test) | AE8: 3 | AF8: BIM-to-Digital-Twin architecture | AG8: Perspective paper defining next-gen CPS/DT with explicit two-way mapping and passive/active control; scenarios (teleoperated drywall robot, postural tracking, near-miss prevention) illustrate bidirectional control but nothing implemented; ML training of movement data only suggested. [Full-text source: Endnote] | AH8: A perspective paper defining next-generation CPS and DT through two-way dynamic mapping between virtual models and the physical facility, distinguishing passive (model-based) from active (actuator-based) control, and illustrating scenarios: a teleoperated drywall robot controlled via wearable IMU motion capture, postural tracking with AR avatars and color-coded ergonomic risk feedback, and near-miss prediction using case-based reasoning and K-nearest neighbor. | AI8: Purely conceptual: none of the scenarios is implemented or validated, and the paper itself lists open challenges of a missing information model for DTs, missing version management guidelines, missing communication latency guidelines, and missing interoperability standards analogous to IFC. | AJ8: Unclear | AK8: Perspective paper defining next-gen CPS/DT; the bidirectional-control scenarios are illustrative only and no data-integration mechanism is implemented. | AL8: High
A9: 3527 | E9: A methodological approach to hybrid AI systems for real-time infrastru… | F9: Scopus | G9: Yes | H9: No | I9: Yes | J9: Yes | K9: Yes | L9: =IF(COUNTBLANK(G9:K9)=5,"",IF(COUNTIF(G9:K9,"No")>0,"EXCLUDE","INCLUDE")) -> EXCLUDE | M9: =IF(L9<>"EXCLUDE","",IF(G9="No","Wrong domain (non-AECO)",IF(H9="No","Digital Twin not core / buzzword",IF(I9="No","No Design for Safety/Quality/PtD",IF(J9="No","Wrong publication type",IF(K9="No","Non-English","")))))) -> Digital Twin not core / buzzword | S9: =IF(N9<>"Yes","",IF(COUNTBLANK(P9:R9)=3,"",IF(COUNTIF(P9:R9,"No")>0,"EXCLUDE","INCLUDE"))) | T9: =IF(S9<>"EXCLUDE","",IF(P9="No","Digital Twin mentioned only, not the subject",IF(Q9="No","No Design for Safety/Quality in full text",IF(R9="No","Methodology not codable","")))) | Y9: =IF(SUM(V9:X9)=0,"",IF(SUM(V9:X9)>=2,"Multi","Single")) | AG9: SHM hybrid AI; no DT built/proposed
A10: 3963 | E10: Neural network-based metamodel for scaffolding behavior: Application f… | F10: Web of Science | G10: Yes | H10: No | I10: Yes | J10: Yes | K10: Yes | L10: =IF(COUNTBLANK(G10:K10)=5,"",IF(COUNTIF(G10:K10,"No")>0,"EXCLUDE","INCLUDE")) -> EXCLUDE | M10: =IF(L10<>"EXCLUDE","",IF(G10="No","Wrong domain (non-AECO)",IF(H10="No","Digital Twin not core / buzzword",IF(I10="No","No Design for Safety/Quality/PtD",IF(J10="No","Wrong publication type",IF(K10="No","Non-English","")))))) -> Digital Twin not core / buzzword | S10: =IF(N10<>"Yes","",IF(COUNTBLANK(P10:R10)=3,"",IF(COUNTIF(P10:R10,"No")>0,"EXCLUDE","INCLUDE"))) | T10: =IF(S10<>"EXCLUDE","",IF(P10="No","Digital Twin mentioned only, not the subject",IF(Q10="No","No Design for Safety/Quality in full text",IF(R10="No","Methodology not codable","")))) | Y10: =IF(SUM(V10:X10)=0,"",IF(SUM(V10:X10)>=2,"Multi","Single")) | AG10: FEM+NN metamodel; authors state not a full digital twin
A11: 3917 | E11: Enhancing resilience through environmental data integration in early c… | F11: Web of Science | G11: Yes | H11: No | I11: No | J11: Yes | K11: Yes | L11: =IF(COUNTBLANK(G11:K11)=5,"",IF(COUNTIF(G11:K11,"No")>0,"EXCLUDE","INCLUDE")) -> EXCLUDE | M11: =IF(L11<>"EXCLUDE","",IF(G11="No","Wrong domain (non-AECO)",IF(H11="No","Digital Twin not core / buzzword",IF(I11="No","No Design for Safety/Quality/PtD",IF(J11="No","Wrong publication type",IF(K11="No","Non-English","")))))) -> Digital Twin not core / buzzword | S11: =IF(N11<>"Yes","",IF(COUNTBLANK(P11:R11)=3,"",IF(COUNTIF(P11:R11,"No")>0,"EXCLUDE","INCLUDE"))) | T11: =IF(S11<>"EXCLUDE","",IF(P11="No","Digital Twin mentioned only, not the subject",IF(Q11="No","No Design for Safety/Quality in full text",IF(R11="No","Methodology not codable","")))) | Y11: =IF(SUM(V11:X11)=0,"",IF(SUM(V11:X11)>=2,"Multi","Single")) | AG11: BIM-ICDD semantic linking; no DT; compliance not DfQ
A12: 3541 | E12: Automation levels for nuclear reactor operations: A revised perspectiv… | F12: Scopus | G12: No | H12: No | I12: No | J12: Yes | K12: Yes | L12: =IF(COUNTBLANK(G12:K12)=5,"",IF(COUNTIF(G12:K12,"No")>0,"EXCLUDE","INCLUDE")) -> EXCLUDE | M12: =IF(L12<>"EXCLUDE","",IF(G12="No","Wrong domain (non-AECO)",IF(H12="No","Digital Twin not core / buzzword",IF(I12="No","No Design for Safety/Quality/PtD",IF(J12="No","Wrong publication type",IF(K12="No","Non-English","")))))) -> Wrong domain (non-AECO) | S12: =IF(N12<>"Yes","",IF(COUNTBLANK(P12:R12)=3,"",IF(COUNTIF(P12:R12,"No")>0,"EXCLUDE","INCLUDE"))) | T12: =IF(S12<>"EXCLUDE","",IF(P12="No","Digital Twin mentioned only, not the subject",IF(Q12="No","No Design for Safety/Quality in full text",IF(R12="No","Methodology not codable","")))) | Y12: =IF(SUM(V12:X12)=0,"",IF(SUM(V12:X12)>=2,"Multi","Single")) | AG12: Nuclear power domain
A13: 3903 | E13: BIM-GIS integrated hydrodynamic modeling for road flood risk assessmen… | F13: Web of Science | G13: Yes | H13: No | I13: Yes | J13: Yes | K13: Yes | L13: =IF(COUNTBLANK(G13:K13)=5,"",IF(COUNTIF(G13:K13,"No")>0,"EXCLUDE","INCLUDE")) -> EXCLUDE | M13: =IF(L13<>"EXCLUDE","",IF(G13="No","Wrong domain (non-AECO)",IF(H13="No","Digital Twin not core / buzzword",IF(I13="No","No Design for Safety/Quality/PtD",IF(J13="No","Wrong publication type",IF(K13="No","Non-English","")))))) -> Digital Twin not core / buzzword | S13: =IF(N13<>"Yes","",IF(COUNTBLANK(P13:R13)=3,"",IF(COUNTIF(P13:R13,"No")>0,"EXCLUDE","INCLUDE"))) | T13: =IF(S13<>"EXCLUDE","",IF(P13="No","Digital Twin mentioned only, not the subject",IF(Q13="No","No Design for Safety/Quality in full text",IF(R13="No","Methodology not codable","")))) | Y13: =IF(SUM(V13:X13)=0,"",IF(SUM(V13:X13)>=2,"Multi","Single")) | AG13: BIM-HDM framework; DT only future early warning
A14: 3915 | B14: Almatared (2024) | C14: 2024 | E14: Digital-Twin-Based Fire Safety Management Framework for Smart Building… | F14: Web of Science | G14: Yes | H14: Yes | I14: Yes | J14: Yes | K14: Yes | L14: =IF(COUNTBLANK(G14:K14)=5,"",IF(COUNTIF(G14:K14,"No")>0,"EXCLUDE","INCLUDE")) -> INCLUDE | M14: =IF(L14<>"EXCLUDE","",IF(G14="No","Wrong domain (non-AECO)",IF(H14="No","Digital Twin not core / buzzword",IF(I14="No","No Design for Safety/Quality/PtD",IF(J14="No","Wrong publication type",IF(K14="No","Non-English","")))))) | N14: Yes | O14: Yes | P14: Yes | Q14: Yes | R14: Yes | S14: =IF(N14<>"Yes","",IF(COUNTBLANK(P14:R14)=3,"",IF(COUNTIF(P14:R14,"No")>0,"EXCLUDE","INCLUDE"))) -> INCLUDE | T14: =IF(S14<>"EXCLUDE","",IF(P14="No","Digital Twin mentioned only, not the subject",IF(Q14="No","No Design for Safety/Quality in full text",IF(R14="No","Methodology not codable","")))) | U14: Tier 3 - Digital Twin (bidirectional, two-way) | V14: 0 | W14: 0 | X14: 1 | Y14: =IF(SUM(V14:X14)=0,"",IF(SUM(V14:X14)>=2,"Multi","Single")) -> Single | Z14: Design for Safety (DfS) | AA14: Mentioned only | AB14: Digital Twin platform (no machine learning) | AC14: Multi (two or more data types) | AD14: Conceptual (no test) | AE14: 3 | AF14: Design for Safety | AG14: Four-layer DT-based fire-safety framework (physical/virtual/application/user-interaction) with explicit feedback "integrated back with the physical building layer for automatic control"; validated only via FM-professional questionnaire, no technical test; AI learning cited from literature, not implemented. [Full-text source: Endnote] | AH14: Addresses the underexplored application of DT to fire safety management: a four-layer framework (physical building, virtual building, application, and user interaction layers) combining BIM, IoT, AI, data fusion, blockchain, and AR, with virtual-layer decisions fed back to the physical building layer for automatic control and operation optimization while keeping FM professionals in the loop. | AI14: Conceptual only: the framework was validated through a thematic analysis of 37 studies and a survey of FM professionals (66 responses, 28 complete) rather than a live implementation; no prototype or sensor deployment is reported. Future work includes a Delphi study with a broader panel and involving firefighters as end users. | AJ14: Unclear | AK14: Four-layer fire-safety framework validated only through a thematic analysis and an FM-professional questionnaire; the layer integration mechanism is not implemented. | AL14: High
A15: 3668 | B15: Alvaro (2025) | C15: 2025 | E15: GUIDE2FR: A smart monitoring platform with a digital twin of a firefig… | F15: Scopus | G15: Yes | H15: Yes | I15: Yes | J15: Yes | K15: Yes | L15: =IF(COUNTBLANK(G15:K15)=5,"",IF(COUNTIF(G15:K15,"No")>0,"EXCLUDE","INCLUDE")) -> INCLUDE | M15: =IF(L15<>"EXCLUDE","",IF(G15="No","Wrong domain (non-AECO)",IF(H15="No","Digital Twin not core / buzzword",IF(I15="No","No Design for Safety/Quality/PtD",IF(J15="No","Wrong publication type",IF(K15="No","Non-English","")))))) | N15: Yes | O15: Yes | P15: Yes | Q15: Yes | R15: Yes | S15: =IF(N15<>"Yes","",IF(COUNTBLANK(P15:R15)=3,"",IF(COUNTIF(P15:R15,"No")>0,"EXCLUDE","INCLUDE"))) -> INCLUDE | T15: =IF(S15<>"EXCLUDE","",IF(P15="No","Digital Twin mentioned only, not the subject",IF(Q15="No","No Design for Safety/Quality in full text",IF(R15="No","Methodology not codable","")))) | U15: Tier 2 - Digital Shadow (one-way physical to virtual) | V15: 0 | W15: 0 | X15: 1 | Y15: =IF(SUM(V15:X15)=0,"",IF(SUM(V15:X15)>=2,"Multi","Single")) -> Single | Z15: Design for Safety (DfS) | AA15: None | AB15: Other / Mixed | AC15: Multi (two or more data types) | AD15: Single case study | AE15: 4 | AF15: Design for Safety | AG15: GUIDE2FR emergency-monitoring DT of a firefighter training tower (Alcorcón): Wi-Fi/LoRa beacon network (temp, humidity, CO2, TVOC) + RTSP video synchronised in a Grafana plugin; offline-trained ML forecasting pipeline (SVR/RF/Huber/GPR, forward-chaining CV, tested on 4 beacons at Fire Station 9) visualised in the DT; one-way data flow to human decision-makers, no actuation and no online learning loop. [Full-text source: Endnote] | AH15: Fills the gap between fire-safety DT research and operational emergency response: a functioning building DT (GUIDE2FR) fusing Wi-Fi/LoRa environmental beacons with live RTSP video in a Grafana plugin, plus an offline-trained ML forecasting pipeline (SVR, Huber, Random Forest, Gaussian Process, forward-chaining CV, adaptive ensemble) tested on data from four beacons during firefighter training exercises at Fire Station 9 in Madrid. | AI15: No actuation or bidirectional link to building systems: forecasting models are offline-trained and never updated online. The platform relies on proprietary ArcGIS, assumes a reliable wireless network, and sensor accuracy under extreme conditions is unverified; future work targets open-source visualization and integration with more real assets for active response and evacuation mechanisms. | AJ15: Aligned | AK15: Each video segment is timestamped and the custom Grafana plugin cross-references RTSP video streams with time-series sensor data stored in MySQL, giving video and beacon data a shared temporal frame (inference still runs on sensor series only). | AL15: High
A16: 4053 | B16: Ammar (2024) | C16: 2024 | E16: Practical Application of Digital Twins for Transportation Asset Data M… | F16: Web of Science | G16: Yes | H16: Yes | I16: Yes | J16: Yes | K16: Yes | L16: =IF(COUNTBLANK(G16:K16)=5,"",IF(COUNTIF(G16:K16,"No")>0,"EXCLUDE","INCLUDE")) -> INCLUDE | M16: =IF(L16<>"EXCLUDE","",IF(G16="No","Wrong domain (non-AECO)",IF(H16="No","Digital Twin not core / buzzword",IF(I16="No","No Design for Safety/Quality/PtD",IF(J16="No","Wrong publication type",IF(K16="No","Non-English","")))))) | N16: Yes | O16: Yes | P16: No | Q16: Yes | R16: Yes | S16: =IF(N16<>"Yes","",IF(COUNTBLANK(P16:R16)=3,"",IF(COUNTIF(P16:R16,"No")>0,"EXCLUDE","INCLUDE"))) -> EXCLUDE | T16: =IF(S16<>"EXCLUDE","",IF(P16="No","Digital Twin mentioned only, not the subject",IF(Q16="No","No Design for Safety/Quality in full text",IF(R16="No","Methodology not codable","")))) -> Digital Twin mentioned only, not the subject | U16: Unclear | Y16: =IF(SUM(V16:X16)=0,"",IF(SUM(V16:X16)>=2,"Multi","Single")) | AG16: Survey + case study on guiderail data management for a transportation agency: investigates current practices and proposes a data architecture for information-rich analytical models using DTs, but no DT is actually built or evaluated - P=No -> Stage-2 exclude. [Full-text source: Endnote]
A17: 3579 | E17: State regulation of the IoT in the Russian Federation: Fundamentals an… | F17: Scopus | G17: No | H17: No | I17: No | J17: Yes | K17: Yes | L17: =IF(COUNTBLANK(G17:K17)=5,"",IF(COUNTIF(G17:K17,"No")>0,"EXCLUDE","INCLUDE")) -> EXCLUDE | M17: =IF(L17<>"EXCLUDE","",IF(G17="No","Wrong domain (non-AECO)",IF(H17="No","Digital Twin not core / buzzword",IF(I17="No","No Design for Safety/Quality/PtD",IF(J17="No","Wrong publication type",IF(K17="No","Non-English","")))))) -> Wrong domain (non-AECO) | S17: =IF(N17<>"Yes","",IF(COUNTBLANK(P17:R17)=3,"",IF(COUNTIF(P17:R17,"No")>0,"EXCLUDE","INCLUDE"))) | T17: =IF(S17<>"EXCLUDE","",IF(P17="No","Digital Twin mentioned only, not the subject",IF(Q17="No","No Design for Safety/Quality in full text",IF(R17="No","Methodology not codable","")))) | Y17: =IF(SUM(V17:X17)=0,"",IF(SUM(V17:X17)>=2,"Multi","Single")) | AG17: Legal/regulatory IoT paper; not AECO
A18: 3838 | E18: The Role of Artificial Intelligence in Shaping Intelligent Motorways: … | F18: Scopus | G18: Yes | H18: No | I18: No | J18: Yes | K18: Yes | L18: =IF(COUNTBLANK(G18:K18)=5,"",IF(COUNTIF(G18:K18,"No")>0,"EXCLUDE","INCLUDE")) -> EXCLUDE | M18: =IF(L18<>"EXCLUDE","",IF(G18="No","Wrong domain (non-AECO)",IF(H18="No","Digital Twin not core / buzzword",IF(I18="No","No Design for Safety/Quality/PtD",IF(J18="No","Wrong publication type",IF(K18="No","Non-English","")))))) -> Digital Twin not core / buzzword | S18: =IF(N18<>"Yes","",IF(COUNTBLANK(P18:R18)=3,"",IF(COUNTIF(P18:R18,"No")>0,"EXCLUDE","INCLUDE"))) | T18: =IF(S18<>"EXCLUDE","",IF(P18="No","Digital Twin mentioned only, not the subject",IF(Q18="No","No Design for Safety/Quality in full text",IF(R18="No","Methodology not codable","")))) | Y18: =IF(SUM(V18:X18)=0,"",IF(SUM(V18:X18)>=2,"Multi","Single")) | AG18: AI-in-motorways review; DT one of many topics
A19: 4020 | E19: FingerCI: Writing industrial process specifications from network traff… | F19: Web of Science | G19: No | H19: Yes | I19: No | J19: Yes | K19: Yes | L19: =IF(COUNTBLANK(G19:K19)=5,"",IF(COUNTIF(G19:K19,"No")>0,"EXCLUDE","INCLUDE")) -> EXCLUDE | M19: =IF(L19<>"EXCLUDE","",IF(G19="No","Wrong domain (non-AECO)",IF(H19="No","Digital Twin not core / buzzword",IF(I19="No","No Design for Safety/Quality/PtD",IF(J19="No","Wrong publication type",IF(K19="No","Non-English","")))))) -> Wrong domain (non-AECO) | S19: =IF(N19<>"Yes","",IF(COUNTBLANK(P19:R19)=3,"",IF(COUNTIF(P19:R19,"No")>0,"EXCLUDE","INCLUDE"))) | T19: =IF(S19<>"EXCLUDE","",IF(P19="No","Digital Twin mentioned only, not the subject",IF(Q19="No","No Design for Safety/Quality in full text",IF(R19="No","Methodology not codable","")))) | Y19: =IF(SUM(V19:X19)=0,"",IF(SUM(V19:X19)>=2,"Multi","Single")) | AG19: Cybersecurity; airport baggage system industrial testbed
A20: 3842 | B20: Aragon (2025) | C20: 2025 | E20: Seeking a Definition of Digital Twins for Construction and Infrastruct… | F20: Scopus | G20: Yes | H20: Yes | I20: Yes | J20: Yes | K20: Yes | L20: =IF(COUNTBLANK(G20:K20)=5,"",IF(COUNTIF(G20:K20,"No")>0,"EXCLUDE","INCLUDE")) -> INCLUDE | M20: =IF(L20<>"EXCLUDE","",IF(G20="No","Wrong domain (non-AECO)",IF(H20="No","Digital Twin not core / buzzword",IF(I20="No","No Design for Safety/Quality/PtD",IF(J20="No","Wrong publication type",IF(K20="No","Non-English","")))))) | N20: Yes | O20: Yes | P20: Yes | Q20: Yes | R20: Yes | S20: =IF(N20<>"Yes","",IF(COUNTBLANK(P20:R20)=3,"",IF(COUNTIF(P20:R20,"No")>0,"EXCLUDE","INCLUDE"))) -> INCLUDE | T20: =IF(S20<>"EXCLUDE","",IF(P20="No","Digital Twin mentioned only, not the subject",IF(Q20="No","No Design for Safety/Quality in full text",IF(R20="No","Methodology not codable","")))) | U20: Tier 1 - Digital Model (static, no live data) | V20: 0 | W20: 0 | X20: 1 | Y20: =IF(SUM(V20:X20)=0,"",IF(SUM(V20:X20)>=2,"Multi","Single")) -> Single | Z20: Design for Safety (DfS) | AA20: None | AB20: Digital Twin platform (no machine learning) | AC20: Multi (two or more data types) | AD20: Cross-project (multiple real projects) | AE20: 3 | AF20: Lifecycle / governance | AG20: Definition/standardisation position paper (CEN/TC 442/WG 9, ISO); two illustrative DT cases (Bidebieta-Basauri railway station, UPM civil engineering school) are management/visualisation platforms with real-time info integration but no analytics loop or learning; safety only a secondary use case. [Full-text source: Endnote] | AH20: A standardization position paper reviewing DT definitions and frameworks and reporting the creation of CEN/TC 442/WG 9, whose 34-use-case technical report CEN/TR 18077 and the resulting European standard aim to give the built environment a shared DT definition; it grounds its argument in two implemented management platforms, the Bidebieta-Basauri railway station and the UPM civil engineering school. | AI20: The two DT cases are management and visualization platforms lacking AI or simulation protocols, which the authors state are still under research, and the paper proposes definitions rather than new empirical validation; the European standard was still pending publication and no quantitative evaluation is offered. | AJ20: Unclear | AK20: Standardisation position paper (CEN/TC 442/WG 9); the two illustrative DT cases are management/visualisation platforms and no data-integration mechanism is specified. | AL20: High
A21: 4028 | B21: Araujo (2025) | C21: 2025 | E21: Proposal of a conceptual model of digital twins for construction sites | F21: Web of Science | G21: Yes | H21: Yes | I21: Yes | J21: Yes | K21: Yes | L21: =IF(COUNTBLANK(G21:K21)=5,"",IF(COUNTIF(G21:K21,"No")>0,"EXCLUDE","INCLUDE")) -> INCLUDE | M21: =IF(L21<>"EXCLUDE","",IF(G21="No","Wrong domain (non-AECO)",IF(H21="No","Digital Twin not core / buzzword",IF(I21="No","No Design for Safety/Quality/PtD",IF(J21="No","Wrong publication type",IF(K21="No","Non-English","")))))) | N21: Yes | O21: Yes | P21: Yes | Q21: Yes | R21: Yes | S21: =IF(N21<>"Yes","",IF(COUNTBLANK(P21:R21)=3,"",IF(COUNTIF(P21:R21,"No")>0,"EXCLUDE","INCLUDE"))) -> INCLUDE | T21: =IF(S21<>"EXCLUDE","",IF(P21="No","Digital Twin mentioned only, not the subject",IF(Q21="No","No Design for Safety/Quality in full text",IF(R21="No","Methodology not codable","")))) | U21: Tier 2 - Digital Shadow (one-way physical to virtual) | V21: 0 | W21: 1 | X21: 0 | Y21: =IF(SUM(V21:X21)=0,"",IF(SUM(V21:X21)>=2,"Multi","Single")) -> Single | Z21: Design for Quality (DfQ) | AA21: None | AB21: Digital Twin platform (no machine learning) | AC21: Multi (two or more data types) | AD21: Conceptual (no test) | AE21: 3 | AF21: BIM-to-Digital-Twin architecture | AG21: DSR conceptual model (F1 data acquisition / F2 data analysis-simulation / F3 BIM transformation boxes) for DT on construction sites, generalised from the empirical Smart Twins 4.0 system (RFID+IoT+BIM tracking of metallic formwork in concrete wall construction; 151 panels inspected, 100% external defects, wear 42% — rework/quality control). Closed-loop is human-in-the-loop only; F2 simulation box proposed but NOT implemented (future Smart Twins 5.0); no ML and no self-improvement. [Full-text source: Endnote] | AH21: Proposes a closed-loop conceptual model of DTs for construction sites, structured as three functional boxes: F1 data acquisition (IoT/RFID), F2 data analysis and simulation, and F3 BIM transformation into a web-based model; it is grounded in the empirical Smart Twins 4.0 system, which tracked 151 formwork panels with RFID and a web-based BIM, finding 100% external and 98% internal defects. | AI21: Smart Twins 4.0 is limited to a single physical resource (formwork), has restricted data analysis capabilities and interoperability, and still requires manual steps in data collection; the model simplifies real-world complexity, omits human roles beyond decision-making, and the authors state it needs future testing in different contexts. | AJ21: Aligned | AK21: Smart Twins 4.0 links physical formworks to their virtual BIM counterparts through automatic database integration (RFID UHF tags read on Android, Firebase, Web-based Revit/Dynamo BIM), i.e. a shared object identity between tag data and BIM elements. | AL21: Medium
A22: 3828 | B22: Arhrib (2026) | C22: 2026 | E22: Serverless 3D Reconstruction and Spatial Anchoring for Cloud-Native In… | F22: Scopus | G22: Yes | H22: Yes | I22: Yes | J22: Yes | K22: Yes | L22: =IF(COUNTBLANK(G22:K22)=5,"",IF(COUNTIF(G22:K22,"No")>0,"EXCLUDE","INCLUDE")) -> INCLUDE | M22: =IF(L22<>"EXCLUDE","",IF(G22="No","Wrong domain (non-AECO)",IF(H22="No","Digital Twin not core / buzzword",IF(I22="No","No Design for Safety/Quality/PtD",IF(J22="No","Wrong publication type",IF(K22="No","Non-English","")))))) | N22: Yes | O22: Yes | P22: Yes | Q22: Yes | R22: Yes | S22: =IF(N22<>"Yes","",IF(COUNTBLANK(P22:R22)=3,"",IF(COUNTIF(P22:R22,"No")>0,"EXCLUDE","INCLUDE"))) -> INCLUDE | T22: =IF(S22<>"EXCLUDE","",IF(P22="No","Digital Twin mentioned only, not the subject",IF(Q22="No","No Design for Safety/Quality in full text",IF(R22="No","Methodology not codable","")))) | U22: Tier 1 - Digital Model (static, no live data) | V22: 0 | W22: 0 | X22: 1 | Y22: =IF(SUM(V22:X22)=0,"",IF(SUM(V22:X22)>=2,"Multi","Single")) -> Single | Z22: Design for Quality (DfQ) | AA22: None | AB22: Digital Twin platform (no machine learning) | AC22: Multi (two or more data types) | AD22: Single case study | AE22: 4 | AF22: Perception / Computer Vision | AG22: Serverless SfM/MVS pipeline + PostGIS defect anchors on real inspection datasets; defects as georeferenced 3D anchors support DfQ traceability; authors explicitly position against passive Level-1 twins, but no live link/learning: periodic re-scan workflow. [Full-text source: Endnote] | AH22: Addresses fragmented inspection data by replacing desktop photogrammetry with a serverless spatial intelligence hub: timeout-resilient orchestration of SfM/MVS, PostGIS-anchored defect records linked to georeferenced 3D meshes via raycasting and frustum-based image retrieval, end-to-end reconstruction in under one hour, sub-25 ms query latency, and over 90% image retrieval accuracy on two real UAV inspection datasets. | AI22: No automated defect detection: annotations are manually created by human inspectors, which the authors call the main bottleneck for scaling; validation covers only two UAV datasets, hyperparameters are not systematically optimized, and the system assumes reliable connectivity. Future work includes automated detection, temporal change monitoring, 3D Gaussian Splatting visualization, and offline capabilities. | AJ22: Aligned | AK22: Defect records are anchored to georeferenced 3D meshes in PostGIS via raycasting and frustum-based image retrieval, putting imagery-derived geometry and defect annotations in one spatial reference frame. | AL22: High
A23: 3662 | B23: Armijo (2024) | C23: 2024 | E23: Integration of Railway Bridge Structural Health Monitoring into the In… | F23: Scopus | G23: Yes | H23: Yes | I23: Yes | J23: Yes | K23: Yes | L23: =IF(COUNTBLANK(G23:K23)=5,"",IF(COUNTIF(G23:K23,"No")>0,"EXCLUDE","INCLUDE")) -> INCLUDE | M23: =IF(L23<>"EXCLUDE","",IF(G23="No","Wrong domain (non-AECO)",IF(H23="No","Digital Twin not core / buzzword",IF(I23="No","No Design for Safety/Quality/PtD",IF(J23="No","Wrong publication type",IF(K23="No","Non-English","")))))) | N23: Yes | O23: Yes | P23: Yes | Q23: Yes | R23: Yes | S23: =IF(N23<>"Yes","",IF(COUNTBLANK(P23:R23)=3,"",IF(COUNTIF(P23:R23,"No")>0,"EXCLUDE","INCLUDE"))) -> INCLUDE | T23: =IF(S23<>"EXCLUDE","",IF(P23="No","Digital Twin mentioned only, not the subject",IF(Q23="No","No Design for Safety/Quality in full text",IF(R23="No","Methodology not codable","")))) | U23: Tier 2 - Digital Shadow (one-way physical to virtual) | V23: 0 | W23: 0 | X23: 1 | Y23: =IF(SUM(V23:X23)=0,"",IF(SUM(V23:X23)>=2,"Multi","Single")) -> Single | Z23: Design for Safety (DfS) | AA23: Implemented | AB23: Other / Mixed | AC23: Single (one data type) | AD23: Single case study | AE23: 4 | AF23: Predictive analytics / decision support | AG23: 2-year in-service railway bridge pilot; unsupervised clustering of normal vibration + FEM-calibrated synthetic damage + LightGBM classifier (ROC-AUC 0.9999); periodic retraining of the model on accumulated data = implemented learning loop, but no convergence criterion/metric. [Full-text source: Endnote] | AH23: Demonstrates an operational digital twin for railway bridge SHM: low-cost wireless accelerometers (about EUR 300), hybrid edge-cloud processing with real-time FFT, unsupervised clustering of normal vibration, FEM-calibrated synthetic damage data, and a LightGBM classifier reaching ROC-AUC 0.9999 on two years of in-service vibration data from a bridge in the Basque Country. | AI23: Detection is anomaly-based rather than damage localization or quantification, which the authors list as future work; validation is limited to one short-span bridge pilot, and analytics still rely on middleware plus cloud, with plans to move FFT and inference onto energy-harvesting edge sensors and to extend to wind towers and broader production deployments. | AJ23: Single | AK23: Only ambient-vibration time series from wireless accelerometers feed the analytics; FEM-calibrated synthetic damage is model-generated training data, not a second measured data type. | AL23: High
A24: 3975 | B24: Aroquipa (2025) | C24: 2025 | E24: Methodological framework for integrating structural health monitoring … | F24: Web of Science | G24: Yes | H24: Yes | I24: Yes | J24: Yes | K24: Yes | L24: =IF(COUNTBLANK(G24:K24)=5,"",IF(COUNTIF(G24:K24,"No")>0,"EXCLUDE","INCLUDE")) -> INCLUDE | M24: =IF(L24<>"EXCLUDE","",IF(G24="No","Wrong domain (non-AECO)",IF(H24="No","Digital Twin not core / buzzword",IF(I24="No","No Design for Safety/Quality/PtD",IF(J24="No","Wrong publication type",IF(K24="No","Non-English","")))))) | N24: Yes | O24: Yes | P24: Yes | Q24: Yes | R24: Yes | S24: =IF(N24<>"Yes","",IF(COUNTBLANK(P24:R24)=3,"",IF(COUNTIF(P24:R24,"No")>0,"EXCLUDE","INCLUDE"))) -> INCLUDE | T24: =IF(S24<>"EXCLUDE","",IF(P24="No","Digital Twin mentioned only, not the subject",IF(Q24="No","No Design for Safety/Quality in full text",IF(R24="No","Methodology not codable","")))) | U24: Tier 1 - Digital Model (static, no live data) | V24: 0 | W24: 0 | X24: 1 | Y24: =IF(SUM(V24:X24)=0,"",IF(SUM(V24:X24)>=2,"Multi","Single")) -> Single | Z24: Design for Safety (DfS) | AA24: None | AB24: Finite Element Method / physics-based | AC24: Multi (two or more data types) | AD24: Conceptual (no test) | AE24: 4 | AF24: BIM-to-Digital-Twin architecture | AG24: Methodological framework for integrating SHM with numerical DT models for seismic assessment of heritage buildings (Basilica Maria Auxiliadora, Lima): numerical models in 3DEC and SAP2000 (modal + time-history of 34 seismic ground-motion records) identify susceptible zones and recommended sensor locations; sensor deployment and validation against experimental models are explicitly future work - no DT implemented, no live data link, no learning loop. [Full-text source: Endnote] | AH24: Provides a methodology for integrating SHM with numerical DT models for seismic assessment of heritage buildings: a LiDAR-derived BIM of the Basilica Maria Auxiliadora in Lima fed calibrated SAP2000 and 3DEC models (about 4500 block elements, 161000 contact zones), modal analysis with 220 modes, time-history analysis reproducing the 2007 Pisco earthquake crack patterns, and 25 sensor control points selected via intensity-duration-frequency plots. | AI24: No sensors are yet deployed: the study covers only Building Virtualization and part of sensor data analysis, so the EWS and DT feedback loop remain pending; validation relies on historical damage reports and analytical consistency, with future research to include experimental models, tri-axial sensor installation, and ambient-vibration calibration of the numerical model. | AJ24: Aligned | AK24: The LiDAR point-cloud survey is converted into a BIM that is linked to the 3DEC/SAP2000 FEM models through an explicit BIM-FEM linking process, sharing one building geometry frame while each model analyses separately. | AL24: Medium
A25: 3996 | B25: Arowoiya (2024) | C25: 2024 | E25: Driving Factors for the Adoption of Digital Twin Technology Implementa… | F25: Web of Science | G25: Yes | H25: Yes | I25: Yes | J25: Yes | K25: Yes | L25: =IF(COUNTBLANK(G25:K25)=5,"",IF(COUNTIF(G25:K25,"No")>0,"EXCLUDE","INCLUDE")) -> INCLUDE | M25: =IF(L25<>"EXCLUDE","",IF(G25="No","Wrong domain (non-AECO)",IF(H25="No","Digital Twin not core / buzzword",IF(I25="No","No Design for Safety/Quality/PtD",IF(J25="No","Wrong publication type",IF(K25="No","Non-English","")))))) | N25: Yes | O25: Yes | P25: No | Q25: Yes | R25: Yes | S25: =IF(N25<>"Yes","",IF(COUNTBLANK(P25:R25)=3,"",IF(COUNTIF(P25:R25,"No")>0,"EXCLUDE","INCLUDE"))) -> EXCLUDE | T25: =IF(S25<>"EXCLUDE","",IF(P25="No","Digital Twin mentioned only, not the subject",IF(Q25="No","No Design for Safety/Quality in full text",IF(R25="No","Methodology not codable","")))) -> Digital Twin mentioned only, not the subject | U25: Unclear | Y25: =IF(SUM(V25:X25)=0,"",IF(SUM(V25:X25)>=2,"Multi","Single")) | AG25: Questionnaire survey (Nigerian construction professionals, purposive+snowball) of drivers for adopting DTT; Shapiro-Wilk + Kruskal-Wallis H + factor analysis grouping drivers into innovation/operation/quality/performance/policy. No digital twin is built, evaluated or framed as a system — DT only appears as the technology whose adoption is surveyed. P=No → Stage-2 exclude. [Full-text source: Endnote]
A26: 4030 | E26: Excavator 3D pose estimation using deep learning and hybrid datasets | F26: Web of Science | G26: Yes | H26: No | I26: Yes | J26: Yes | K26: Yes | L26: =IF(COUNTBLANK(G26:K26)=5,"",IF(COUNTIF(G26:K26,"No")>0,"EXCLUDE","INCLUDE")) -> EXCLUDE | M26: =IF(L26<>"EXCLUDE","",IF(G26="No","Wrong domain (non-AECO)",IF(H26="No","Digital Twin not core / buzzword",IF(I26="No","No Design for Safety/Quality/PtD",IF(J26="No","Wrong publication type",IF(K26="No","Non-English","")))))) -> Digital Twin not core / buzzword | S26: =IF(N26<>"Yes","",IF(COUNTBLANK(P26:R26)=3,"",IF(COUNTIF(P26:R26,"No")>0,"EXCLUDE","INCLUDE"))) | T26: =IF(S26<>"EXCLUDE","",IF(P26="No","Digital Twin mentioned only, not the subject",IF(Q26="No","No Design for Safety/Quality in full text",IF(R26="No","Methodology not codable","")))) | Y26: =IF(SUM(V26:X26)=0,"",IF(SUM(V26:X26)>=2,"Multi","Single")) | AG26: CV pose estimation; DT only synthesizes training data
A27: 3982 | E27: Integrating Web-Based Weather Data into Building Information Modeling … | F27: Web of Science | G27: Yes | H27: No | I27: Yes | J27: Yes | K27: Yes | L27: =IF(COUNTBLANK(G27:K27)=5,"",IF(COUNTIF(G27:K27,"No")>0,"EXCLUDE","INCLUDE")) -> EXCLUDE | M27: =IF(L27<>"EXCLUDE","",IF(G27="No","Wrong domain (non-AECO)",IF(H27="No","Digital Twin not core / buzzword",IF(I27="No","No Design for Safety/Quality/PtD",IF(J27="No","Wrong publication type",IF(K27="No","Non-English","")))))) -> Digital Twin not core / buzzword | S27: =IF(N27<>"Yes","",IF(COUNTBLANK(P27:R27)=3,"",IF(COUNTIF(P27:R27,"No")>0,"EXCLUDE","INCLUDE"))) | T27: =IF(S27<>"EXCLUDE","",IF(P27="No","Digital Twin mentioned only, not the subject",IF(Q27="No","No Design for Safety/Quality in full text",IF(R27="No","Methodology not codable","")))) | Y27: =IF(SUM(V27:X27)=0,"",IF(SUM(V27:X27)>=2,"Multi","Single")) | AG27: BIM+RPA weather alerts; static BIM, no live DT
A28: 3940 | E28: Circular economy in construction: The digital transformation perspecti… | F28: Web of Science | G28: Yes | H28: No | I28: No | J28: Yes | K28: Yes | L28: =IF(COUNTBLANK(G28:K28)=5,"",IF(COUNTIF(G28:K28,"No")>0,"EXCLUDE","INCLUDE")) -> EXCLUDE | M28: =IF(L28<>"EXCLUDE","",IF(G28="No","Wrong domain (non-AECO)",IF(H28="No","Digital Twin not core / buzzword",IF(I28="No","No Design for Safety/Quality/PtD",IF(J28="No","Wrong publication type",IF(K28="No","Non-English","")))))) -> Digital Twin not core / buzzword | S28: =IF(N28<>"Yes","",IF(COUNTBLANK(P28:R28)=3,"",IF(COUNTIF(P28:R28,"No")>0,"EXCLUDE","INCLUDE"))) | T28: =IF(S28<>"EXCLUDE","",IF(P28="No","Digital Twin mentioned only, not the subject",IF(Q28="No","No Design for Safety/Quality in full text",IF(R28="No","Methodology not codable","")))) | Y28: =IF(SUM(V28:X28)=0,"",IF(SUM(V28:X28)>=2,"Multi","Single")) | AG28: CE/digitalisation review; DT peripheral
A29: 4037 | B29: Bao (2026) | C29: 2026 | E29: Intelligent technologies for tunnel construction and maintenance: A st… | F29: Web of Science | G29: Yes | H29: Yes | I29: Yes | J29: Yes | K29: Yes | L29: =IF(COUNTBLANK(G29:K29)=5,"",IF(COUNTIF(G29:K29,"No")>0,"EXCLUDE","INCLUDE")) -> INCLUDE | M29: =IF(L29<>"EXCLUDE","",IF(G29="No","Wrong domain (non-AECO)",IF(H29="No","Digital Twin not core / buzzword",IF(I29="No","No Design for Safety/Quality/PtD",IF(J29="No","Wrong publication type",IF(K29="No","Non-English","")))))) | N29: Yes | O29: Yes | P29: No | Q29: Yes | R29: Yes | S29: =IF(N29<>"Yes","",IF(COUNTBLANK(P29:R29)=3,"",IF(COUNTIF(P29:R29,"No")>0,"EXCLUDE","INCLUDE"))) -> EXCLUDE | T29: =IF(S29<>"EXCLUDE","",IF(P29="No","Digital Twin mentioned only, not the subject",IF(Q29="No","No Design for Safety/Quality in full text",IF(R29="No","Methodology not codable","")))) -> Digital Twin mentioned only, not the subject | U29: Unclear | Y29: =IF(SUM(V29:X29)=0,"",IF(SUM(V29:X29)>=2,"Multi","Single")) | AG29: State-of-the-art review of intelligent tunnel construction & O&M technologies (IoT, big data, AI, platforms) across design/construction/O&M; digital twins appear as one component (geological DTs, future DT co-simulation) but are not the actual subject of the paper. P=No → Stage-2 exclude. Safety/risk is a genuine theme (construction safety, real-time risk analysis). [Full-text source: Endnote]
A30: 3551 | E30: Improving Organizational and Engineering Reliability during Dismantlin… | F30: Scopus | G30: Yes | H30: No | I30: Yes | J30: Yes | K30: No | L30: =IF(COUNTBLANK(G30:K30)=5,"",IF(COUNTIF(G30:K30,"No")>0,"EXCLUDE","INCLUDE")) -> EXCLUDE | M30: =IF(L30<>"EXCLUDE","",IF(G30="No","Wrong domain (non-AECO)",IF(H30="No","Digital Twin not core / buzzword",IF(I30="No","No Design for Safety/Quality/PtD",IF(J30="No","Wrong publication type",IF(K30="No","Non-English","")))))) -> Digital Twin not core / buzzword | S30: =IF(N30<>"Yes","",IF(COUNTBLANK(P30:R30)=3,"",IF(COUNTIF(P30:R30,"No")>0,"EXCLUDE","INCLUDE"))) | T30: =IF(S30<>"EXCLUDE","",IF(P30="No","Digital Twin mentioned only, not the subject",IF(Q30="No","No Design for Safety/Quality in full text",IF(R30="No","Methodology not codable","")))) | Y30: =IF(SUM(V30:X30)=0,"",IF(SUM(V30:X30)>=2,"Multi","Single")) | AG30: Russian journal; BIM/DT mentioned, full text non-English
A31: 3571 | E31: The Process of Digitalization of the Urban Environment for the Develop… | F31: Scopus | G31: Yes | H31: No | I31: No | J31: Yes | K31: Yes | L31: =IF(COUNTBLANK(G31:K31)=5,"",IF(COUNTIF(G31:K31,"No")>0,"EXCLUDE","INCLUDE")) -> EXCLUDE | M31: =IF(L31<>"EXCLUDE","",IF(G31="No","Wrong domain (non-AECO)",IF(H31="No","Digital Twin not core / buzzword",IF(I31="No","No Design for Safety/Quality/PtD",IF(J31="No","Wrong publication type",IF(K31="No","Non-English","")))))) -> Digital Twin not core / buzzword | S31: =IF(N31<>"Yes","",IF(COUNTBLANK(P31:R31)=3,"",IF(COUNTIF(P31:R31,"No")>0,"EXCLUDE","INCLUDE"))) | T31: =IF(S31<>"EXCLUDE","",IF(P31="No","Digital Twin mentioned only, not the subject",IF(Q31="No","No Design for Safety/Quality in full text",IF(R31="No","Methodology not codable","")))) | Y31: =IF(SUM(V31:X31)=0,"",IF(SUM(V31:X31)>=2,"Multi","Single")) | AG31: Urban regeneration protocol; DT as future archive
A32: 3707 | E32: Construction and application of digital twin system for coal ports | F32: Scopus | G32: No | H32: Yes | I32: Yes | J32: Yes | K32: No | L32: =IF(COUNTBLANK(G32:K32)=5,"",IF(COUNTIF(G32:K32,"No")>0,"EXCLUDE","INCLUDE")) -> EXCLUDE | M32: =IF(L32<>"EXCLUDE","",IF(G32="No","Wrong domain (non-AECO)",IF(H32="No","Digital Twin not core / buzzword",IF(I32="No","No Design for Safety/Quality/PtD",IF(J32="No","Wrong publication type",IF(K32="No","Non-English","")))))) -> Wrong domain (non-AECO) | S32: =IF(N32<>"Yes","",IF(COUNTBLANK(P32:R32)=3,"",IF(COUNTIF(P32:R32,"No")>0,"EXCLUDE","INCLUDE"))) | T32: =IF(S32<>"EXCLUDE","",IF(P32="No","Digital Twin mentioned only, not the subject",IF(Q32="No","No Design for Safety/Quality in full text",IF(R32="No","Methodology not codable","")))) | Y32: =IF(SUM(V32:X32)=0,"",IF(SUM(V32:X32)>=2,"Multi","Single")) | AG32: Industrial port ops; Chinese journal, non-English
A33: 3613 | E33: Incorporation of pre-existing longitudinal cracks in finite element an… | F33: Scopus | G33: Yes | H33: No | I33: Yes | J33: Yes | K33: Yes | L33: =IF(COUNTBLANK(G33:K33)=5,"",IF(COUNTIF(G33:K33,"No")>0,"EXCLUDE","INCLUDE")) -> EXCLUDE | M33: =IF(L33<>"EXCLUDE","",IF(G33="No","Wrong domain (non-AECO)",IF(H33="No","Digital Twin not core / buzzword",IF(I33="No","No Design for Safety/Quality/PtD",IF(J33="No","Wrong publication type",IF(K33="No","Non-English","")))))) -> Digital Twin not core / buzzword | S33: =IF(N33<>"Yes","",IF(COUNTBLANK(P33:R33)=3,"",IF(COUNTIF(P33:R33,"No")>0,"EXCLUDE","INCLUDE"))) | T33: =IF(S33<>"EXCLUDE","",IF(P33="No","Digital Twin mentioned only, not the subject",IF(Q33="No","No Design for Safety/Quality in full text",IF(R33="No","Methodology not codable","")))) | Y33: =IF(SUM(V33:X33)=0,"",IF(SUM(V33:X33)>=2,"Multi","Single")) | AG33: Pure FEM structural analysis; no DT
A34: 3645 | E34: The evolution of BIM work standards: current, best, and future practic… | F34: Scopus | G34: Yes | H34: No | I34: No | J34: Yes | K34: Yes | L34: =IF(COUNTBLANK(G34:K34)=5,"",IF(COUNTIF(G34:K34,"No")>0,"EXCLUDE","INCLUDE")) -> EXCLUDE | M34: =IF(L34<>"EXCLUDE","",IF(G34="No","Wrong domain (non-AECO)",IF(H34="No","Digital Twin not core / buzzword",IF(I34="No","No Design for Safety/Quality/PtD",IF(J34="No","Wrong publication type",IF(K34="No","Non-English","")))))) -> Digital Twin not core / buzzword | S34: =IF(N34<>"Yes","",IF(COUNTBLANK(P34:R34)=3,"",IF(COUNTIF(P34:R34,"No")>0,"EXCLUDE","INCLUDE"))) | T34: =IF(S34<>"EXCLUDE","",IF(P34="No","Digital Twin mentioned only, not the subject",IF(Q34="No","No Design for Safety/Quality in full text",IF(R34="No","Methodology not codable","")))) | Y34: =IF(SUM(V34:X34)=0,"",IF(SUM(V34:X34)>=2,"Multi","Single")) | AG34: BIM-manager narrative review; no DT core
A35: 3807 | E35: Railway condition information modelling in a BIM framework for mainten… | F35: Scopus | G35: Yes | H35: No | I35: Yes | J35: Yes | K35: Yes | L35: =IF(COUNTBLANK(G35:K35)=5,"",IF(COUNTIF(G35:K35,"No")>0,"EXCLUDE","INCLUDE")) -> EXCLUDE | M35: =IF(L35<>"EXCLUDE","",IF(G35="No","Wrong domain (non-AECO)",IF(H35="No","Digital Twin not core / buzzword",IF(I35="No","No Design for Safety/Quality/PtD",IF(J35="No","Wrong publication type",IF(K35="No","Non-English","")))))) -> Digital Twin not core / buzzword | S35: =IF(N35<>"Yes","",IF(COUNTBLANK(P35:R35)=3,"",IF(COUNTIF(P35:R35,"No")>0,"EXCLUDE","INCLUDE"))) | T35: =IF(S35<>"EXCLUDE","",IF(P35="No","Digital Twin mentioned only, not the subject",IF(Q35="No","No Design for Safety/Quality in full text",IF(R35="No","Methodology not codable","")))) | Y35: =IF(SUM(V35:X35)=0,"",IF(SUM(V35:X35)>=2,"Multi","Single")) | AG35: I-BIM maintenance framework; DT aspirational
A36: 3595 | B36: Brucherseifer (2021) | C36: 2021 | E36: Digital Twin conceptual framework for improving critical infrastructur… | F36: Scopus | G36: Yes | H36: Yes | I36: Yes | J36: Yes | K36: Yes | L36: =IF(COUNTBLANK(G36:K36)=5,"",IF(COUNTIF(G36:K36,"No")>0,"EXCLUDE","INCLUDE")) -> INCLUDE | M36: =IF(L36<>"EXCLUDE","",IF(G36="No","Wrong domain (non-AECO)",IF(H36="No","Digital Twin not core / buzzword",IF(I36="No","No Design for Safety/Quality/PtD",IF(J36="No","Wrong publication type",IF(K36="No","Non-English","")))))) | N36: Yes | O36: Yes | P36: Yes | Q36: Yes | R36: Yes | S36: =IF(N36<>"Yes","",IF(COUNTBLANK(P36:R36)=3,"",IF(COUNTIF(P36:R36,"No")>0,"EXCLUDE","INCLUDE"))) -> INCLUDE | T36: =IF(S36<>"EXCLUDE","",IF(P36="No","Digital Twin mentioned only, not the subject",IF(Q36="No","No Design for Safety/Quality in full text",IF(R36="No","Methodology not codable","")))) | U36: Tier 1 - Digital Model (static, no live data) | V36: 0 | W36: 0 | X36: 1 | Y36: =IF(SUM(V36:X36)=0,"",IF(SUM(V36:X36)>=2,"Multi","Single")) -> Single | Z36: Design for Safety (DfS) | AA36: None | AB36: Digital Twin platform (no machine learning) | AC36: Multi (two or more data types) | AD36: Conceptual (no test) | AE36: 3 | AF36: Lifecycle / governance | AG36: Digital Twin Conceptual Framework for critical infrastructure resilience (DLR): comprehensive requirements analysis for infrastructure crisis management/resilience, deriving a conceptual framework (virtual replica, virtual clones, smart-tool toolbox, human-operated control center) with guiding principles for construction/planning phases and a conceptual DT model; resilience cycle with learning from past events is discussed conceptually but not implemented; no DT built or validated, no learning loop. [Full-text source: Endnote] | AH36: Derives a comprehensive requirements analysis for critical infrastructure crisis management and resilience and maps it onto a Digital Twin Conceptual Framework with four guiding principles (human-in-the-loop control, parsimony with accepted uncertainty, preparedness for complexity and emergence, safe experiments and training) plus a conceptual model of virtual replica, clones, toolbox, and control center. | AI36: Entirely conceptual: no implementation, prototype, or case evaluation is presented, so none of the requirements or tools is tested. The authors list open challenges of integrating uncertain data sources and heterogeneous models, evaluating intelligent tools for the resilience cycle, and IT scalability and reliability, proposing federated digital twins instead of monolithic implementations. | AJ36: Unclear | AK36: Conceptual resilience framework for critical infrastructure; no implementation, prototype or case evaluation, so no integration mechanism can be identified. | AL36: High
A37: 3888 | E37: From BIM to Web3: A critical interpretive synthesis of present and eme… | F37: Web of Science | G37: Yes | H37: No | I37: No | J37: Yes | K37: Yes | L37: =IF(COUNTBLANK(G37:K37)=5,"",IF(COUNTIF(G37:K37,"No")>0,"EXCLUDE","INCLUDE")) -> EXCLUDE | M37: =IF(L37<>"EXCLUDE","",IF(G37="No","Wrong domain (non-AECO)",IF(H37="No","Digital Twin not core / buzzword",IF(I37="No","No Design for Safety/Quality/PtD",IF(J37="No","Wrong publication type",IF(K37="No","Non-English","")))))) -> Digital Twin not core / buzzword | S37: =IF(N37<>"Yes","",IF(COUNTBLANK(P37:R37)=3,"",IF(COUNTIF(P37:R37,"No")>0,"EXCLUDE","INCLUDE"))) | T37: =IF(S37<>"EXCLUDE","",IF(P37="No","Digital Twin mentioned only, not the subject",IF(Q37="No","No Design for Safety/Quality in full text",IF(R37="No","Methodology not codable","")))) | Y37: =IF(SUM(V37:X37)=0,"",IF(SUM(V37:X37)>=2,"Multi","Single")) | AG37: Data-management review; no DT core, no safety/quality
A38: 3869 | E38: Affective computing in smart city spaces: Research on emotion recognit… | F38: Scopus | G38: No | H38: No | I38: No | J38: Yes | K38: Yes | L38: =IF(COUNTBLANK(G38:K38)=5,"",IF(COUNTIF(G38:K38,"No")>0,"EXCLUDE","INCLUDE")) -> EXCLUDE | M38: =IF(L38<>"EXCLUDE","",IF(G38="No","Wrong domain (non-AECO)",IF(H38="No","Digital Twin not core / buzzword",IF(I38="No","No Design for Safety/Quality/PtD",IF(J38="No","Wrong publication type",IF(K38="No","Non-English","")))))) -> Wrong domain (non-AECO) | S38: =IF(N38<>"Yes","",IF(COUNTBLANK(P38:R38)=3,"",IF(COUNTIF(P38:R38,"No")>0,"EXCLUDE","INCLUDE"))) | T38: =IF(S38<>"EXCLUDE","",IF(P38="No","Digital Twin mentioned only, not the subject",IF(Q38="No","No Design for Safety/Quality in full text",IF(R38="No","Methodology not codable","")))) | Y38: =IF(SUM(V38:X38)=0,"",IF(SUM(V38:X38)>=2,"Multi","Single")) | AG38: Emotion recognition; no built asset, no safety/quality
