Workbook

Sheet 0_Guide
B2: One Matrix - Four Steps (LLM-ready, no background assumed)
B3: A single progressive-disclosure matrix for screening, coding, deep-read analysis and reporting.
B5: CONTEXT PRIMER (read this before coding any paper)
B6: What is this review about | C6: This is a systematic literature review about DIGITAL TWINS used in the built-environment industry, specifically to improve SAFETY and QUALITY of designs. You are screening and coding academic papers.
B7: AECO | C7: AECO = Architecture, Engineering, Construction and Operations. It means the built-environment / construction industry (buildings, bridges, infrastructure, civil engineering). NOT manufacturing, automotive, aerospace, power/electrical equipment, healthcare, or agriculture.
B8: Digital Twin (DT) | C8: A Digital Twin is a live virtual replica of a physical asset that is connected to it by data. It is MORE than a static 3D/BIM model. If a paper only says the words 'digital twin' in passing but does not actually build or study one, treat DT as a buzzword (answer 'No').
B9: Design for Safety (DfS) | C9: Design for Safety = designing to prevent construction/operation safety incidents (e.g. fall from height, hazards, accident prevention).
B10: Design for Quality (DfQ) | C10: Design for Quality = designing to prevent defects, rework, or quality failures.
B11: Prevention through Design (PtD) | C11: Prevention through Design = the principle of eliminating risks at the design stage before construction begins. Closely related to DfS/DfQ.
B12: BIM | C12: BIM = Building Information Modelling. A static, design-stage digital model. A BIM model alone is NOT a Digital Twin (no live data link).
B13: bidirectional | C13: 'bidirectional' means data flows BOTH ways: physical->virtual AND virtual->physical (the twin can act back on the real asset). One-way data flow is only a 'digital shadow'.
B14: Answer format | C14: Every Stage-1 and Stage-2 question is answered strictly as 'Yes' or 'No'. If genuinely unsure from the abstract, answer 'No' (conservative) and add a note. Do not invent information not present in the text.
B15: One reason only | C15: When a paper is excluded, the matrix auto-picks ONE standardized reason by priority. You do not write the reason yourself.
B17: THE FOUR STEPS
B18: Step 1 (all 450 papers) | C18: An LLM or reviewer fills the AMBER Stage-1 columns (G-K) for EVERY paper, from the TITLE and ABSTRACT only. Column L auto-decides Include/Exclude; column M auto-writes the single exclusion reason.
B19: Step 2 (the matrix) | C19: This workbook IS the summary matrix. There is nothing separate to generate.
B20: Retrieval + PDF gateway | C20: For Stage-1 includes, first mark column N 'PDF full text on hand?'. This is the gateway: only papers with the PDF on hand can be deep-read. You can revisit later - when a PDF is found, change N from 'No' to 'Yes' and the paper becomes ready for Stage-2/3.
B21: Step 3 (deep read) | C21: For papers whose PDF is on hand, fill the RED Stage-2 columns (P-R) and then the GREEN synthesis 'angle' columns (U-AG). These are the evidence for your findings section.
B22: Step 4 (report) | C22: Open 'Step1_Report' (screening + PRISMA chain + exclusion reasons) and 'Step3_Report' (capability-tier / phase / method / modality / validation / self-improvement tables). Both auto-tally from the same rows.
B24: COLOUR KEY
B25: Bands | C25: AMBER = Stage-1 input (from abstract) · BLUE = PDF gateway · RED = Stage-2 input (from full text) · GREEN = Stage-3 deep-read input · BLUE-GREY = auto formula, do not edit.
B26: Golden rule | C26: Never delete a paper. A paper excluded at any stage stays in the matrix with its reason recorded. This is what makes the PRISMA flow reproducible.

Sheet 1_CodeLists
A1: YN | B1: Src | C1: Bin | D1: Tier | E1: DfX | F1: Self | G1: Method | H1: Modality | I1: Valid | J1: Cluster | K1: Fusion | L1: Conf
A2: Yes | B2: Scopus | C2: 0 | D2: Tier 1 - Digital Model (static, no live data) | E2: Design for Safety (DfS) | F2: None | G2: Computer Vision / CNN / object-detection | H2: Single (one data type) | I2: Conceptual (no test) | J2: BIM-to-Digital-Twin architecture | K2: Single | L2: High
A3: No | B3: Web of Science | C3: 1 | D3: Tier 2 - Digital Shadow (one-way physical to virtual) | E3: Design for Quality (DfQ) | F3: Mentioned only | G3: Graph Neural Network (GNN) | H3: Multi (two or more data types) | I3: Simulation | J3: Semantic interoperability | K3: Co-present | L3: Medium
B4: Lens.org | D4: Tier 3 - Digital Twin (bidirectional, two-way) | E4: Both | F4: Implemented | G4: LSTM / RNN (recurrent networks) | I4: Lab / scale-model experiment | J4: Perception / Computer Vision | K4: Aligned | L4: Low
B5: Backward-snowball | D5: Tier 4 - Cognitive / Self-improving | E5: Other | F5: Convergence-characterised | G5: Transformer / Large Language Model (LLM) | I5: Single case study | J5: Design for Safety | K5: Fused
B6: Forward-snowball | D6: Unclear | G6: Reinforcement Learning (RL) | I6: Cross-project (multiple real projects) | J6: Predictive analytics / decision support | K6: Unclear
G7: Bayesian / probabilistic | J7: Lifecycle / governance
G8: Agent-based model (ABM) | J8: Other
G9: Finite Element Method / physics-based
G10: Ontology / semantic
G11: Statistical / change-point
G12: Digital Twin platform (no machine learning)
G13: Other / Mixed

Sheet Matrix
P1: a | Q1: b | R1: c | T1: d - 2nd duplicate
G2: a | H2: b | I2: c | K2: e | L2: =COUNTIF(L4:L501,"Exclude") -> 262 | N2: =COUNTIF(N4:N469,"No") -> 2 | O2: =COUNTIF(O4:O469,"No") -> 2 | P2: =COUNTIF(P4:P469,"No") -> 10 | Q2: =COUNTIF(Q4:Q469,"No") -> 3 | R2: =COUNTIF(R4:R469,"No") -> 6 | S2: =COUNTIF(S4:S469,"Exclude") -> 13 | T2: 2
A3: =COUNTA(A5:A502) -> 429 | G3: =COUNTIF(G4:G469,"No") -> 99 | H3: =COUNTIF(H4:H469,"No") -> 133 | I3: =COUNTIF(I4:I469,"No") -> 101 | J3: =COUNTIF(J4:J469,"No") -> 0 | K3: =COUNTIF(K4:K469,"No") -> 59 | L3: =COUNTIF(L4:L469,"Include") -> 167 | N3: =COUNTIF(N4:N469,"Yes") -> 165 | O3: =COUNTIF(O4:O469,"Yes") -> 165 | P3: =COUNTIF(P4:P469,"Yes") -> 153 | Q3: =COUNTIF(Q4:Q469,"Yes") -> 160 | R3: =COUNTIF(R4:R469,"Yes") -> 157 | S3: =COUNTIF(S4:S469,"Include")-T2 -> 150
A4: ID | B4: Authors (year) | C4: Year | D4: Journal | E4: Title | F4: Source database | G4: Stage1: Domain is AECO (built environment)? | H4: Stage1: Digital Twin is core (not just a buzzword)? | I4: Stage1: About Design for Safety / Quality / Prevention through Design? | J4: Stage1: Publication type OK (journal/conference article, not editorial/erratum)? | K4: Stage1: Written in English (full text)? | L4: STAGE-1 decision | M4: Stage-1 exclusion reason (auto) | N4: GATEWAY: PDF full text on hand? (change to Yes when found) | O4: Full text retrieved for PRISMA? | P4: Stage2: Digital Twin is the actual subject (full text)? | Q4: Stage2: Design for Safety/Quality confirmed in full text? | R4: Stage2: Methodology is clear enough to code? | S4: STAGE-2 decision | T4: Stage-2 exclusion reason (auto) | U4: Deep-read: Digital Twin capability tier | V4: Phase: Design (1/0) | W4: Phase: Construction (1/0) | X4: Phase: Operation (1/0) | Y4: Cross-phase? (auto) | Z4: Deep-read: Design-for-X target | AA4: Deep-read: Self-improvement / convergence | AB4: Deep-read: Methodology | AC4: Deep-read: Data modality | AD4: Deep-read: Validation level | AE4: Deep-read: Quality appraisal score (0 to 5) | AF4: Deep-read: Thematic cluster | AG4: Deep-read: Key evidence / notes | AH4: Deep-read: Strength / research gap filled | AI4: Deep-read: Deficiencies & future work | AJ4: Deep-read: Fusion depth (AC1) | AK4: Deep-read: Fusion evidence (AC2) | AL4: Deep-read: Fusion confidence (AC3) | AM4: Fusion coding flag (review) | AN4: Full-text verification (date, source, outcome) | AO4: DOI
A5: 3566 | E5: =IF($A5="","",IFERROR(_xlfn.XLOOKUP($A5,'2_DOI_Lookup'!$D$2:$D$430,'2_DOI_Lookup'!$E$2:$E$430),"TITLE NOT IN SOURCE")) -> An association rule mining model for the application of construction technologies during COVID-19 | F5: Scopus | G5: Yes | H5: No | I5: No | J5: Yes | K5: Yes | L5: =IF(COUNTBLANK(G5:K5)=5,"",IF(COUNTIF(G5:K5,"No")>0,"EXCLUDE","INCLUDE")) -> EXCLUDE | M5: =IF(L5<>"EXCLUDE","",IF(G5="No","Wrong domain (non-AECO)",IF(H5="No","Digital Twin not core / buzzword",IF(I5="No","No Design for Safety/Quality/PtD",IF(J5="No","Wrong publication type",IF(K5="No","Non-English","")))))) -> Digital Twin not core / buzzword | S5: =IF(N5<>"Yes","",IF(COUNTBLANK(P5:R5)=3,"",IF(COUNTIF(P5:R5,"No")>0,"EXCLUDE","INCLUDE"))) | T5: =IF(S5<>"EXCLUDE","",IF(P5="No","Digital Twin mentioned only, not the subject",IF(Q5="No","No Design for Safety/Quality in full text",IF(R5="No","Methodology not codable","")))) | Y5: =IF(SUM(V5:X5)=0,"",IF(SUM(V5:X5)>=2,"Multi","Single")) | AG5: Tech-adoption survey (ARM); no DT, no DfS/DfQ focus | AO5: =IF($A5="","",IFERROR(_xlfn.XLOOKUP($A5,'2_DOI_Lookup'!$A$2:$A$430,'2_DOI_Lookup'!$B$2:$B$430),"NOT IN SOURCE")) -> 10.1080/15623599.2023.2212420
A6: 3741 | E6: =IF($A6="","",IFERROR(_xlfn.XLOOKUP($A6,'2_DOI_Lookup'!$D$2:$D$430,'2_DOI_Lookup'!$E$2:$E$430),"TITLE NOT IN SOURCE")) -> Digital twin and AI-driven smart adaptive walls for energy, comfort and carbon optimization in intelligent green buildings | F6: Scopus | G6: Yes | H6: Yes | I6: No | J6: Yes | K6: Yes | L6: =IF(COUNTBLANK(G6:K6)=5,"",IF(COUNTIF(G6:K6,"No")>0,"EXCLUDE","INCLUDE")) -> EXCLUDE | M6: =IF(L6<>"EXCLUDE","",IF(G6="No","Wrong domain (non-AECO)",IF(H6="No","Digital Twin not core / buzzword",IF(I6="No","No Design for Safety/Quality/PtD",IF(J6="No","Wrong publication type",IF(K6="No","Non-English","")))))) -> No Design for Safety/Quality/PtD | S6: =IF(N6<>"Yes","",IF(COUNTBLANK(P6:R6)=3,"",IF(COUNTIF(P6:R6,"No")>0,"EXCLUDE","INCLUDE"))) | T6: =IF(S6<>"EXCLUDE","",IF(P6="No","Digital Twin mentioned only, not the subject",IF(Q6="No","No Design for Safety/Quality in full text",IF(R6="No","Methodology not codable","")))) | Y6: =IF(SUM(V6:X6)=0,"",IF(SUM(V6:X6)>=2,"Multi","Single")) | AG6: Energy/comfort/carbon optimization; safety shield is control constraint (edge 5) | AO6: =IF($A6="","",IFERROR(_xlfn.XLOOKUP($A6,'2_DOI_Lookup'!$A$2:$A$430,'2_DOI_Lookup'!$B$2:$B$430),"NOT IN SOURCE")) -> 10.1016/j.energy.2026.140990
A7: 3665 | E7: =IF($A7="","",IFERROR(_xlfn.XLOOKUP($A7,'2_DOI_Lookup'!$D$2:$D$430,'2_DOI_Lookup'!$E$2:$E$430),"TITLE NOT IN SOURCE")) -> Enhancing attack resilience of cyber-physical systems through state dependency graph models | F7: Scopus | G7: No | H7: No | I7: No | J7: Yes | K7: Yes | L7: =IF(COUNTBLANK(G7:K7)=5,"",IF(COUNTIF(G7:K7,"No")>0,"EXCLUDE","INCLUDE")) -> EXCLUDE | M7: =IF(L7<>"EXCLUDE","",IF(G7="No","Wrong domain (non-AECO)",IF(H7="No","Digital Twin not core / buzzword",IF(I7="No","No Design for Safety/Quality/PtD",IF(J7="No","Wrong publication type",IF(K7="No","Non-English","")))))) -> Wrong domain (non-AECO) | S7: =IF(N7<>"Yes","",IF(COUNTBLANK(P7:R7)=3,"",IF(COUNTIF(P7:R7,"No")>0,"EXCLUDE","INCLUDE"))) | T7: =IF(S7<>"EXCLUDE","",IF(P7="No","Digital Twin mentioned only, not the subject",IF(Q7="No","No Design for Safety/Quality in full text",IF(R7="No","Methodology not codable","")))) | Y7: =IF(SUM(V7:X7)=0,"",IF(SUM(V7:X7)>=2,"Multi","Single")) | AG7: Cybersecurity of industrial CPS/SCADA; not AECO | AO7: =IF($A7="","",IFERROR(_xlfn.XLOOKUP($A7,'2_DOI_Lookup'!$A$2:$A$430,'2_DOI_Lookup'!$B$2:$B$430),"NOT IN SOURCE")) -> 10.1007/s10207-023-00731-w
A8: 3657 | E8: =IF($A8="","",IFERROR(_xlfn.XLOOKUP($A8,'2_DOI_Lookup'!$D$2:$D$430,'2_DOI_Lookup'!$E$2:$E$430),"TITLE NOT IN SOURCE")) -> IoT-Driven Resilience Monitoring: Case Study of a Cyber-Physical System | F8: Scopus | G8: No | H8: Yes | I8: No | J8: Yes | K8: Yes | L8: =IF(COUNTBLANK(G8:K8)=5,"",IF(COUNTIF(G8:K8,"No")>0,"EXCLUDE","INCLUDE")) -> EXCLUDE | M8: =IF(L8<>"EXCLUDE","",IF(G8="No","Wrong domain (non-AECO)",IF(H8="No","Digital Twin not core / buzzword",IF(I8="No","No Design for Safety/Quality/PtD",IF(J8="No","Wrong publication type",IF(K8="No","Non-English","")))))) -> Wrong domain (non-AECO) | S8: =IF(N8<>"Yes","",IF(COUNTBLANK(P8:R8)=3,"",IF(COUNTIF(P8:R8,"No")>0,"EXCLUDE","INCLUDE"))) | T8: =IF(S8<>"EXCLUDE","",IF(P8="No","Digital Twin mentioned only, not the subject",IF(Q8="No","No Design for Safety/Quality in full text",IF(R8="No","Methodology not codable","")))) | Y8: =IF(SUM(V8:X8)=0,"",IF(SUM(V8:X8)>=2,"Multi","Single")) | AG8: Smart energy systems CI; not built environment | AO8: =IF($A8="","",IFERROR(_xlfn.XLOOKUP($A8,'2_DOI_Lookup'!$A$2:$A$430,'2_DOI_Lookup'!$B$2:$B$430),"NOT IN SOURCE")) -> 10.3390/app15042092
A9: 3685 | E9: =IF($A9="","",IFERROR(_xlfn.XLOOKUP($A9,'2_DOI_Lookup'!$D$2:$D$430,'2_DOI_Lookup'!$E$2:$E$430),"TITLE NOT IN SOURCE")) -> Virtual Fencing for Safety-Critical Cyber-Physical Systems: Computer-Vision Enabled Digital Twins | F9: Scopus | G9: No | H9: Yes | I9: No | J9: Yes | K9: Yes | L9: =IF(COUNTBLANK(G9:K9)=5,"",IF(COUNTIF(G9:K9,"No")>0,"EXCLUDE","INCLUDE")) -> EXCLUDE | M9: =IF(L9<>"EXCLUDE","",IF(G9="No","Wrong domain (non-AECO)",IF(H9="No","Digital Twin not core / buzzword",IF(I9="No","No Design for Safety/Quality/PtD",IF(J9="No","Wrong publication type",IF(K9="No","Non-English","")))))) -> Wrong domain (non-AECO) | S9: =IF(N9<>"Yes","",IF(COUNTBLANK(P9:R9)=3,"",IF(COUNTIF(P9:R9,"No")>0,"EXCLUDE","INCLUDE"))) | T9: =IF(S9<>"EXCLUDE","",IF(P9="No","Digital Twin mentioned only, not the subject",IF(Q9="No","No Design for Safety/Quality in full text",IF(R9="No","Methodology not codable","")))) | Y9: =IF(SUM(V9:X9)=0,"",IF(SUM(V9:X9)>=2,"Multi","Single")) | AG9: Crowd management/surveillance; no built asset DfS/DfQ | AO9: =IF($A9="","",IFERROR(_xlfn.XLOOKUP($A9,'2_DOI_Lookup'!$A$2:$A$430,'2_DOI_Lookup'!$B$2:$B$430),"NOT IN SOURCE")) -> 10.1109/ACCESS.2025.3581041
A10: 3756 | B10: Ahmad (2025) | C10: 2025 | E10: =IF($A10="","",IFERROR(_xlfn.XLOOKUP($A10,'2_DOI_Lookup'!$D$2:$D$430,'2_DOI_Lookup'!$E$2:$E$430),"TITLE NOT IN SOURCE")) -> Lessons Learned from the Real-World Deployment of Multisensor Fusion for Proactive Work Zone Safety Application | F10: Scopus | G10: Yes | H10: Yes | I10: Yes | J10: Yes | K10: Yes | L10: =IF(COUNTBLANK(G10:K10)=5,"",IF(COUNTIF(G10:K10,"No")>0,"EXCLUDE","INCLUDE")) -> INCLUDE | M10: =IF(L10<>"EXCLUDE","",IF(G10="No","Wrong domain (non-AECO)",IF(H10="No","Digital Twin not core / buzzword",IF(I10="No","No Design for Safety/Quality/PtD",IF(J10="No","Wrong publication type",IF(K10="No","Non-English","")))))) | N10: Yes | O10: Yes | P10: Yes | Q10: Yes | R10: Yes | S10: =IF(N10<>"Yes","",IF(COUNTBLANK(P10:R10)=3,"",IF(COUNTIF(P10:R10,"No")>0,"EXCLUDE","INCLUDE"))) -> INCLUDE | T10: =IF(S10<>"EXCLUDE","",IF(P10="No","Digital Twin mentioned only, not the subject",IF(Q10="No","No Design for Safety/Quality in full text",IF(R10="No","Methodology not codable","")))) | U10: Tier 2 - Digital Shadow (one-way physical to virtual) | V10: 0 | W10: 1 | X10: 0 | Y10: =IF(SUM(V10:X10)=0,"",IF(SUM(V10:X10)>=2,"Multi","Single")) -> Single | Z10: Design for Safety (DfS) | AA10: None | AB10: Other / Mixed | AC10: Multi (two or more data types) | AD10: Single case study | AE10: 4 | AF10: Design for Safety | AG10: Deployed LiDAR+radar+camera fusion validated with RTK-GNSS at real work zone (lane-level accuracy); Predictive DT framework (Digital Shadow + Digital Sibling, TTC/PET conflict metrics, C-V2X warnings) proposed but not implemented — hence Tier 2, AA None. [Full-text source: arXiv OA preprint] | AH10: Fills the gap between work zone safety DT research and real-world deployment: LiDAR+radar+camera fusion validated with RTK-GNSS at a real work zone achieving lane-level accuracy, feeding a predictive DT framework pairing a Digital Shadow and Digital Sibling with TTC/PET conflict metrics and C-V2X warnings for proactive safety. | AI10: Deployment lessons rather than controlled validation: one real work zone, and the predictive framework (conflict metrics, C-V2X warnings) stays at framework level without demonstrated closed-loop actuation; no explicit future work is stated. | AJ10: Fused | AK10: Deployed LiDAR+radar+camera fusion validated with RTK-GNSS at lane-level accuracy at a real work zone (joint multi-sensor deployment feeding conflict metrics). | AL10: Medium | AM10: RESOLVED 2026-08-22: Year 2026 -> 2025 and author label updated. Verified full text is arXiv:2508.01599v1 [cs.OH] 3 Aug 2025, submission date August 5, 2025; no journal version of record found in the document | AN10: Verified 2026-08-22 (deep re-read) vs PDF. Lane-level tracking, RTK GNSS (NovAtel CPT7700), Digital Shadow/Digital Sibling, TTC/PET, C-V2X confirmed; "no explicit future work" confirmed (paper ends with CONCLUSION AND RECOMMENDATIONS). YEAR CORRECTED 2026 -> 2025: header reads "arXiv:2508.01599v1 [cs.OH] 3 Aug 2025" and "Submission Date: August 5, 2025"; the document contains no evidence of a 2026 version of record. | AO10: =IF($A10="","",IFERROR(_xlfn.XLOOKUP($A10,'2_DOI_Lookup'!$A$2:$A$430,'2_DOI_Lookup'!$B$2:$B$430),"NOT IN SOURCE")) -> 10.1177/03611981261441281
A11: 3978 | B11: Akanmu (2021) | C11: 2021 | E11: =IF($A11="","",IFERROR(_xlfn.XLOOKUP($A11,'2_DOI_Lookup'!$D$2:$D$430,'2_DOI_Lookup'!$E$2:$E$430),"TITLE NOT IN SOURCE")) -> TOWARDS NEXT GENERATION CYBER-PHYSICAL SYSTEMS AND DIGITAL TWINS FOR CONSTRUCTION | F11: Web of Science | G11: Yes | H11: Yes | I11: Yes | J11: Yes | K11: Yes | L11: =IF(COUNTBLANK(G11:K11)=5,"",IF(COUNTIF(G11:K11,"No")>0,"EXCLUDE","INCLUDE")) -> INCLUDE | M11: =IF(L11<>"EXCLUDE","",IF(G11="No","Wrong domain (non-AECO)",IF(H11="No","Digital Twin not core / buzzword",IF(I11="No","No Design for Safety/Quality/PtD",IF(J11="No","Wrong publication type",IF(K11="No","Non-English","")))))) | N11: Yes | O11: Yes | P11: Yes | Q11: Yes | R11: Yes | S11: =IF(N11<>"Yes","",IF(COUNTBLANK(P11:R11)=3,"",IF(COUNTIF(P11:R11,"No")>0,"EXCLUDE","INCLUDE"))) -> INCLUDE | T11: =IF(S11<>"EXCLUDE","",IF(P11="No","Digital Twin mentioned only, not the subject",IF(Q11="No","No Design for Safety/Quality in full text",IF(R11="No","Methodology not codable","")))) | U11: Tier 3 - Digital Twin (bidirectional, two-way) | V11: 0 | W11: 1 | X11: 1 | Y11: =IF(SUM(V11:X11)=0,"",IF(SUM(V11:X11)>=2,"Multi","Single")) -> Multi | Z11: Design for Safety (DfS) | AA11: Mentioned only | AB11: Digital Twin platform (no machine learning) | AC11: Multi (two or more data types) | AD11: Conceptual (no test) | AE11: 3 | AF11: BIM-to-Digital-Twin architecture | AG11: Perspective paper defining next-gen CPS/DT with explicit two-way mapping and passive/active control; scenarios (teleoperated drywall robot, postural tracking, near-miss prevention) illustrate bidirectional control but nothing implemented; ML training of movement data only suggested. [Full-text source: Endnote] | AH11: A perspective paper defining next-generation CPS and DT through two-way dynamic mapping between virtual models and the physical facility, distinguishing passive (model-based) from active (actuator-based) control, and illustrating scenarios: a teleoperated drywall robot controlled via wearable IMU motion capture, postural tracking with AR avatars and color-coded ergonomic risk feedback, and near-miss prediction using case-based reasoning and K-nearest neighbor. | AI11: Purely conceptual: none of the scenarios is implemented or validated, and the paper itself lists open challenges of a missing information model for DTs, missing version management guidelines, missing communication latency guidelines, and missing interoperability standards analogous to IFC. | AJ11: Unclear | AK11: Perspective paper defining next-gen CPS/DT; the bidirectional-control scenarios are illustrative only and no data-integration mechanism is implemented. | AL11: High | AN11: Verified 2026-08-22 vs PDF. Perspective paper: "two-way dynamic mapping between virtual models and physical components", drywall/near-miss scenarios with case-based reasoning described as opportunities, nothing implemented. Tier 3, AD Conceptual, AA Mentioned only all upheld. | AO11: =IF($A11="","",IFERROR(_xlfn.XLOOKUP($A11,'2_DOI_Lookup'!$A$2:$A$430,'2_DOI_Lookup'!$B$2:$B$430),"NOT IN SOURCE")) -> 10.36680/j.itcon.2021.027
A12: 3527 | E12: =IF($A12="","",IFERROR(_xlfn.XLOOKUP($A12,'2_DOI_Lookup'!$D$2:$D$430,'2_DOI_Lookup'!$E$2:$E$430),"TITLE NOT IN SOURCE")) -> A methodological approach to hybrid AI systems for real-time infrastructure monitoring in civil engineering | F12: Scopus | G12: Yes | H12: No | I12: Yes | J12: Yes | K12: Yes | L12: =IF(COUNTBLANK(G12:K12)=5,"",IF(COUNTIF(G12:K12,"No")>0,"EXCLUDE","INCLUDE")) -> EXCLUDE | M12: =IF(L12<>"EXCLUDE","",IF(G12="No","Wrong domain (non-AECO)",IF(H12="No","Digital Twin not core / buzzword",IF(I12="No","No Design for Safety/Quality/PtD",IF(J12="No","Wrong publication type",IF(K12="No","Non-English","")))))) -> Digital Twin not core / buzzword | S12: =IF(N12<>"Yes","",IF(COUNTBLANK(P12:R12)=3,"",IF(COUNTIF(P12:R12,"No")>0,"EXCLUDE","INCLUDE"))) | T12: =IF(S12<>"EXCLUDE","",IF(P12="No","Digital Twin mentioned only, not the subject",IF(Q12="No","No Design for Safety/Quality in full text",IF(R12="No","Methodology not codable","")))) | Y12: =IF(SUM(V12:X12)=0,"",IF(SUM(V12:X12)>=2,"Multi","Single")) | AG12: SHM hybrid AI; no DT built/proposed | AO12: =IF($A12="","",IFERROR(_xlfn.XLOOKUP($A12,'2_DOI_Lookup'!$A$2:$A$430,'2_DOI_Lookup'!$B$2:$B$430),"NOT IN SOURCE")) -> 10.1007/s42107-025-01409-5
A13: 3963 | E13: =IF($A13="","",IFERROR(_xlfn.XLOOKUP($A13,'2_DOI_Lookup'!$D$2:$D$430,'2_DOI_Lookup'!$E$2:$E$430),"TITLE NOT IN SOURCE")) -> Neural network-based metamodel for scaffolding behavior: Application for structural load analysis and safety enhancement | F13: Web of Science | G13: Yes | H13: No | I13: Yes | J13: Yes | K13: Yes | L13: =IF(COUNTBLANK(G13:K13)=5,"",IF(COUNTIF(G13:K13,"No")>0,"EXCLUDE","INCLUDE")) -> EXCLUDE | M13: =IF(L13<>"EXCLUDE","",IF(G13="No","Wrong domain (non-AECO)",IF(H13="No","Digital Twin not core / buzzword",IF(I13="No","No Design for Safety/Quality/PtD",IF(J13="No","Wrong publication type",IF(K13="No","Non-English","")))))) -> Digital Twin not core / buzzword | S13: =IF(N13<>"Yes","",IF(COUNTBLANK(P13:R13)=3,"",IF(COUNTIF(P13:R13,"No")>0,"EXCLUDE","INCLUDE"))) | T13: =IF(S13<>"EXCLUDE","",IF(P13="No","Digital Twin mentioned only, not the subject",IF(Q13="No","No Design for Safety/Quality in full text",IF(R13="No","Methodology not codable","")))) | Y13: =IF(SUM(V13:X13)=0,"",IF(SUM(V13:X13)>=2,"Multi","Single")) | AG13: FEM+NN metamodel; authors state not a full digital twin | AO13: =IF($A13="","",IFERROR(_xlfn.XLOOKUP($A13,'2_DOI_Lookup'!$A$2:$A$430,'2_DOI_Lookup'!$B$2:$B$430),"NOT IN SOURCE")) -> 10.1016/j.apples.2025.100240
A14: 3917 | E14: =IF($A14="","",IFERROR(_xlfn.XLOOKUP($A14,'2_DOI_Lookup'!$D$2:$D$430,'2_DOI_Lookup'!$E$2:$E$430),"TITLE NOT IN SOURCE")) -> Enhancing resilience through environmental data integration in early construction planning: a cloud-based framework | F14: Web of Science | G14: Yes | H14: No | I14: No | J14: Yes | K14: Yes | L14: =IF(COUNTBLANK(G14:K14)=5,"",IF(COUNTIF(G14:K14,"No")>0,"EXCLUDE","INCLUDE")) -> EXCLUDE | M14: =IF(L14<>"EXCLUDE","",IF(G14="No","Wrong domain (non-AECO)",IF(H14="No","Digital Twin not core / buzzword",IF(I14="No","No Design for Safety/Quality/PtD",IF(J14="No","Wrong publication type",IF(K14="No","Non-English","")))))) -> Digital Twin not core / buzzword | S14: =IF(N14<>"Yes","",IF(COUNTBLANK(P14:R14)=3,"",IF(COUNTIF(P14:R14,"No")>0,"EXCLUDE","INCLUDE"))) | T14: =IF(S14<>"EXCLUDE","",IF(P14="No","Digital Twin mentioned only, not the subject",IF(Q14="No","No Design for Safety/Quality in full text",IF(R14="No","Methodology not codable","")))) | Y14: =IF(SUM(V14:X14)=0,"",IF(SUM(V14:X14)>=2,"Multi","Single")) | AG14: BIM-ICDD semantic linking; no DT; compliance not DfQ | AO14: =IF($A14="","",IFERROR(_xlfn.XLOOKUP($A14,'2_DOI_Lookup'!$A$2:$A$430,'2_DOI_Lookup'!$B$2:$B$430),"NOT IN SOURCE")) -> 10.3389/fbuil.2026.1748837
A15: 3541 | E15: =IF($A15="","",IFERROR(_xlfn.XLOOKUP($A15,'2_DOI_Lookup'!$D$2:$D$430,'2_DOI_Lookup'!$E$2:$E$430),"TITLE NOT IN SOURCE")) -> Automation levels for nuclear reactor operations: A revised perspective | F15: Scopus | G15: No | H15: No | I15: No | J15: Yes | K15: Yes | L15: =IF(COUNTBLANK(G15:K15)=5,"",IF(COUNTIF(G15:K15,"No")>0,"EXCLUDE","INCLUDE")) -> EXCLUDE | M15: =IF(L15<>"EXCLUDE","",IF(G15="No","Wrong domain (non-AECO)",IF(H15="No","Digital Twin not core / buzzword",IF(I15="No","No Design for Safety/Quality/PtD",IF(J15="No","Wrong publication type",IF(K15="No","Non-English","")))))) -> Wrong domain (non-AECO) | S15: =IF(N15<>"Yes","",IF(COUNTBLANK(P15:R15)=3,"",IF(COUNTIF(P15:R15,"No")>0,"EXCLUDE","INCLUDE"))) | T15: =IF(S15<>"EXCLUDE","",IF(P15="No","Digital Twin mentioned only, not the subject",IF(Q15="No","No Design for Safety/Quality in full text",IF(R15="No","Methodology not codable","")))) | Y15: =IF(SUM(V15:X15)=0,"",IF(SUM(V15:X15)>=2,"Multi","Single")) | AG15: Nuclear power domain | AO15: =IF($A15="","",IFERROR(_xlfn.XLOOKUP($A15,'2_DOI_Lookup'!$A$2:$A$430,'2_DOI_Lookup'!$B$2:$B$430),"NOT IN SOURCE")) -> 10.1016/j.pnucene.2022.104559
A16: 3903 | E16: =IF($A16="","",IFERROR(_xlfn.XLOOKUP($A16,'2_DOI_Lookup'!$D$2:$D$430,'2_DOI_Lookup'!$E$2:$E$430),"TITLE NOT IN SOURCE")) -> BIM-GIS integrated hydrodynamic modeling for road flood risk assessment: A case study in Algeria's Chiffa Wadi | F16: Web of Science | G16: Yes | H16: No | I16: Yes | J16: Yes | K16: Yes | L16: =IF(COUNTBLANK(G16:K16)=5,"",IF(COUNTIF(G16:K16,"No")>0,"EXCLUDE","INCLUDE")) -> EXCLUDE | M16: =IF(L16<>"EXCLUDE","",IF(G16="No","Wrong domain (non-AECO)",IF(H16="No","Digital Twin not core / buzzword",IF(I16="No","No Design for Safety/Quality/PtD",IF(J16="No","Wrong publication type",IF(K16="No","Non-English","")))))) -> Digital Twin not core / buzzword | S16: =IF(N16<>"Yes","",IF(COUNTBLANK(P16:R16)=3,"",IF(COUNTIF(P16:R16,"No")>0,"EXCLUDE","INCLUDE"))) | T16: =IF(S16<>"EXCLUDE","",IF(P16="No","Digital Twin mentioned only, not the subject",IF(Q16="No","No Design for Safety/Quality in full text",IF(R16="No","Methodology not codable","")))) | Y16: =IF(SUM(V16:X16)=0,"",IF(SUM(V16:X16)>=2,"Multi","Single")) | AG16: BIM-HDM framework; DT only future early warning | AO16: =IF($A16="","",IFERROR(_xlfn.XLOOKUP($A16,'2_DOI_Lookup'!$A$2:$A$430,'2_DOI_Lookup'!$B$2:$B$430),"NOT IN SOURCE")) -> 10.1016/j.ress.2025.111906
A17: 3915 | B17: Almatared (2024) | C17: 2024 | E17: =IF($A17="","",IFERROR(_xlfn.XLOOKUP($A17,'2_DOI_Lookup'!$D$2:$D$430,'2_DOI_Lookup'!$E$2:$E$430),"TITLE NOT IN SOURCE")) -> Digital-Twin-Based Fire Safety Management Framework for Smart Buildings | F17: Web of Science | G17: Yes | H17: Yes | I17: Yes | J17: Yes | K17: Yes | L17: =IF(COUNTBLANK(G17:K17)=5,"",IF(COUNTIF(G17:K17,"No")>0,"EXCLUDE","INCLUDE")) -> INCLUDE | M17: =IF(L17<>"EXCLUDE","",IF(G17="No","Wrong domain (non-AECO)",IF(H17="No","Digital Twin not core / buzzword",IF(I17="No","No Design for Safety/Quality/PtD",IF(J17="No","Wrong publication type",IF(K17="No","Non-English","")))))) | N17: Yes | O17: Yes | P17: Yes | Q17: Yes | R17: Yes | S17: =IF(N17<>"Yes","",IF(COUNTBLANK(P17:R17)=3,"",IF(COUNTIF(P17:R17,"No")>0,"EXCLUDE","INCLUDE"))) -> INCLUDE | T17: =IF(S17<>"EXCLUDE","",IF(P17="No","Digital Twin mentioned only, not the subject",IF(Q17="No","No Design for Safety/Quality in full text",IF(R17="No","Methodology not codable","")))) | U17: Tier 3 - Digital Twin (bidirectional, two-way) | V17: 0 | W17: 0 | X17: 1 | Y17: =IF(SUM(V17:X17)=0,"",IF(SUM(V17:X17)>=2,"Multi","Single")) -> Single | Z17: Design for Safety (DfS) | AA17: Mentioned only | AB17: Digital Twin platform (no machine learning) | AC17: Multi (two or more data types) | AD17: Conceptual (no test) | AE17: 3 | AF17: Design for Safety | AG17: Four-layer DT-based fire-safety framework (physical/virtual/application/user-interaction) with explicit feedback "integrated back with the physical building layer for automatic control"; validated only via FM-professional questionnaire, no technical test; AI learning cited from literature, not implemented. [Full-text source: Endnote] | AH17: Addresses the underexplored application of DT to fire safety management: a four-layer framework (physical building, virtual building, application, and user interaction layers) combining BIM, IoT, AI, data fusion, blockchain, and AR, with virtual-layer decisions fed back to the physical building layer for automatic control and operation optimization while keeping FM professionals in the loop. | AI17: Conceptual only: the framework was validated through a thematic analysis of 37 studies and a survey of FM professionals (66 responses, 28 complete) rather than a live implementation; no prototype or sensor deployment is reported. Future work includes a Delphi study with a broader panel and involving firefighters as end users. | AJ17: Unclear | AK17: Four-layer fire-safety framework validated only through a thematic analysis and an FM-professional questionnaire; the layer integration mechanism is not implemented. | AL17: High | AN17: Verified 2026-08-22 vs PDF (Buildings 2024). Tier 3 supported verbatim: decisions "integrated back with the physical building layer for automatic control and operation optimization". Validation is a questionnaire of FM professionals only, so AD Conceptual and AA Mentioned only upheld. | AO17: =IF($A17="","",IFERROR(_xlfn.XLOOKUP($A17,'2_DOI_Lookup'!$A$2:$A$430,'2_DOI_Lookup'!$B$2:$B$430),"NOT IN SOURCE")) -> 10.3390/buildings14010004
A18: 3668 | B18: Alvaro (2025) | C18: 2025 | E18: =IF($A18="","",IFERROR(_xlfn.XLOOKUP($A18,'2_DOI_Lookup'!$D$2:$D$430,'2_DOI_Lookup'!$E$2:$E$430),"TITLE NOT IN SOURCE")) -> GUIDE2FR: A smart monitoring platform with a digital twin of a firefighter training tower for emergency scenarios | F18: Scopus | G18: Yes | H18: Yes | I18: Yes | J18: Yes | K18: Yes | L18: =IF(COUNTBLANK(G18:K18)=5,"",IF(COUNTIF(G18:K18,"No")>0,"EXCLUDE","INCLUDE")) -> INCLUDE | M18: =IF(L18<>"EXCLUDE","",IF(G18="No","Wrong domain (non-AECO)",IF(H18="No","Digital Twin not core / buzzword",IF(I18="No","No Design for Safety/Quality/PtD",IF(J18="No","Wrong publication type",IF(K18="No","Non-English","")))))) | N18: Yes | O18: Yes | P18: Yes | Q18: Yes | R18: Yes | S18: =IF(N18<>"Yes","",IF(COUNTBLANK(P18:R18)=3,"",IF(COUNTIF(P18:R18,"No")>0,"EXCLUDE","INCLUDE"))) -> INCLUDE | T18: =IF(S18<>"EXCLUDE","",IF(P18="No","Digital Twin mentioned only, not the subject",IF(Q18="No","No Design for Safety/Quality in full text",IF(R18="No","Methodology not codable","")))) | U18: Tier 2 - Digital Shadow (one-way physical to virtual) | V18: 0 | W18: 0 | X18: 1 | Y18: =IF(SUM(V18:X18)=0,"",IF(SUM(V18:X18)>=2,"Multi","Single")) -> Single | Z18: Design for Safety (DfS) | AA18: None | AB18: Other / Mixed | AC18: Multi (two or more data types) | AD18: Single case study | AE18: 4 | AF18: Design for Safety | AG18: GUIDE2FR emergency-monitoring DT of a firefighter training tower (Alcorcón): Wi-Fi/LoRa beacon network (temp, humidity, CO2, TVOC) + RTSP video synchronised in a Grafana plugin; offline-trained ML forecasting pipeline (SVR/RF/Huber/GPR, forward-chaining CV, tested on 4 beacons at Fire Station 9) visualised in the DT; one-way data flow to human decision-makers, no actuation and no online learning loop. [Full-text source: Endnote] | AH18: Fills the gap between fire-safety DT research and operational emergency response: a functioning building DT (GUIDE2FR) fusing Wi-Fi/LoRa environmental beacons with live RTSP video in a Grafana plugin, plus an offline-trained ML forecasting pipeline (SVR, Huber, Random Forest, Gaussian Process, forward-chaining CV, adaptive ensemble) tested on data from four beacons during firefighter training exercises at Fire Station 9 in Madrid. | AI18: No actuation or bidirectional link to building systems: forecasting models are offline-trained and never updated online. The platform relies on proprietary ArcGIS, assumes a reliable wireless network, and sensor accuracy under extreme conditions is unverified; future work targets open-source visualization and integration with more real assets for active response and evacuation mechanisms. | AJ18: Aligned | AK18: Each video segment is timestamped and the custom Grafana plugin cross-references RTSP video streams with time-series sensor data stored in MySQL, giving video and beacon data a shared temporal frame (inference still runs on sensor series only). | AL18: High | AN18: Verified 2026-08-22 vs PDF (Internet of Things, Elsevier). GUIDE2FR platform, firefighter training tower at CUS Alcorcon (Madrid), Grafana plugin synchronising RTSP video with sensor data, ArcGIS geolocation all confirmed. Tier 2, AA None upheld. | AO18: =IF($A18="","",IFERROR(_xlfn.XLOOKUP($A18,'2_DOI_Lookup'!$A$2:$A$430,'2_DOI_Lookup'!$B$2:$B$430),"NOT IN SOURCE")) -> 10.1016/j.iot.2025.101768
A19: 4053 | B19: Ammar (2024) | C19: 2024 | E19: =IF($A19="","",IFERROR(_xlfn.XLOOKUP($A19,'2_DOI_Lookup'!$D$2:$D$430,'2_DOI_Lookup'!$E$2:$E$430),"TITLE NOT IN SOURCE")) -> Practical Application of Digital Twins for Transportation Asset Data Management: Case Example of a Safety Hardware Asset | F19: Web of Science | G19: Yes | H19: Yes | I19: Yes | J19: Yes | K19: Yes | L19: =IF(COUNTBLANK(G19:K19)=5,"",IF(COUNTIF(G19:K19,"No")>0,"EXCLUDE","INCLUDE")) -> INCLUDE | M19: =IF(L19<>"EXCLUDE","",IF(G19="No","Wrong domain (non-AECO)",IF(H19="No","Digital Twin not core / buzzword",IF(I19="No","No Design for Safety/Quality/PtD",IF(J19="No","Wrong publication type",IF(K19="No","Non-English","")))))) | N19: Yes | O19: Yes | P19: No | Q19: Yes | R19: Yes | S19: =IF(N19<>"Yes","",IF(COUNTBLANK(P19:R19)=3,"",IF(COUNTIF(P19:R19,"No")>0,"EXCLUDE","INCLUDE"))) -> EXCLUDE | T19: =IF(S19<>"EXCLUDE","",IF(P19="No","Digital Twin mentioned only, not the subject",IF(Q19="No","No Design for Safety/Quality in full text",IF(R19="No","Methodology not codable","")))) -> Digital Twin mentioned only, not the subject | U19: Unclear | Y19: =IF(SUM(V19:X19)=0,"",IF(SUM(V19:X19)>=2,"Multi","Single")) | AG19: Survey + case study on guiderail data management for a transportation agency: investigates current practices and proposes a data architecture for information-rich analytical models using DTs, but no DT is actually built or evaluated - P=No -> Stage-2 exclude. [Full-text source: Endnote] | AN19: Verified 2026-08-22 vs PDF (Transportation Research Record 2678(10):114-130). Survey plus CTDOT subject-matter-expert interviews on guiderail asset data management and a proposed guiderail data architecture; DTs are discussed as potential rather than built or evaluated. Stage-2 EXCLUDE (P=No) upheld. | AO19: =IF($A19="","",IFERROR(_xlfn.XLOOKUP($A19,'2_DOI_Lookup'!$A$2:$A$430,'2_DOI_Lookup'!$B$2:$B$430),"NOT IN SOURCE")) -> 10.1177/03611981241231804
A20: 3579 | E20: =IF($A20="","",IFERROR(_xlfn.XLOOKUP($A20,'2_DOI_Lookup'!$D$2:$D$430,'2_DOI_Lookup'!$E$2:$E$430),"TITLE NOT IN SOURCE")) -> State regulation of the IoT in the Russian Federation: Fundamentals and challenges | F20: Scopus | G20: No | H20: No | I20: No | J20: Yes | K20: Yes | L20: =IF(COUNTBLANK(G20:K20)=5,"",IF(COUNTIF(G20:K20,"No")>0,"EXCLUDE","INCLUDE")) -> EXCLUDE | M20: =IF(L20<>"EXCLUDE","",IF(G20="No","Wrong domain (non-AECO)",IF(H20="No","Digital Twin not core / buzzword",IF(I20="No","No Design for Safety/Quality/PtD",IF(J20="No","Wrong publication type",IF(K20="No","Non-English","")))))) -> Wrong domain (non-AECO) | S20: =IF(N20<>"Yes","",IF(COUNTBLANK(P20:R20)=3,"",IF(COUNTIF(P20:R20,"No")>0,"EXCLUDE","INCLUDE"))) | T20: =IF(S20<>"EXCLUDE","",IF(P20="No","Digital Twin mentioned only, not the subject",IF(Q20="No","No Design for Safety/Quality in full text",IF(R20="No","Methodology not codable","")))) | Y20: =IF(SUM(V20:X20)=0,"",IF(SUM(V20:X20)>=2,"Multi","Single")) | AG20: Legal/regulatory IoT paper; not AECO | AO20: =IF($A20="","",IFERROR(_xlfn.XLOOKUP($A20,'2_DOI_Lookup'!$A$2:$A$430,'2_DOI_Lookup'!$B$2:$B$430),"NOT IN SOURCE")) -> 10.11591/ijece.v11i5.pp4542-4549
A21: 3838 | E21: =IF($A21="","",IFERROR(_xlfn.XLOOKUP($A21,'2_DOI_Lookup'!$D$2:$D$430,'2_DOI_Lookup'!$E$2:$E$430),"TITLE NOT IN SOURCE")) -> The Role of Artificial Intelligence in Shaping Intelligent Motorways: Opportunities, Challenges, and Real-World Implementations | F21: Scopus | G21: Yes | H21: No | I21: No | J21: Yes | K21: Yes | L21: =IF(COUNTBLANK(G21:K21)=5,"",IF(COUNTIF(G21:K21,"No")>0,"EXCLUDE","INCLUDE")) -> EXCLUDE | M21: =IF(L21<>"EXCLUDE","",IF(G21="No","Wrong domain (non-AECO)",IF(H21="No","Digital Twin not core / buzzword",IF(I21="No","No Design for Safety/Quality/PtD",IF(J21="No","Wrong publication type",IF(K21="No","Non-English","")))))) -> Digital Twin not core / buzzword | S21: =IF(N21<>"Yes","",IF(COUNTBLANK(P21:R21)=3,"",IF(COUNTIF(P21:R21,"No")>0,"EXCLUDE","INCLUDE"))) | T21: =IF(S21<>"EXCLUDE","",IF(P21="No","Digital Twin mentioned only, not the subject",IF(Q21="No","No Design for Safety/Quality in full text",IF(R21="No","Methodology not codable","")))) | Y21: =IF(SUM(V21:X21)=0,"",IF(SUM(V21:X21)>=2,"Multi","Single")) | AG21: AI-in-motorways review; DT one of many topics | AO21: =IF($A21="","",IFERROR(_xlfn.XLOOKUP($A21,'2_DOI_Lookup'!$A$2:$A$430,'2_DOI_Lookup'!$B$2:$B$430),"NOT IN SOURCE")) -> 10.1109/TITS.2025.3609972
A22: 4020 | E22: =IF($A22="","",IFERROR(_xlfn.XLOOKUP($A22,'2_DOI_Lookup'!$D$2:$D$430,'2_DOI_Lookup'!$E$2:$E$430),"TITLE NOT IN SOURCE")) -> FingerCI: Writing industrial process specifications from network traffic | F22: Web of Science | G22: No | H22: Yes | I22: No | J22: Yes | K22: Yes | L22: =IF(COUNTBLANK(G22:K22)=5,"",IF(COUNTIF(G22:K22,"No")>0,"EXCLUDE","INCLUDE")) -> EXCLUDE | M22: =IF(L22<>"EXCLUDE","",IF(G22="No","Wrong domain (non-AECO)",IF(H22="No","Digital Twin not core / buzzword",IF(I22="No","No Design for Safety/Quality/PtD",IF(J22="No","Wrong publication type",IF(K22="No","Non-English","")))))) -> Wrong domain (non-AECO) | S22: =IF(N22<>"Yes","",IF(COUNTBLANK(P22:R22)=3,"",IF(COUNTIF(P22:R22,"No")>0,"EXCLUDE","INCLUDE"))) | T22: =IF(S22<>"EXCLUDE","",IF(P22="No","Digital Twin mentioned only, not the subject",IF(Q22="No","No Design for Safety/Quality in full text",IF(R22="No","Methodology not codable","")))) | Y22: =IF(SUM(V22:X22)=0,"",IF(SUM(V22:X22)>=2,"Multi","Single")) | AG22: Cybersecurity; airport baggage system industrial testbed | AO22: =IF($A22="","",IFERROR(_xlfn.XLOOKUP($A22,'2_DOI_Lookup'!$A$2:$A$430,'2_DOI_Lookup'!$B$2:$B$430),"NOT IN SOURCE")) -> 10.1016/j.ijcip.2024.100725
A23: 3842 | B23: Aragon (2025) | C23: 2025 | E23: =IF($A23="","",IFERROR(_xlfn.XLOOKUP($A23,'2_DOI_Lookup'!$D$2:$D$430,'2_DOI_Lookup'!$E$2:$E$430),"TITLE NOT IN SOURCE")) -> Seeking a Definition of Digital Twins for Construction and Infrastructure Management | F23: Scopus | G23: Yes | H23: Yes | I23: Yes | J23: Yes | K23: Yes | L23: =IF(COUNTBLANK(G23:K23)=5,"",IF(COUNTIF(G23:K23,"No")>0,"EXCLUDE","INCLUDE")) -> INCLUDE | M23: =IF(L23<>"EXCLUDE","",IF(G23="No","Wrong domain (non-AECO)",IF(H23="No","Digital Twin not core / buzzword",IF(I23="No","No Design for Safety/Quality/PtD",IF(J23="No","Wrong publication type",IF(K23="No","Non-English","")))))) | N23: Yes | O23: Yes | P23: Yes | Q23: Yes | R23: Yes | S23: =IF(N23<>"Yes","",IF(COUNTBLANK(P23:R23)=3,"",IF(COUNTIF(P23:R23,"No")>0,"EXCLUDE","INCLUDE"))) -> INCLUDE | T23: =IF(S23<>"EXCLUDE","",IF(P23="No","Digital Twin mentioned only, not the subject",IF(Q23="No","No Design for Safety/Quality in full text",IF(R23="No","Methodology not codable","")))) | U23: Tier 1 - Digital Model (static, no live data) | V23: 0 | W23: 0 | X23: 1 | Y23: =IF(SUM(V23:X23)=0,"",IF(SUM(V23:X23)>=2,"Multi","Single")) -> Single | Z23: Design for Safety (DfS) | AA23: None | AB23: Digital Twin platform (no machine learning) | AC23: Multi (two or more data types) | AD23: Cross-project (multiple real projects) | AE23: 3 | AF23: Lifecycle / governance | AG23: Definition/standardisation position paper (CEN/TC 442/WG 9, ISO); two illustrative DT cases (Bidebieta-Basauri railway station, UPM civil engineering school) are management/visualisation platforms with real-time info integration but no analytics loop or learning; safety only a secondary use case. [Full-text source: Endnote] | AH23: A standardization position paper reviewing DT definitions and frameworks and reporting the creation of CEN/TC 442/WG 9, whose 34-use-case technical report CEN/TR 18077 and the resulting European standard aim to give the built environment a shared DT definition; it grounds its argument in two implemented management platforms, the Bidebieta-Basauri railway station and the UPM civil engineering school. | AI23: The two DT cases are management and visualization platforms lacking AI or simulation protocols, which the authors state are still under research, and the paper proposes definitions rather than new empirical validation; the European standard was still pending publication and no quantitative evaluation is offered. | AJ23: Unclear | AK23: Standardisation position paper (CEN/TC 442/WG 9); the two illustrative DT cases are management/visualisation platforms and no data-integration mechanism is specified. | AL23: High | AN23: Verified 2026-08-22 vs PDF (UPM / UNE / CEN). CEN/TC 442/WG 9 and CEN/TR 18077 confirmed; two implemented DT management platforms described - Bidebieta-Basauri railway station (Bilbao-Orduna network, Basque Country) and the UPM civil engineering school. AD Cross-project supported by two distinct real projects. Tier 1, AA None upheld. | AO23: =IF($A23="","",IFERROR(_xlfn.XLOOKUP($A23,'2_DOI_Lookup'!$A$2:$A$430,'2_DOI_Lookup'!$B$2:$B$430),"NOT IN SOURCE")) -> 10.3390/app15031557
A24: 4028 | B24: Araujo (2025) | C24: 2025 | E24: =IF($A24="","",IFERROR(_xlfn.XLOOKUP($A24,'2_DOI_Lookup'!$D$2:$D$430,'2_DOI_Lookup'!$E$2:$E$430),"TITLE NOT IN SOURCE")) -> Proposal of a conceptual model of digital twins for construction sites | F24: Web of Science | G24: Yes | H24: Yes | I24: Yes | J24: Yes | K24: Yes | L24: =IF(COUNTBLANK(G24:K24)=5,"",IF(COUNTIF(G24:K24,"No")>0,"EXCLUDE","INCLUDE")) -> INCLUDE | M24: =IF(L24<>"EXCLUDE","",IF(G24="No","Wrong domain (non-AECO)",IF(H24="No","Digital Twin not core / buzzword",IF(I24="No","No Design for Safety/Quality/PtD",IF(J24="No","Wrong publication type",IF(K24="No","Non-English","")))))) | N24: Yes | O24: Yes | P24: Yes | Q24: Yes | R24: Yes | S24: =IF(N24<>"Yes","",IF(COUNTBLANK(P24:R24)=3,"",IF(COUNTIF(P24:R24,"No")>0,"EXCLUDE","INCLUDE"))) -> INCLUDE | T24: =IF(S24<>"EXCLUDE","",IF(P24="No","Digital Twin mentioned only, not the subject",IF(Q24="No","No Design for Safety/Quality in full text",IF(R24="No","Methodology not codable","")))) | U24: Tier 2 - Digital Shadow (one-way physical to virtual) | V24: 0 | W24: 1 | X24: 0 | Y24: =IF(SUM(V24:X24)=0,"",IF(SUM(V24:X24)>=2,"Multi","Single")) -> Single | Z24: Design for Quality (DfQ) | AA24: None | AB24: Digital Twin platform (no machine learning) | AC24: Multi (two or more data types) | AD24: Conceptual (no test) | AE24: 3 | AF24: BIM-to-Digital-Twin architecture | AG24: DSR conceptual model (F1 data acquisition / F2 data analysis-simulation / F3 BIM transformation boxes) for DT on construction sites, generalised from the empirical Smart Twins 4.0 system (RFID+IoT+BIM tracking of metallic formwork in concrete wall construction; 151 panels inspected, 100% external defects, wear 42% — rework/quality control). Closed-loop is human-in-the-loop only; F2 simulation box proposed but NOT implemented (future Smart Twins 5.0); no ML and no self-improvement. [Full-text source: Endnote] | AH24: Proposes a closed-loop conceptual model of DTs for construction sites, structured as three functional boxes: F1 data acquisition (IoT/RFID), F2 data analysis and simulation, and F3 BIM transformation into a web-based model; it is grounded in the empirical Smart Twins 4.0 system, which tracked 151 formwork panels with RFID and a web-based BIM, finding 100% external and 98% internal defects. | AI24: Smart Twins 4.0 is limited to a single physical resource (formwork), has restricted data analysis capabilities and interoperability, and still requires manual steps in data collection; the model simplifies real-world complexity, omits human roles beyond decision-making, and the authors state it needs future testing in different contexts. | AJ24: Aligned | AK24: Smart Twins 4.0 links physical formworks to their virtual BIM counterparts through automatic database integration (RFID UHF tags read on Android, Firebase, Web-based Revit/Dynamo BIM), i.e. a shared object identity between tag data and BIM elements. | AL24: Medium | AN24: Verified 2026-08-22 vs PDF. Design Science Research methodology confirmed; Smart Twins 4.0 empirical study confirmed verbatim: "Through an inspection of 151 panels using Smart Twins, 100% exhibited external defects, and 98% exhibited internal defects", most common defect external wear (42%). Tier 2, AD Conceptual, AA None upheld. | AO24: =IF($A24="","",IFERROR(_xlfn.XLOOKUP($A24,'2_DOI_Lookup'!$A$2:$A$430,'2_DOI_Lookup'!$B$2:$B$430),"NOT IN SOURCE")) -> 10.7764/RIC.00168.21
A25: 3828 | B25: Arhrib (2026) | C25: 2026 | E25: =IF($A25="","",IFERROR(_xlfn.XLOOKUP($A25,'2_DOI_Lookup'!$D$2:$D$430,'2_DOI_Lookup'!$E$2:$E$430),"TITLE NOT IN SOURCE")) -> Serverless 3D Reconstruction and Spatial Anchoring for Cloud-Native Infrastructure Inspection | F25: Scopus | G25: Yes | H25: Yes | I25: Yes | J25: Yes | K25: Yes | L25: =IF(COUNTBLANK(G25:K25)=5,"",IF(COUNTIF(G25:K25,"No")>0,"EXCLUDE","INCLUDE")) -> INCLUDE | M25: =IF(L25<>"EXCLUDE","",IF(G25="No","Wrong domain (non-AECO)",IF(H25="No","Digital Twin not core / buzzword",IF(I25="No","No Design for Safety/Quality/PtD",IF(J25="No","Wrong publication type",IF(K25="No","Non-English","")))))) | N25: Yes | O25: Yes | P25: Yes | Q25: Yes | R25: Yes | S25: =IF(N25<>"Yes","",IF(COUNTBLANK(P25:R25)=3,"",IF(COUNTIF(P25:R25,"No")>0,"EXCLUDE","INCLUDE"))) -> INCLUDE | T25: =IF(S25<>"EXCLUDE","",IF(P25="No","Digital Twin mentioned only, not the subject",IF(Q25="No","No Design for Safety/Quality in full text",IF(R25="No","Methodology not codable","")))) | U25: Tier 1 - Digital Model (static, no live data) | V25: 0 | W25: 0 | X25: 1 | Y25: =IF(SUM(V25:X25)=0,"",IF(SUM(V25:X25)>=2,"Multi","Single")) -> Single | Z25: Design for Quality (DfQ) | AA25: None | AB25: Digital Twin platform (no machine learning) | AC25: Multi (two or more data types) | AD25: Cross-project (multiple real projects) | AE25: 4 | AF25: Perception / Computer Vision | AG25: Serverless SfM/MVS pipeline + PostGIS defect anchors on real inspection datasets; defects as georeferenced 3D anchors support DfQ traceability; authors explicitly position against passive Level-1 twins, but no live link/learning: periodic re-scan workflow. [Full-text source: Endnote] | AH25: Addresses fragmented inspection data by replacing desktop photogrammetry with a serverless spatial intelligence hub: timeout-resilient orchestration of SfM/MVS, PostGIS-anchored defect records linked to georeferenced 3D meshes via raycasting and frustum-based image retrieval, end-to-end reconstruction in under one hour, sub-25 ms query latency, and over 90% image retrieval accuracy on two real UAV inspection datasets. | AI25: No automated defect detection: annotations are manually created by human inspectors, which the authors call the main bottleneck for scaling; validation covers only two UAV datasets, hyperparameters are not systematically optimized, and the system assumes reliable connectivity. Future work includes automated detection, temporal change monitoring, 3D Gaussian Splatting visualization, and offline capabilities. | AJ25: Aligned | AK25: Defect records are anchored to georeferenced 3D meshes in PostGIS via raycasting and frustum-based image retrieval, putting imagery-derived geometry and defect annotations in one spatial reference frame. | AL25: High | AM25: RESOLVED 2026-08-22: AD Single case study -> Cross-project. Dataset A = The Mill building, London (167 UAV images); Dataset B = building roof at EPFL, Lausanne (85 images) - two distinct real assets in different countries | AN25: Verified 2026-08-22 (deep re-read) vs PDF (Buildings 2026, 16, 2433). Serverless orchestration, PostGIS anchors, sub-25 ms query latency and >90% image retrieval confirmed; explicit contrast with passive "Level 1" twins supports Tier 1. VALIDATION SCOPE RESOLVED: "experiments using two distinct datasets" - Dataset A is The Mill building in London (167 UAV images, nadir + single oblique pass) and Dataset B is a building roof structure at EPFL, Lausanne (85 images, circular oblique, Phantom FC330 at 30 m AGL). Two separate real assets => AD corrected to Cross-project. | AO25: =IF($A25="","",IFERROR(_xlfn.XLOOKUP($A25,'2_DOI_Lookup'!$A$2:$A$430,'2_DOI_Lookup'!$B$2:$B$430),"NOT IN SOURCE")) -> 10.3390/buildings16122433
A26: 3662 | B26: Armijo (2024) | C26: 2024 | E26: =IF($A26="","",IFERROR(_xlfn.XLOOKUP($A26,'2_DOI_Lookup'!$D$2:$D$430,'2_DOI_Lookup'!$E$2:$E$430),"TITLE NOT IN SOURCE")) -> Integration of Railway Bridge Structural Health Monitoring into the Internet of Things with a Digital Twin: A Case Study | F26: Scopus | G26: Yes | H26: Yes | I26: Yes | J26: Yes | K26: Yes | L26: =IF(COUNTBLANK(G26:K26)=5,"",IF(COUNTIF(G26:K26,"No")>0,"EXCLUDE","INCLUDE")) -> INCLUDE | M26: =IF(L26<>"EXCLUDE","",IF(G26="No","Wrong domain (non-AECO)",IF(H26="No","Digital Twin not core / buzzword",IF(I26="No","No Design for Safety/Quality/PtD",IF(J26="No","Wrong publication type",IF(K26="No","Non-English","")))))) | N26: Yes | O26: Yes | P26: Yes | Q26: Yes | R26: Yes | S26: =IF(N26<>"Yes","",IF(COUNTBLANK(P26:R26)=3,"",IF(COUNTIF(P26:R26,"No")>0,"EXCLUDE","INCLUDE"))) -> INCLUDE | T26: =IF(S26<>"EXCLUDE","",IF(P26="No","Digital Twin mentioned only, not the subject",IF(Q26="No","No Design for Safety/Quality in full text",IF(R26="No","Methodology not codable","")))) | U26: Tier 2 - Digital Shadow (one-way physical to virtual) | V26: 0 | W26: 0 | X26: 1 | Y26: =IF(SUM(V26:X26)=0,"",IF(SUM(V26:X26)>=2,"Multi","Single")) -> Single | Z26: Design for Safety (DfS) | AA26: Mentioned only | AB26: Other / Mixed | AC26: Single (one data type) | AD26: Single case study | AE26: 4 | AF26: Predictive analytics / decision support | AG26: 2-year in-service railway bridge pilot; unsupervised clustering of normal vibration + FEM-calibrated synthetic damage + LightGBM classifier (ROC-AUC 0.9999). SELF-IMPROVEMENT DOWNGRADED 2026-08-23 (slow full-text re-read, not keyword match): the "continuous learning through periodic retraining" wording sits in the GENERIC methodology (Step 7 of 7, Sec. 4.1.7), and the authors state "While not all seven steps were fully implemented for the pilot bridge in this work". The pilot sections (4.2) and Results (5) report ONE AutoML/MLflow training run on 8646 rows (60/20/20 split, best iteration 281, early stop 286) and no retraining event, no re-trained model, no accuracy-over-time series. The only adaptation actually reported - coping with seasonal vibration shifts - was an outlier filter whose "correction of this issue was carried out manually by accessing the sensors’ remote interfaces". Retraining is an architectural capability (Databricks/MLflow MLOps) that is described, not executed. AA = Mentioned only. [Full-text source: Endnote] | AH26: Demonstrates an operational digital twin for railway bridge SHM: low-cost wireless accelerometers (about EUR 300), hybrid edge-cloud processing with real-time FFT, unsupervised clustering of normal vibration, FEM-calibrated synthetic damage data, and a LightGBM classifier reaching ROC-AUC 0.9999 on two years of in-service vibration data from a bridge in the Basque Country. | AI26: Detection is anomaly-based rather than damage localization or quantification, which the authors list as future work; validation is limited to one short-span bridge pilot, and analytics still rely on middleware plus cloud, with plans to move FFT and inference onto energy-harvesting edge sensors and to extend to wind towers and broader production deployments. The advertised continuous-learning loop is never exercised: the paper concedes not all seven methodology steps were implemented for the pilot, reports a single model training, and handled the one observed distribution shift (seasonality) by a manual sensor-offset correction. | AJ26: Single | AK26: Only ambient-vibration time series from wireless accelerometers feed the analytics; FEM-calibrated synthetic damage is model-generated training data, not a second measured data type. | AL26: High | AM26: RESOLVED 2026-08-23: AA Implemented -> Mentioned only. Re-read of full text shows the periodic-retraining loop belongs to the generic 7-step reference methodology, which the authors say was not fully implemented for the pilot; no retraining is executed or measured anywhere in Sec. 4.2 or Sec. 5. | AN26: Verified 2026-08-22 vs PDF (Sensors 2024, 24, 2115). ROC-AUC 0.9999 and 2-year in-service pilot confirmed. RE-VERIFIED 2026-08-23 (self-improvement audit, full text, not keyword search): AA=Implemented OVERTURNED. The retraining language is confined to Sec. 4.1.7 of the GENERIC methodology; Sec. 4.1 states verbatim "While not all seven steps were fully implemented for the pilot bridge in this work" and "Validation and continuous learning" is step 7. The pilot (Sec. 4.2) and Results (Sec. 5) document a single Databricks AutoML/MLflow experiment (8646 rows, 60/20/20) with no repeat training, no updated model version and no performance-over-time evidence; the sole reported adaptation to seasonal drift was a manual sensor-offset correction. AA corrected to Mentioned only. | AO26: =IF($A26="","",IFERROR(_xlfn.XLOOKUP($A26,'2_DOI_Lookup'!$A$2:$A$430,'2_DOI_Lookup'!$B$2:$B$430),"NOT IN SOURCE")) -> 10.3390/s24072115
A27: 3975 | B27: Aroquipa (2025) | C27: 2025 | E27: =IF($A27="","",IFERROR(_xlfn.XLOOKUP($A27,'2_DOI_Lookup'!$D$2:$D$430,'2_DOI_Lookup'!$E$2:$E$430),"TITLE NOT IN SOURCE")) -> Methodological framework for integrating structural health monitoring and digital-twin models for seismic assessment of heritage buildings: Case study of Basilica Maria Auxiliadora, Lima, Peru | F27: Web of Science | G27: Yes | H27: Yes | I27: Yes | J27: Yes | K27: Yes | L27: =IF(COUNTBLANK(G27:K27)=5,"",IF(COUNTIF(G27:K27,"No")>0,"EXCLUDE","INCLUDE")) -> INCLUDE | M27: =IF(L27<>"EXCLUDE","",IF(G27="No","Wrong domain (non-AECO)",IF(H27="No","Digital Twin not core / buzzword",IF(I27="No","No Design for Safety/Quality/PtD",IF(J27="No","Wrong publication type",IF(K27="No","Non-English","")))))) | N27: Yes | O27: Yes | P27: Yes | Q27: Yes | R27: Yes | S27: =IF(N27<>"Yes","",IF(COUNTBLANK(P27:R27)=3,"",IF(COUNTIF(P27:R27,"No")>0,"EXCLUDE","INCLUDE"))) -> INCLUDE | T27: =IF(S27<>"EXCLUDE","",IF(P27="No","Digital Twin mentioned only, not the subject",IF(Q27="No","No Design for Safety/Quality in full text",IF(R27="No","Methodology not codable","")))) | U27: Tier 1 - Digital Model (static, no live data) | V27: 0 | W27: 0 | X27: 1 | Y27: =IF(SUM(V27:X27)=0,"",IF(SUM(V27:X27)>=2,"Multi","Single")) -> Single | Z27: Design for Safety (DfS) | AA27: None | AB27: Finite Element Method / physics-based | AC27: Multi (two or more data types) | AD27: Conceptual (no test) | AE27: 4 | AF27: BIM-to-Digital-Twin architecture | AG27: Methodological framework for integrating SHM with numerical DT models for seismic assessment of heritage buildings (Basilica Maria Auxiliadora, Lima): numerical models in 3DEC and SAP2000 (modal + time-history of 34 seismic ground-motion records) identify susceptible zones and recommended sensor locations; sensor deployment and validation against experimental models are explicitly future work - no DT implemented, no live data link, no learning loop. [Full-text source: Endnote] | AH27: Provides a methodology for integrating SHM with numerical DT models for seismic assessment of heritage buildings: a LiDAR-derived BIM of the Basilica Maria Auxiliadora in Lima fed calibrated SAP2000 and 3DEC models (about 4500 block elements, 161000 contact zones), modal analysis with 220 modes, time-history analysis reproducing the 2007 Pisco earthquake crack patterns, and 25 sensor control points selected via intensity-duration-frequency plots. | AI27: No sensors are yet deployed: the study covers only Building Virtualization and part of sensor data analysis, so the EWS and DT feedback loop remain pending; validation relies on historical damage reports and analytical consistency, with future research to include experimental models, tri-axial sensor installation, and ambient-vibration calibration of the numerical model. | AJ27: Aligned | AK27: The LiDAR point-cloud survey is converted into a BIM that is linked to the 3DEC/SAP2000 FEM models through an explicit BIM-FEM linking process, sharing one building geometry frame while each model analyses separately. | AL27: Medium | AN27: Verified 2026-08-22 vs PDF (Structures). 3DEC and SAP2000 models, "modal and time-history analyses for a set of 34 seismic ground motion records", and Basilica Maria Auxiliadora (Lima, Peru) all confirmed. Sensor integration and AVT-based calibration explicitly deferred: "AVT-based calibration will be considered in future work during the sensor integration phase" - Tier 1, AD Conceptual, AA None upheld. | AO27: =IF($A27="","",IFERROR(_xlfn.XLOOKUP($A27,'2_DOI_Lookup'!$A$2:$A$430,'2_DOI_Lookup'!$B$2:$B$430),"NOT IN SOURCE")) -> 10.1016/j.istruc.2025.110115
A28: 3996 | B28: Arowoiya (2024) | C28: 2024 | E28: =IF($A28="","",IFERROR(_xlfn.XLOOKUP($A28,'2_DOI_Lookup'!$D$2:$D$430,'2_DOI_Lookup'!$E$2:$E$430),"TITLE NOT IN SOURCE")) -> Driving Factors for the Adoption of Digital Twin Technology Implementation for Construction Project Performance in Nigeria | F28: Web of Science | G28: Yes | H28: Yes | I28: Yes | J28: Yes | K28: Yes | L28: =IF(COUNTBLANK(G28:K28)=5,"",IF(COUNTIF(G28:K28,"No")>0,"EXCLUDE","INCLUDE")) -> INCLUDE | M28: =IF(L28<>"EXCLUDE","",IF(G28="No","Wrong domain (non-AECO)",IF(H28="No","Digital Twin not core / buzzword",IF(I28="No","No Design for Safety/Quality/PtD",IF(J28="No","Wrong publication type",IF(K28="No","Non-English","")))))) | N28: Yes | O28: Yes | P28: No | Q28: Yes | R28: Yes | S28: =IF(N28<>"Yes","",IF(COUNTBLANK(P28:R28)=3,"",IF(COUNTIF(P28:R28,"No")>0,"EXCLUDE","INCLUDE"))) -> EXCLUDE | T28: =IF(S28<>"EXCLUDE","",IF(P28="No","Digital Twin mentioned only, not the subject",IF(Q28="No","No Design for Safety/Quality in full text",IF(R28="No","Methodology not codable","")))) -> Digital Twin mentioned only, not the subject | U28: Unclear | Y28: =IF(SUM(V28:X28)=0,"",IF(SUM(V28:X28)>=2,"Multi","Single")) | AG28: Questionnaire survey (Nigerian construction professionals, purposive+snowball) of drivers for adopting DTT; Shapiro-Wilk + Kruskal-Wallis H + factor analysis grouping drivers into innovation/operation/quality/performance/policy. No digital twin is built, evaluated or framed as a system — DT only appears as the technology whose adoption is surveyed. P=No → Stage-2 exclude. [Full-text source: Endnote] | AN28: Verified 2026-08-22 vs PDF (ASCE). Close-ended questionnaires to Nigerian professionals via purposive and snowball sampling, Shapiro-Wilk and Kruskal-Wallis analysis; no DT built or evaluated. Stage-2 EXCLUDE (P=No) upheld. | AO28: =IF($A28="","",IFERROR(_xlfn.XLOOKUP($A28,'2_DOI_Lookup'!$A$2:$A$430,'2_DOI_Lookup'!$B$2:$B$430),"NOT IN SOURCE")) -> 10.1061/JCEMD4.COENG-13659
