Workbook

Sheet 0_Guide
B2: One Matrix - Four Steps (LLM-ready, no background assumed)
B3: A single progressive-disclosure matrix for screening, coding, deep-read analysis and reporting.
B5: CONTEXT PRIMER (read this before coding any paper)
B6: What is this review about | C6: This is a systematic literature review about DIGITAL TWINS used in the built-environment industry, specifically to improve SAFETY and QUALITY of designs. You are screening and coding academic papers.
B7: AECO | C7: AECO = Architecture, Engineering, Construction and Operations. It means the built-environment / construction industry (buildings, bridges, infrastructure, civil engineering). NOT manufacturing, automotive, aerospace, power/electrical equipment, healthcare, or agriculture.
B8: Digital Twin (DT) | C8: A Digital Twin is a live virtual replica of a physical asset that is connected to it by data. It is MORE than a static 3D/BIM model. If a paper only says the words 'digital twin' in passing but does not actually build or study one, treat DT as a buzzword (answer 'No').
B9: Design for Safety (DfS) | C9: Design for Safety = designing to prevent construction/operation safety incidents (e.g. fall from height, hazards, accident prevention).
B10: Design for Quality (DfQ) | C10: Design for Quality = designing to prevent defects, rework, or quality failures.
B11: Prevention through Design (PtD) | C11: Prevention through Design = the principle of eliminating risks at the design stage before construction begins. Closely related to DfS/DfQ.
B12: BIM | C12: BIM = Building Information Modelling. A static, design-stage digital model. A BIM model alone is NOT a Digital Twin (no live data link).
B13: bidirectional | C13: 'bidirectional' means data flows BOTH ways: physical->virtual AND virtual->physical (the twin can act back on the real asset). One-way data flow is only a 'digital shadow'.
B14: Answer format | C14: Every Stage-1 and Stage-2 question is answered strictly as 'Yes' or 'No'. If genuinely unsure from the abstract, answer 'No' (conservative) and add a note. Do not invent information not present in the text.
B15: One reason only | C15: When a paper is excluded, the matrix auto-picks ONE standardized reason by priority. You do not write the reason yourself.
B17: THE FOUR STEPS
B18: Step 1 (all 450 papers) | C18: An LLM or reviewer fills the AMBER Stage-1 columns (G-K) for EVERY paper, from the TITLE and ABSTRACT only. Column L auto-decides Include/Exclude; column M auto-writes the single exclusion reason.
B19: Step 2 (the matrix) | C19: This workbook IS the summary matrix. There is nothing separate to generate.
B20: Retrieval + PDF gateway | C20: For Stage-1 includes, first mark column N 'PDF full text on hand?'. This is the gateway: only papers with the PDF on hand can be deep-read. You can revisit later - when a PDF is found, change N from 'No' to 'Yes' and the paper becomes ready for Stage-2/3.
B21: Step 3 (deep read) | C21: For papers whose PDF is on hand, fill the RED Stage-2 columns (P-R) and then the GREEN synthesis 'angle' columns (U-AG). These are the evidence for your findings section.
B22: Step 4 (report) | C22: Open 'Step1_Report' (screening + PRISMA chain + exclusion reasons) and 'Step3_Report' (capability-tier / phase / method / modality / validation / self-improvement tables). Both auto-tally from the same rows.
B24: COLOUR KEY
B25: Bands | C25: AMBER = Stage-1 input (from abstract) · BLUE = PDF gateway · RED = Stage-2 input (from full text) · GREEN = Stage-3 deep-read input · BLUE-GREY = auto formula, do not edit.
B26: Golden rule | C26: Never delete a paper. A paper excluded at any stage stays in the matrix with its reason recorded. This is what makes the PRISMA flow reproducible.

Sheet 1_CodeLists
A1: YN | B1: Src | C1: Bin | D1: Tier | E1: DfX | F1: Self | G1: Method | H1: Modality | I1: Valid | J1: Cluster
A2: Yes | B2: Scopus | C2: 0 | D2: Tier 1 - Digital Model (static, no live data) | E2: Design for Safety (DfS) | F2: None | G2: Computer Vision / CNN / object-detection | H2: Single (one data type) | I2: Conceptual (no test) | J2: BIM-to-Digital-Twin architecture
A3: No | B3: Web of Science | C3: 1 | D3: Tier 2 - Digital Shadow (one-way physical to virtual) | E3: Design for Quality (DfQ) | F3: Mentioned only | G3: Graph Neural Network (GNN) | H3: Multi (two or more data types) | I3: Simulation | J3: Semantic interoperability
B4: Lens.org | D4: Tier 3 - Digital Twin (bidirectional, two-way) | E4: Both | F4: Implemented | G4: LSTM / RNN (recurrent networks) | I4: Single case study | J4: Perception / Computer Vision
B5: Backward-snowball | D5: Tier 4 - Cognitive / Self-improving | E5: Other | F5: Convergence-characterised | G5: Transformer / Large Language Model (LLM) | I5: Cross-project (multiple real projects) | J5: Design for Safety
B6: Forward-snowball | D6: Unclear | G6: Reinforcement Learning (RL) | J6: Predictive analytics / decision support
G7: Bayesian / probabilistic | J7: Lifecycle / governance
G8: Agent-based model (ABM) | J8: Other
G9: Finite Element Method / physics-based
G10: Ontology / semantic
G11: Statistical / change-point
G12: Digital Twin platform (no machine learning)
G13: Other / Mixed

Sheet Matrix
A1: ID | B1: Authors (year) | C1: Year | D1: Journal | E1: Title | F1: Source database | G1: Stage1: Domain is AECO (built environment)? | H1: Stage1: Digital Twin is core (not just a buzzword)? | I1: Stage1: About Design for Safety / Quality / Prevention through Design? | J1: Stage1: Publication type OK (journal/conference article, not editorial/erratum)? | K1: Stage1: Written in English (full text)? | L1: STAGE-1 decision | M1: Stage-1 exclusion reason (auto) | N1: GATEWAY: PDF full text on hand? (change to Yes when found) | O1: Full text retrieved for PRISMA? | P1: Stage2: Digital Twin is the actual subject (full text)? | Q1: Stage2: Design for Safety/Quality confirmed in full text? | R1: Stage2: Methodology is clear enough to code? | S1: STAGE-2 decision | T1: Stage-2 exclusion reason (auto) | U1: Deep-read: Digital Twin capability tier | V1: Phase: Design (1/0) | W1: Phase: Construction (1/0) | X1: Phase: Operation (1/0) | Y1: Cross-phase? (auto) | Z1: Deep-read: Design-for-X target | AA1: Deep-read: Self-improvement / convergence | AB1: Deep-read: Methodology | AC1: Deep-read: Data modality | AD1: Deep-read: Validation level | AE1: Deep-read: Quality appraisal score (0 to 5) | AF1: Deep-read: Thematic cluster | AG1: Deep-read: Key evidence / notes
A2: P001 | L2: =IF(COUNTBLANK(G2:K2)=5,"",IF(COUNTIF(G2:K2,"No")>0,"EXCLUDE","INCLUDE")) | M2: =IF(L2<>"EXCLUDE","",IF(G2="No","Wrong domain (non-AECO)",IF(H2="No","Digital Twin not core / buzzword",IF(I2="No","No Design for Safety/Quality/PtD",IF(J2="No","Wrong publication type",IF(K2="No","Non-English","")))))) | S2: =IF(N2<>"Yes","",IF(COUNTBLANK(P2:R2)=3,"",IF(COUNTIF(P2:R2,"No")>0,"EXCLUDE","INCLUDE"))) | T2: =IF(S2<>"EXCLUDE","",IF(P2="No","Digital Twin mentioned only, not the subject",IF(Q2="No","No Design for Safety/Quality in full text",IF(R2="No","Methodology not codable","")))) | Y2: =IF(SUM(V2:X2)=0,"",IF(SUM(V2:X2)>=2,"Multi","Single"))
A3: P002 | L3: =IF(COUNTBLANK(G3:K3)=5,"",IF(COUNTIF(G3:K3,"No")>0,"EXCLUDE","INCLUDE")) | M3: =IF(L3<>"EXCLUDE","",IF(G3="No","Wrong domain (non-AECO)",IF(H3="No","Digital Twin not core / buzzword",IF(I3="No","No Design for Safety/Quality/PtD",IF(J3="No","Wrong publication type",IF(K3="No","Non-English","")))))) | S3: =IF(N3<>"Yes","",IF(COUNTBLANK(P3:R3)=3,"",IF(COUNTIF(P3:R3,"No")>0,"EXCLUDE","INCLUDE"))) | T3: =IF(S3<>"EXCLUDE","",IF(P3="No","Digital Twin mentioned only, not the subject",IF(Q3="No","No Design for Safety/Quality in full text",IF(R3="No","Methodology not codable","")))) | Y3: =IF(SUM(V3:X3)=0,"",IF(SUM(V3:X3)>=2,"Multi","Single"))
A4: P003 | L4: =IF(COUNTBLANK(G4:K4)=5,"",IF(COUNTIF(G4:K4,"No")>0,"EXCLUDE","INCLUDE")) | M4: =IF(L4<>"EXCLUDE","",IF(G4="No","Wrong domain (non-AECO)",IF(H4="No","Digital Twin not core / buzzword",IF(I4="No","No Design for Safety/Quality/PtD",IF(J4="No","Wrong publication type",IF(K4="No","Non-English","")))))) | S4: =IF(N4<>"Yes","",IF(COUNTBLANK(P4:R4)=3,"",IF(COUNTIF(P4:R4,"No")>0,"EXCLUDE","INCLUDE"))) | T4: =IF(S4<>"EXCLUDE","",IF(P4="No","Digital Twin mentioned only, not the subject",IF(Q4="No","No Design for Safety/Quality in full text",IF(R4="No","Methodology not codable","")))) | Y4: =IF(SUM(V4:X4)=0,"",IF(SUM(V4:X4)>=2,"Multi","Single"))
A5: P004 | L5: =IF(COUNTBLANK(G5:K5)=5,"",IF(COUNTIF(G5:K5,"No")>0,"EXCLUDE","INCLUDE")) | M5: =IF(L5<>"EXCLUDE","",IF(G5="No","Wrong domain (non-AECO)",IF(H5="No","Digital Twin not core / buzzword",IF(I5="No","No Design for Safety/Quality/PtD",IF(J5="No","Wrong publication type",IF(K5="No","Non-English","")))))) | S5: =IF(N5<>"Yes","",IF(COUNTBLANK(P5:R5)=3,"",IF(COUNTIF(P5:R5,"No")>0,"EXCLUDE","INCLUDE"))) | T5: =IF(S5<>"EXCLUDE","",IF(P5="No","Digital Twin mentioned only, not the subject",IF(Q5="No","No Design for Safety/Quality in full text",IF(R5="No","Methodology not codable","")))) | Y5: =IF(SUM(V5:X5)=0,"",IF(SUM(V5:X5)>=2,"Multi","Single"))
A6: P005 | L6: =IF(COUNTBLANK(G6:K6)=5,"",IF(COUNTIF(G6:K6,"No")>0,"EXCLUDE","INCLUDE")) | M6: =IF(L6<>"EXCLUDE","",IF(G6="No","Wrong domain (non-AECO)",IF(H6="No","Digital Twin not core / buzzword",IF(I6="No","No Design for Safety/Quality/PtD",IF(J6="No","Wrong publication type",IF(K6="No","Non-English","")))))) | S6: =IF(N6<>"Yes","",IF(COUNTBLANK(P6:R6)=3,"",IF(COUNTIF(P6:R6,"No")>0,"EXCLUDE","INCLUDE"))) | T6: =IF(S6<>"EXCLUDE","",IF(P6="No","Digital Twin mentioned only, not the subject",IF(Q6="No","No Design for Safety/Quality in full text",IF(R6="No","Methodology not codable","")))) | Y6: =IF(SUM(V6:X6)=0,"",IF(SUM(V6:X6)>=2,"Multi","Single"))
A7: P006 | L7: =IF(COUNTBLANK(G7:K7)=5,"",IF(COUNTIF(G7:K7,"No")>0,"EXCLUDE","INCLUDE")) | M7: =IF(L7<>"EXCLUDE","",IF(G7="No","Wrong domain (non-AECO)",IF(H7="No","Digital Twin not core / buzzword",IF(I7="No","No Design for Safety/Quality/PtD",IF(J7="No","Wrong publication type",IF(K7="No","Non-English","")))))) | S7: =IF(N7<>"Yes","",IF(COUNTBLANK(P7:R7)=3,"",IF(COUNTIF(P7:R7,"No")>0,"EXCLUDE","INCLUDE"))) | T7: =IF(S7<>"EXCLUDE","",IF(P7="No","Digital Twin mentioned only, not the subject",IF(Q7="No","No Design for Safety/Quality in full text",IF(R7="No","Methodology not codable","")))) | Y7: =IF(SUM(V7:X7)=0,"",IF(SUM(V7:X7)>=2,"Multi","Single"))
A8: P007 | L8: =IF(COUNTBLANK(G8:K8)=5,"",IF(COUNTIF(G8:K8,"No")>0,"EXCLUDE","INCLUDE")) | M8: =IF(L8<>"EXCLUDE","",IF(G8="No","Wrong domain (non-AECO)",IF(H8="No","Digital Twin not core / buzzword",IF(I8="No","No Design for Safety/Quality/PtD",IF(J8="No","Wrong publication type",IF(K8="No","Non-English","")))))) | S8: =IF(N8<>"Yes","",IF(COUNTBLANK(P8:R8)=3,"",IF(COUNTIF(P8:R8,"No")>0,"EXCLUDE","INCLUDE"))) | T8: =IF(S8<>"EXCLUDE","",IF(P8="No","Digital Twin mentioned only, not the subject",IF(Q8="No","No Design for Safety/Quality in full text",IF(R8="No","Methodology not codable","")))) | Y8: =IF(SUM(V8:X8)=0,"",IF(SUM(V8:X8)>=2,"Multi","Single"))
A9: P008 | L9: =IF(COUNTBLANK(G9:K9)=5,"",IF(COUNTIF(G9:K9,"No")>0,"EXCLUDE","INCLUDE")) | M9: =IF(L9<>"EXCLUDE","",IF(G9="No","Wrong domain (non-AECO)",IF(H9="No","Digital Twin not core / buzzword",IF(I9="No","No Design for Safety/Quality/PtD",IF(J9="No","Wrong publication type",IF(K9="No","Non-English","")))))) | S9: =IF(N9<>"Yes","",IF(COUNTBLANK(P9:R9)=3,"",IF(COUNTIF(P9:R9,"No")>0,"EXCLUDE","INCLUDE"))) | T9: =IF(S9<>"EXCLUDE","",IF(P9="No","Digital Twin mentioned only, not the subject",IF(Q9="No","No Design for Safety/Quality in full text",IF(R9="No","Methodology not codable","")))) | Y9: =IF(SUM(V9:X9)=0,"",IF(SUM(V9:X9)>=2,"Multi","Single"))
A10: P009 | L10: =IF(COUNTBLANK(G10:K10)=5,"",IF(COUNTIF(G10:K10,"No")>0,"EXCLUDE","INCLUDE")) | M10: =IF(L10<>"EXCLUDE","",IF(G10="No","Wrong domain (non-AECO)",IF(H10="No","Digital Twin not core / buzzword",IF(I10="No","No Design for Safety/Quality/PtD",IF(J10="No","Wrong publication type",IF(K10="No","Non-English","")))))) | S10: =IF(N10<>"Yes","",IF(COUNTBLANK(P10:R10)=3,"",IF(COUNTIF(P10:R10,"No")>0,"EXCLUDE","INCLUDE"))) | T10: =IF(S10<>"EXCLUDE","",IF(P10="No","Digital Twin mentioned only, not the subject",IF(Q10="No","No Design for Safety/Quality in full text",IF(R10="No","Methodology not codable","")))) | Y10: =IF(SUM(V10:X10)=0,"",IF(SUM(V10:X10)>=2,"Multi","Single"))
A11: P010 | L11: =IF(COUNTBLANK(G11:K11)=5,"",IF(COUNTIF(G11:K11,"No")>0,"EXCLUDE","INCLUDE")) | M11: =IF(L11<>"EXCLUDE","",IF(G11="No","Wrong domain (non-AECO)",IF(H11="No","Digital Twin not core / buzzword",IF(I11="No","No Design for Safety/Quality/PtD",IF(J11="No","Wrong publication type",IF(K11="No","Non-English","")))))) | S11: =IF(N11<>"Yes","",IF(COUNTBLANK(P11:R11)=3,"",IF(COUNTIF(P11:R11,"No")>0,"EXCLUDE","INCLUDE"))) | T11: =IF(S11<>"EXCLUDE","",IF(P11="No","Digital Twin mentioned only, not the subject",IF(Q11="No","No Design for Safety/Quality in full text",IF(R11="No","Methodology not codable","")))) | Y11: =IF(SUM(V11:X11)=0,"",IF(SUM(V11:X11)>=2,"Multi","Single"))
A12: P011 | L12: =IF(COUNTBLANK(G12:K12)=5,"",IF(COUNTIF(G12:K12,"No")>0,"EXCLUDE","INCLUDE")) | M12: =IF(L12<>"EXCLUDE","",IF(G12="No","Wrong domain (non-AECO)",IF(H12="No","Digital Twin not core / buzzword",IF(I12="No","No Design for Safety/Quality/PtD",IF(J12="No","Wrong publication type",IF(K12="No","Non-English","")))))) | S12: =IF(N12<>"Yes","",IF(COUNTBLANK(P12:R12)=3,"",IF(COUNTIF(P12:R12,"No")>0,"EXCLUDE","INCLUDE"))) | T12: =IF(S12<>"EXCLUDE","",IF(P12="No","Digital Twin mentioned only, not the subject",IF(Q12="No","No Design for Safety/Quality in full text",IF(R12="No","Methodology not codable","")))) | Y12: =IF(SUM(V12:X12)=0,"",IF(SUM(V12:X12)>=2,"Multi","Single"))
A13: P012 | L13: =IF(COUNTBLANK(G13:K13)=5,"",IF(COUNTIF(G13:K13,"No")>0,"EXCLUDE","INCLUDE")) | M13: =IF(L13<>"EXCLUDE","",IF(G13="No","Wrong domain (non-AECO)",IF(H13="No","Digital Twin not core / buzzword",IF(I13="No","No Design for Safety/Quality/PtD",IF(J13="No","Wrong publication type",IF(K13="No","Non-English","")))))) | S13: =IF(N13<>"Yes","",IF(COUNTBLANK(P13:R13)=3,"",IF(COUNTIF(P13:R13,"No")>0,"EXCLUDE","INCLUDE"))) | T13: =IF(S13<>"EXCLUDE","",IF(P13="No","Digital Twin mentioned only, not the subject",IF(Q13="No","No Design for Safety/Quality in full text",IF(R13="No","Methodology not codable","")))) | Y13: =IF(SUM(V13:X13)=0,"",IF(SUM(V13:X13)>=2,"Multi","Single"))
... A451: P450 | L451: =IF(COUNTBLANK(G451:K451)=5,"",IF(COUNTIF(G451:K451,"No")>0,"EXCLUDE","INCLUDE")) | M451: =IF(L451<>"EXCLUDE","",IF(G451="No","Wrong domain (non-AECO)",IF(H451="No","Digital Twin not core / buzzword",IF(I451="No","No Design for Safety/Quality/PtD",IF(J451="No","Wrong publication type",IF(K451="No","Non-English","")))))) | S451: =IF(N451<>"Yes","",IF(COUNTBLANK(P451:R451)=3,"",IF(COUNTIF(P451:R451,"No")>0,"EXCLUDE","INCLUDE"))) | T451: =IF(S451<>"EXCLUDE","",IF(P451="No","Digital Twin mentioned only, not the subject",IF(Q451="No","No Design for Safety/Quality in full text",IF(R451="No","Methodology not codable","")))) | Y451: =IF(SUM(V451:X451)=0,"",IF(SUM(V451:X451)>=2,"Multi","Single"))

Sheet Step1_Report
A1: STEP 1 & PRISMA - screening outcomes (auto)
A3: PRISMA stage | B3: n
A4: Records identified (in matrix) | B4: =COUNTA(Matrix!$A$2:$A$451) -> 450
A5: Records screened (Stage-1 decided) | B5: =COUNTIF(Matrix!$L$2:$L$451,"INCLUDE")+COUNTIF(Matrix!$L$2:$L$451,"EXCLUDE") -> 0
A6: Excluded at Stage-1 (title/abstract) | B6: =COUNTIF(Matrix!$L$2:$L$451,"EXCLUDE") -> 0
A7: Stage-1 INCLUDE -> sought for retrieval | B7: =COUNTIF(Matrix!$L$2:$L$451,"INCLUDE") -> 0
A8: PDF full text on hand (gateway = Yes) | B8: =COUNTIFS(Matrix!$L$2:$L$451,"INCLUDE",Matrix!$N$2:$N$451,"Yes") -> 0
A9: PDF not yet on hand (revisit later) | B9: =COUNTIFS(Matrix!$L$2:$L$451,"INCLUDE",Matrix!$N$2:$N$451,"No") -> 0
A10: Reports assessed for eligibility (full text) | B10: =COUNTIFS(Matrix!$N$2:$N$451,"Yes",Matrix!$S$2:$S$451,"INCLUDE")+COUNTIFS(Matrix!$N$2:$N$451,"Yes",Matrix!$S$2:$S$451,"EXCLUDE") -> 0
A11: Excluded at Stage-2 (full text, with reasons) | B11: =COUNTIF(Matrix!$S$2:$S$451,"EXCLUDE") -> 0
A12: STUDIES INCLUDED IN SYNTHESIS | B12: =COUNTIF(Matrix!$S$2:$S$451,"INCLUDE") -> 0
A14: Stage-1 exclusion reasons
A15: Reason | B15: n
A16: Wrong domain (non-AECO) | B16: =COUNTIF(Matrix!$M$2:$M$451,"Wrong domain (non-AECO)") -> 0
A17: Digital Twin not core / buzzword | B17: =COUNTIF(Matrix!$M$2:$M$451,"Digital Twin not core / buzzword") -> 0
A18: No Design for Safety/Quality/PtD | B18: =COUNTIF(Matrix!$M$2:$M$451,"No Design for Safety/Quality/PtD") -> 0
A19: Wrong publication type | B19: =COUNTIF(Matrix!$M$2:$M$451,"Wrong publication type") -> 0
A20: Non-English | B20: =COUNTIF(Matrix!$M$2:$M$451,"Non-English") -> 0
A21: Total Stage-1 exclusions | B21: =SUM(B16:B20) -> 0
A23: Stage-2 (full-text) exclusion reasons
A24: Reason | B24: n
A25: Digital Twin mentioned only, not the subject | B25: =COUNTIF(Matrix!$T$2:$T$451,"Digital Twin mentioned only, not the subject") -> 0
A26: No Design for Safety/Quality in full text | B26: =COUNTIF(Matrix!$T$2:$T$451,"No Design for Safety/Quality in full text") -> 0
A27: Methodology not codable | B27: =COUNTIF(Matrix!$T$2:$T$451,"Methodology not codable") -> 0
A28: Total Stage-2 exclusions | B28: =SUM(B25:B27) -> 0

Sheet Step3_Report
A1: STEP 3 - deep-read synthesis tables (auto = findings section)
A2: Total included studies | B2: =COUNTIF(Matrix!$S$2:$S$451,"INCLUDE") -> 0
A4: Digital Twin capability tier (Gap 1)
A5: Category | B5: n | C5: % of incl.
A6: Tier 1 - Digital Model (static, no live data) | B6: =COUNTIFS(Matrix!$S$2:$S$451,"INCLUDE",Matrix!$U$2:$U$451,"Tier 1 - Digital Model (static, no live data)") -> 0 | C6: =IF($B$2=0,"-",B6/$B$2) -> -
A7: Tier 2 - Digital Shadow (one-way physical to virtual) | B7: =COUNTIFS(Matrix!$S$2:$S$451,"INCLUDE",Matrix!$U$2:$U$451,"Tier 2 - Digital Shadow (one-way physical to virtual)") -> 0 | C7: =IF($B$2=0,"-",B7/$B$2) -> -
A8: Tier 3 - Digital Twin (bidirectional, two-way) | B8: =COUNTIFS(Matrix!$S$2:$S$451,"INCLUDE",Matrix!$U$2:$U$451,"Tier 3 - Digital Twin (bidirectional, two-way)") -> 0 | C8: =IF($B$2=0,"-",B8/$B$2) -> -
A9: Tier 4 - Cognitive / Self-improving | B9: =COUNTIFS(Matrix!$S$2:$S$451,"INCLUDE",Matrix!$U$2:$U$451,"Tier 4 - Cognitive / Self-improving") -> 0 | C9: =IF($B$2=0,"-",B9/$B$2) -> -
A10: Unclear | B10: =COUNTIFS(Matrix!$S$2:$S$451,"INCLUDE",Matrix!$U$2:$U$451,"Unclear") -> 0 | C10: =IF($B$2=0,"-",B10/$B$2) -> -
A12: Self-improvement / convergence (core gap)
A13: Category | B13: n | C13: % of incl.
A14: None | B14: =COUNTIFS(Matrix!$S$2:$S$451,"INCLUDE",Matrix!$AA$2:$AA$451,"None") -> 0 | C14: =IF($B$2=0,"-",B14/$B$2) -> -
A15: Mentioned only | B15: =COUNTIFS(Matrix!$S$2:$S$451,"INCLUDE",Matrix!$AA$2:$AA$451,"Mentioned only") -> 0 | C15: =IF($B$2=0,"-",B15/$B$2) -> -
A16: Implemented | B16: =COUNTIFS(Matrix!$S$2:$S$451,"INCLUDE",Matrix!$AA$2:$AA$451,"Implemented") -> 0 | C16: =IF($B$2=0,"-",B16/$B$2) -> -
A17: Convergence-characterised | B17: =COUNTIFS(Matrix!$S$2:$S$451,"INCLUDE",Matrix!$AA$2:$AA$451,"Convergence-characterised") -> 0 | C17: =IF($B$2=0,"-",B17/$B$2) -> -
A19: Design-for-X target
A20: Category | B20: n | C20: % of incl.
A21: Design for Safety (DfS) | B21: =COUNTIFS(Matrix!$S$2:$S$451,"INCLUDE",Matrix!$Z$2:$Z$451,"Design for Safety (DfS)") -> 0 | C21: =IF($B$2=0,"-",B21/$B$2) -> -
A22: Design for Quality (DfQ) | B22: =COUNTIFS(Matrix!$S$2:$S$451,"INCLUDE",Matrix!$Z$2:$Z$451,"Design for Quality (DfQ)") -> 0 | C22: =IF($B$2=0,"-",B22/$B$2) -> -
A23: Both | B23: =COUNTIFS(Matrix!$S$2:$S$451,"INCLUDE",Matrix!$Z$2:$Z$451,"Both") -> 0 | C23: =IF($B$2=0,"-",B23/$B$2) -> -
A24: Other | B24: =COUNTIFS(Matrix!$S$2:$S$451,"INCLUDE",Matrix!$Z$2:$Z$451,"Other") -> 0 | C24: =IF($B$2=0,"-",B24/$B$2) -> -
A26: Data modality (Gap 2)
A27: Category | B27: n | C27: % of incl.
A28: Single (one data type) | B28: =COUNTIFS(Matrix!$S$2:$S$451,"INCLUDE",Matrix!$AC$2:$AC$451,"Single (one data type)") -> 0 | C28: =IF($B$2=0,"-",B28/$B$2) -> -
A29: Multi (two or more data types) | B29: =COUNTIFS(Matrix!$S$2:$S$451,"INCLUDE",Matrix!$AC$2:$AC$451,"Multi (two or more data types)") -> 0 | C29: =IF($B$2=0,"-",B29/$B$2) -> -
A31: Validation level (Gap 5)
A32: Category | B32: n | C32: % of incl.
A33: Conceptual (no test) | B33: =COUNTIFS(Matrix!$S$2:$S$451,"INCLUDE",Matrix!$AD$2:$AD$451,"Conceptual (no test)") -> 0 | C33: =IF($B$2=0,"-",B33/$B$2) -> -
A34: Simulation | B34: =COUNTIFS(Matrix!$S$2:$S$451,"INCLUDE",Matrix!$AD$2:$AD$451,"Simulation") -> 0 | C34: =IF($B$2=0,"-",B34/$B$2) -> -
A35: Single case study | B35: =COUNTIFS(Matrix!$S$2:$S$451,"INCLUDE",Matrix!$AD$2:$AD$451,"Single case study") -> 0 | C35: =IF($B$2=0,"-",B35/$B$2) -> -
A36: Cross-project (multiple real projects) | B36: =COUNTIFS(Matrix!$S$2:$S$451,"INCLUDE",Matrix!$AD$2:$AD$451,"Cross-project (multiple real projects)") -> 0 | C36: =IF($B$2=0,"-",B36/$B$2) -> -
A38: Methodology (RQ2)
A39: Category | B39: n | C39: % of incl.
A40: Computer Vision / CNN / object-detection | B40: =COUNTIFS(Matrix!$S$2:$S$451,"INCLUDE",Matrix!$AB$2:$AB$451,"Computer Vision / CNN / object-detection") -> 0 | C40: =IF($B$2=0,"-",B40/$B$2) -> -
A41: Graph Neural Network (GNN) | B41: =COUNTIFS(Matrix!$S$2:$S$451,"INCLUDE",Matrix!$AB$2:$AB$451,"Graph Neural Network (GNN)") -> 0 | C41: =IF($B$2=0,"-",B41/$B$2) -> -
A42: LSTM / RNN (recurrent networks) | B42: =COUNTIFS(Matrix!$S$2:$S$451,"INCLUDE",Matrix!$AB$2:$AB$451,"LSTM / RNN (recurrent networks)") -> 0 | C42: =IF($B$2=0,"-",B42/$B$2) -> -
A43: Transformer / Large Language Model (LLM) | B43: =COUNTIFS(Matrix!$S$2:$S$451,"INCLUDE",Matrix!$AB$2:$AB$451,"Transformer / Large Language Model (LLM)") -> 0 | C43: =IF($B$2=0,"-",B43/$B$2) -> -
A44: Reinforcement Learning (RL) | B44: =COUNTIFS(Matrix!$S$2:$S$451,"INCLUDE",Matrix!$AB$2:$AB$451,"Reinforcement Learning (RL)") -> 0 | C44: =IF($B$2=0,"-",B44/$B$2) -> -
A45: Bayesian / probabilistic | B45: =COUNTIFS(Matrix!$S$2:$S$451,"INCLUDE",Matrix!$AB$2:$AB$451,"Bayesian / probabilistic") -> 0 | C45: =IF($B$2=0,"-",B45/$B$2) -> -
A46: Agent-based model (ABM) | B46: =COUNTIFS(Matrix!$S$2:$S$451,"INCLUDE",Matrix!$AB$2:$AB$451,"Agent-based model (ABM)") -> 0 | C46: =IF($B$2=0,"-",B46/$B$2) -> -
...
